Workbook
Name ADVANCE: Masters!$U$3:$U$22
Name AMANAT: Masters!$P$3:$P$32
Name BEPAARI: Masters!$B$3:$B$52
Name CAPITAL: Masters!$P$3:$P$32
Name DUKANDAR: Masters!$J$3:$J$150
Name LOAN: Masters!$P$3:$P$32

Sheet Masters
A1: BEPAARI MASTER | I1: DUKANDAR MASTER | O1: CAPITAL/LOAN/AMANAT | T1: ADVANCE PARTIES | X1: SETTINGS & B/F BALANCES
A2: Sr | B2: Bepaari Name | C2: Comm% | D2: Flat ₹/Goat | E2: Opening Bal | F2: Phone | G2: Remarks | I2: Sr | J2: Dukandar Name | K2: Opening Bal | L2: Phone | M2: Remarks | O2: Sr | P2: Party Name | Q2: Opening Bal | R2: Type | T2: Sr | U2: Party Name | V2: Opening Bal | X2: Commission Rate (%) | Y2: 4
A3: 1 | B3: ABUL HASAN | C3: 4 | E3: 7550 | I3: 1 | J3: SAKIM | K3: 113500 | O3: 1 | P3: MHN CAPITAL | Q3: 4469981 | R3: CAPITAL | T3: 1 | U3: SALIM MANGROL | V3: 50000 | X3: KK Fixed (₹/Bepari) | Y3: 100
A4: 2 | B4: SHARAFAT | C4: 4 | E4: 0 | I4: 2 | J4: SHARIK | K4: 879000 | O4: 2 | P4: SHAKIL GHODEGAON AMANAT | Q4: 2000000 | R4: AMANAT | T4: 2 | U4: MUDASSIR | V4: 25000 | X4: JB Rate (₹/Goat) | Y4: 10
A5: 3 | B5: JUNAID | C5: 4 | E5: 0 | I5: 3 | J5: YUNUS | K5: 94931 | O5: 3 | P5: KMN | Q5: 0 | R5: AMANAT | T5: 3 | U5: AYAAN | V5: 203700
A6: 4 | B6: ANNU SHARIF | C6: 4 | E6: 0 | I6: 4 | J6: MUDASSIR | K6: 516778 | O6: 4 | P6: AYAAN | Q6: 0 | R6: AMANAT | T6: 4 | U6: KMN | V6: 347500 | X6: Opening Cash | Y6: 394666
A7: 5 | B7: GAYYUR | C7: 4 | E7: 142530 | I7: 5 | J7: ARIF | K7: 187650 | O7: 5 | P7: WAHIDA | Q7: 0 | R7: AMANAT | T7: 5 | U7: SANTOSH | V7: 3000 | X7: Opening Bank | Y7: 724604
A8: 6 | B8: KISHOR | C8: 4 | E8: -152964 | I8: 6 | J8: SHOEB BYCULLA | K8: 0 | O8: 6 | P8: TILLA | Q8: 0 | R8: AMANAT | T8: 6 | U8: SHAKIL GHODEGAON | V8: 100000
A9: 7 | B9: MAULANA | C9: 4 | E9: 35330 | I9: 7 | J9: ISLAM D | K9: 100000 | O9: 7 | T9: 7 | X9: --- LIABILITIES B/F ---
A10: 8 | B10: SALIM RAJ | C10: 4 | E10: 0 | I10: 8 | J10: MEHMOOD MADH | K10: 15000 | O10: 8 | T10: 8 | X10: JB Opening (B/F) | Y10: 17100
A11: 9 | B11: ANAS RAJ | C11: 4 | E11: 0 | I11: 9 | J11: MOBIN CHIPLUN | K11: 486250 | O11: 9 | T11: 9 | X11: KK Opening (B/F) | Y11: 10100
A12: 10 | B12: AYAZ | C12: 4 | E12: 1530 | I12: 10 | J12: JALIL | K12: 90950 | O12: 10 | T12: 10 | X12: Zakat Opening (B/F) | Y12: 73111
A13: 11 | B13: NEERAJ | C13: 4 | E13: 0 | I13: 11 | J13: IRFAN JOGESHWARI | K13: 0 | O13: 11 | T13: 11 | X13: Commission Opening (B/F) | Y13: 358808
A14: 12 | B14: CHINTU SHUJALPUR | C14: 4 | E14: 0 | I14: 12 | J14: YUNUS DOMBIVLI | K14: 59662 | O14: 12 | T14: 12
A15: 13 | B15: SANNA | C15: 4 | E15: -14048 | I15: 13 | J15: IFTEKHAR PUNE | K15: 2000 | O15: 13 | T15: 13 | X15: --- ASSETS B/F ---
A16: 14 | B16: WAHID | C16: 4 | E16: -4661 | I16: 14 | J16: LALA/ASIF | K16: 0 | O16: 14 | T16: 14 | X16: Mandi Exp Opening (B/F) | Y16: 24816
A17: 15 | B17: MANSOOR | C17: 4 | E17: -9845 | I17: 15 | J17: JAFER KASHIMIRA | K17: 92500 | O17: 15 | T17: 15 | X17: BF Discount Opening (B/F) | Y17: 17450
A18: 16 | B18: AYAZ PREVIOUS BAL | C18: 4 | E18: -88000 | I18: 16 | J18: HANIF KALAM | K18: 0 | O18: 16 | T18: 16 | X18: MHN Personal Opening (B/F) | Y18: 294265
A19: 17 | B19: SHAKIL SHUJALPUR | C19: 4 | E19: 660 | I19: 17 | J19: SAUD K | K19: 0 | O19: 17 | T19: 17
A20: 18 | B20: USMAN | C20: 4 | E20: 40440 | I20: 18 | J20: AKRAM | K20: 0 | O20: 18 | T20: 18 | X20: SALIM MANGROL RECEIVABLE | Y20: 50000
A21: 19 | B21: JUNAID AMANAT | C21: 4 | E21: -100000 | I21: 19 | J21: WAHID | K21: 4000 | O21: 19 | T21: 19 | X21: MUDASSIR RECEIVABLE | Y21: 25000
A22: 20 | B22: SHARIF RAJ | C22: 4 | E22: 0 | I22: 20 | J22: VAZIR | K22: 134750 | O22: 20 | T22: 20 | X22: KMN RECEIVABLE | Y22: 347500
A23: 21 | C23: 4 | I23: 21 | J23: ISMAIL SOPARA | K23: 0 | O23: 21 | X23: SANTOSH RECEIVABLE | Y23: 3000
A24: 22 | C24: 4 | I24: 22 | J24: ARIF CHINCHOTI | K24: 0 | O24: 22 | X24: SHAKIL GHODEGAON RECEIVABLE | Y24: 100000
A25: 23 | C25: 4 | I25: 23 | J25: NADEEM BHIWANDI | K25: 265000 | O25: 23 | X25: AYAAN RECEIVABLE | Y25: 203700
A26: 24 | C26: 4 | I26: 24 | J26: GABBAR | K26: 33050 | O26: 24
A27: 25 | C27: 4 | I27: 25 | J27: BABU GABBAR | K27: 50000 | O27: 25
A28: 26 | C28: 4 | I28: 26 | J28: BABU TALOJA | K28: 2600 | O28: 26
A29: 27 | C29: 4 | I29: 27 | J29: SHAKIL KON | K29: 34000 | O29: 27
A30: 28 | C30: 4 | I30: 28 | J30: PARVEZ | K30: 0 | O30: 28
A31: 29 | C31: 4 | I31: 29 | J31: I CHO CHO | K31: 20500 | O31: 29
A32: 30 | C32: 4 | I32: 30 | J32: MD VIRAR | K32: 1900 | O32: 30
A33: 31 | C33: 4 | I33: 31 | J33: MAYA | K33: 11000
A34: 32 | C34: 4 | I34: 32 | J34: NAEEM THORPE | K34: 0
A35: 33 | C35: 4 | I35: 33 | J35: CHAND | K35: 59000
A36: 34 | C36: 4 | I36: 34 | J36: ASIF GOREGAON | K36: 57550
A37: 35 | C37: 4 | I37: 35 | J37: SOHAIL MAROL | K37: 0
A38: 36 | C38: 4 | I38: 36 | J38: ANEES KM | K38: 70000
A39: 37 | C39: 4 | I39: 37 | J39: RAFIQ AHMED HAJI | K39: 356250
A40: 38 | C40: 4 | I40: 38 | J40: ABP - MAJEED THANA | K40: 0
...

Sheet Daily_Sales
A1: DAILY SALES (Bepaari to Dukandar)
A3: Sr | B3: Date | C3: Bepaari | D3: Dukandar | E3: Qty | F3: Rate | G3: Gross | H3: Discount | I3: Net
A4: 1 | B4: 46107 | C4: ANAS RAJ | D4: HAKIM BOMBAY | E4: 20 | F4: 11400 | G4: =IF(E4="","",E4*F4) -> 228000 | H4: 2000 | I4: =IF(G4="","",G4-IF(H4="",0,H4)) -> 226000
A5: 2 | B5: 46107 | C5: ANAS RAJ | D5: JUNAID KHATIK | E5: 13 | F5: 8200 | G5: =IF(E5="","",E5*F5) -> 106600 | H5: 650 | I5: =IF(G5="","",G5-IF(H5="",0,H5)) -> 105950
A6: 3 | B6: 46107 | C6: JUNAID | D6: MANISH | E6: 12 | F6: 9500 | G6: =IF(E6="","",E6*F6) -> 114000 | I6: =IF(G6="","",G6-IF(H6="",0,H6)) -> 114000
A7: 4 | B7: 46107 | C7: JUNAID | D7: CASH SALES | E7: 10 | F7: 8500 | G7: =IF(E7="","",E7*F7) -> 85000 | I7: =IF(G7="","",G7-IF(H7="",0,H7)) -> 85000
A8: 5 | B8: 46107 | C8: JUNAID | D8: JALIL | E8: 1 | F8: 6500 | G8: =IF(E8="","",E8*F8) -> 6500 | I8: =IF(G8="","",G8-IF(H8="",0,H8)) -> 6500
A9: 6 | B9: 46107 | C9: SHARIF RAJ | D9: SHOEB BYCULLA | E9: 11 | F9: 10250 | G9: =IF(E9="","",E9*F9) -> 112750 | H9: 2750 | I9: =IF(G9="","",G9-IF(H9="",0,H9)) -> 110000
A10: 7 | B10: 46107 | C10: CHINTU SHUJALPUR | D10: MEHMOOD MADH | E10: 6 | F10: 9350 | G10: =IF(E10="","",E10*F10) -> 56100 | I10: =IF(G10="","",G10-IF(H10="",0,H10)) -> 56100
A11: 8 | B11: 46107 | C11: CHINTU SHUJALPUR | D11: JALIL | E11: 4 | F11: 8750 | G11: =IF(E11="","",E11*F11) -> 35000 | I11: =IF(G11="","",G11-IF(H11="",0,H11)) -> 35000
A12: 9 | B12: 46107 | C12: CHINTU SHUJALPUR | D12: YUNUS | E12: 4 | F12: 8075 | G12: =IF(E12="","",E12*F12) -> 32300 | I12: =IF(G12="","",G12-IF(H12="",0,H12)) -> 32300
A13: 10 | B13: 46107 | C13: CHINTU SHUJALPUR | D13: MAJEED THANA | E13: 10 | F13: 6500 | G13: =IF(E13="","",E13*F13) -> 65000 | I13: =IF(G13="","",G13-IF(H13="",0,H13)) -> 65000
A14: 11 | B14: 46109 | C14: USMAN | D14: GABBAR | E14: 10 | F14: 15500 | G14: =IF(E14="","",E14*F14) -> 155000 | H14: 2000 | I14: =IF(G14="","",G14-IF(H14="",0,H14)) -> 153000
A15: 12 | B15: 46109 | C15: USMAN | D15: YUNUS | E15: 5 | F15: 14000 | G15: =IF(E15="","",E15*F15) -> 70000 | H15: 2500 | I15: =IF(G15="","",G15-IF(H15="",0,H15)) -> 67500
A16: 13 | B16: 46109 | C16: MAULANA | D16: SHAKIL KON | E16: 15 | F16: 13750 | G16: =IF(E16="","",E16*F16) -> 206250 | I16: =IF(G16="","",G16-IF(H16="",0,H16)) -> 206250
A17: 14 | B17: 46109 | C17: MAULANA | D17: NAWAZ V | E17: 11 | F17: 10600 | G17: =IF(E17="","",E17*F17) -> 116600 | H17: 1100 | I17: =IF(G17="","",G17-IF(H17="",0,H17)) -> 115500
A18: 15 | B18: 46109 | C18: ABUL HASAN | D18: PARVEZ | E18: 15 | F18: 15750 | G18: =IF(E18="","",E18*F18) -> 236250 | I18: =IF(G18="","",G18-IF(H18="",0,H18)) -> 236250
A19: 16 | B19: 46109 | C19: ABUL HASAN | D19: PARVEZ | E19: 1 | F19: 12000 | G19: =IF(E19="","",E19*F19) -> 12000 | I19: =IF(G19="","",G19-IF(H19="",0,H19)) -> 12000
A20: 17 | B20: 46109 | C20: ABUL HASAN | D20: RAMESH KALAL | E20: 13 | F20: 9800 | G20: =IF(E20="","",E20*F20) -> 127400 | H20: 1300 | I20: =IF(G20="","",G20-IF(H20="",0,H20)) -> 126100
A21: 18 | B21: 46109 | C21: ABUL HASAN | D21: JUNAID KHATIK | E21: 15 | F21: 7100 | G21: =IF(E21="","",E21*F21) -> 106500 | I21: =IF(G21="","",G21-IF(H21="",0,H21)) -> 106500
A22: 19 | B22: 46109 | C22: SHARIF RAJ | D22: SAUD K | E22: 18 | F22: 8400 | G22: =IF(E22="","",E22*F22) -> 151200 | H22: 7200 | I22: =IF(G22="","",G22-IF(H22="",0,H22)) -> 144000
A23: 20 | B23: 46109 | C23: SHARIF RAJ | D23: SAKIM | E23: 13 | F23: 7600 | G23: =IF(E23="","",E23*F23) -> 98800 | I23: =IF(G23="","",G23-IF(H23="",0,H23)) -> 98800
A24: 21 | B24: 46109 | C24: KISHOR | D24: IMRAN MUMBRA | E24: 21 | F24: 15500 | G24: =IF(E24="","",E24*F24) -> 325500
A25: 22 | B25: 46109 | C25: KISHOR | D25: IMRAN MUMBRA | E25: 1 | F25: 12500 | G25: =IF(E25="","",E25*F25) -> 12500 | I25: =IF(G25="","",G25-IF(H25="",0,H25)) -> 12500
A26: 23 | B26: 46109 | C26: KISHOR | D26: JAVED THANA | E26: 8 | F26: 10500 | G26: =IF(E26="","",E26*F26) -> 84000 | H26: 800 | I26: =IF(G26="","",G26-IF(H26="",0,H26)) -> 83200
A27: 24 | B27: 46109 | C27: KISHOR | D27: CASH SALES | E27: 2 | F27: 21000 | G27: =IF(E27="","",E27*F27) -> 42000 | I27: =IF(G27="","",G27-IF(H27="",0,H27)) -> 42000
A28: 25 | B28: 46109 | C28: JUNAID | D28: MEHMOOD MADH | E28: 14 | F28: 9200 | G28: =IF(E28="","",E28*F28) -> 128800 | I28: =IF(G28="","",G28-IF(H28="",0,H28)) -> 128800
A29: 26 | B29: 46109 | C29: JUNAID | D29: JUNAID KHATIK | E29: 11 | F29: 5750 | G29: =IF(E29="","",E29*F29) -> 63250 | H29: 550 | I29: =IF(G29="","",G29-IF(H29="",0,H29)) -> 62700
A30: 27 | B30: 46109 | C30: JUNAID | D30: YUNUS | E30: 10 | F30: 11500 | G30: =IF(E30="","",E30*F30) -> 115000 | H30: 2500 | I30: =IF(G30="","",G30-IF(H30="",0,H30)) -> 112500
A31: 28 | B31: 46109 | C31: JUNAID | D31: JALIL | E31: 10 | F31: 10500 | G31: =IF(E31="","",E31*F31) -> 105000 | I31: =IF(G31="","",G31-IF(H31="",0,H31)) -> 105000
A32: 29 | B32: 46109 | C32: CHINTU SHUJALPUR | D32: MANISH | E32: 18 | F32: 8750 | G32: =IF(E32="","",E32*F32) -> 157500 | I32: =IF(G32="","",G32-IF(H32="",0,H32)) -> 157500
A33: 30 | B33: 46109 | C33: CHINTU SHUJALPUR | D33: MANISH | E33: 2 | F33: 6000 | G33: =IF(E33="","",E33*F33) -> 12000 | I33: =IF(G33="","",G33-IF(H33="",0,H33)) -> 12000
A34: 31 | B34: 28 | C34: CHINTU SHUJALPUR | D34: YUNUS | E34: 2 | F34: 17000 | G34: =IF(E34="","",E34*F34) -> 34000 | I34: =IF(G34="","",G34-IF(H34="",0,H34)) -> 34000
A35: 32 | B35: 46109 | C35: GAYYUR | D35: SHAHNAWAZ | E35: 5 | F35: 4750 | G35: =IF(E35="","",E35*F35) -> 23750 | I35: =IF(G35="","",G35-IF(H35="",0,H35)) -> 23750
A36: 33 | B36: 46109 | C36: NEERAJ | D36: PAROLA | E36: 5 | F36: 8400 | G36: =IF(E36="","",E36*F36) -> 42000 | I36: =IF(G36="","",G36-IF(H36="",0,H36)) -> 42000
A37: 34 | B37: 46112 | C37: ABUL HASAN | D37: REHAN BYC | E37: 13 | F37: 17200 | G37: =IF(E37="","",E37*F37) -> 223600 | H37: 2600 | I37: =IF(G37="","",G37-IF(H37="",0,H37)) -> 221000
A38: 35 | B38: 46112 | C38: ABUL HASAN | D38: KHALIL | E38: 5 | F38: 7250 | G38: =IF(E38="","",E38*F38) -> 36250 | I38: =IF(G38="","",G38-IF(H38="",0,H38)) -> 36250
A39: 36 | B39: 46112 | C39: GAYYUR | D39: CASH SALES | E39: 1 | F39: 19000 | G39: =IF(E39="","",E39*F39) -> 19000 | I39: =IF(G39="","",G39-IF(H39="",0,H39)) -> 19000
A40: 37 | B40: 46112 | C40: GAYYUR | D40: VAZIR | E40: 15 | F40: 15500 | G40: =IF(E40="","",E40*F40) -> 232500 | I40: =IF(G40="","",G40-IF(H40="",0,H40)) -> 232500
A41: 38 | B41: 46112 | C41: GAYYUR | D41: VAZIR | E41: 1 | F41: 10000 | G41: =IF(E41="","",E41*F41) -> 10000 | I41: =IF(G41="","",G41-IF(H41="",0,H41)) -> 10000
...

Sheet Cash_Book
A1: CASH BOOK (All Transactions) | J1: CASH/BANK SUMMARY
A2: Select TYPE first → Party dropdown shows relevant list | I2: Opening Cash | J2: =Masters!$Y$6 -> 394666
A3: Sr | B3: Date | C3: Type | D3: Sub-Type | E3: Party | F3: Particulars | G3: Amount | H3: Mode | I3: Opening Bank | J3: =Masters!$Y$7 -> 724604
A4: 1 | B4: 46107 | C4: DUKANDAR | D4: RECEIPT | E4: YUNUS | G4: 15000 | H4: CASH
A5: 2 | B5: 46107 | C5: DUKANDAR | D5: RECEIPT | E5: YUNUS | F5: 55990-5000 (PAID OBO YUNUS) | G5: 50990 | H5: BANK | I5: Cash OUT | J5: =SUMIFS($G$4:$G$1008,$H$4:$H$1008,"CASH",$D$4:$D$1008,"PAYMENT")+SUMIFS($G$4:$G$1008,$H$4:$H$1008,"CASH",$D$4:$D$1008,"MOTOR")+SUMIFS($G$4:$G$1008,$H$4:$H$1008,"CASH",$D$4:$D$1008,"BHUSSA")+SUMIFS($G$4:$G$1008,$H$4:$H$1008,"CASH",$D$4:$D$1008,"GAWALI")+SUMIFS($G$4:$G$1008,$H$4:$H$1008,"CASH",$D$4:$D$1008,"CASH_ADV")+SUMIFS($G$4:$G$1008,$H$4:$H$1008,"CASH",$D$4:$D$1008,"DISCOUNT")+SUMIFS($G$4:$G$1008,$H$4:$H$1008,"CASH",$D$4:$D$1008,"WITHDRAWN")+SUMIFS($G$4:$G$1008,$H$4:$H$1008,"CASH",$D$4:$D$1008,"REPAID")+SUMIFS($G$4:$G$1008,$H$4:$H$1008,"CASH",$D$4:$D$1008,"GIVEN")+SUMIFS($G$4:$G$1008,$H$4:$H$1008,"CASH",$D$4:$D$1008,"MANDI")+SUMIFS($G$4:$G$1008,$H$4:$H$1008,"CASH",$D$4:$D$1008,"TRAVEL")+SUMIFS($G$4:$G$1008,$H$4:$H$1008,"CASH",$D$4:$D$1008,"FOOD")+SUMIFS($G$4:$G$1008,$H$4:$H$1008,"CASH",$D$4:$D$1008,"SALARY")+SUMIFS($G$4:$G$1008,$H$4:$H$1008,"CASH",$D$4:$D$1008,"BF_DISC")+SUMIFS($G$4:$G$1008,$H$4:$H$1008,"CASH",$D$4:$D$1008,"JB_PAID")+SUMIFS($G$4:$G$1008,$H$4:$H$1008,"CASH",$D$4:$D$1008,"MHN_PERSONAL")+SUMIFS($G$4:$G$1008,$H$4:$H$1008,"CASH",$D$4:$D$1008,"PAID")+SUMIFS($G$4:$G$1008,$H$4:$H$1008,"CASH",$D$4:$D$1008,"MISC")+SUMIFS($G$4:$G$1008,$H$4:$H$1008,"CASH",$D$4:$D$1008,"OTHER") -> 2841919
A6: 3 | B6: 46107 | C6: DUKANDAR | D6: RECEIPT | E6: NADEEM BHIWANDI | G6: 79687 | H6: BANK | I6: Bank OUT | J6: =SUMIFS($G$4:$G$1008,$H$4:$H$1008,"BANK",$D$4:$D$1008,"PAYMENT")+SUMIFS($G$4:$G$1008,$H$4:$H$1008,"BANK",$D$4:$D$1008,"MOTOR")+SUMIFS($G$4:$G$1008,$H$4:$H$1008,"BANK",$D$4:$D$1008,"BHUSSA")+SUMIFS($G$4:$G$1008,$H$4:$H$1008,"BANK",$D$4:$D$1008,"GAWALI")+SUMIFS($G$4:$G$1008,$H$4:$H$1008,"BANK",$D$4:$D$1008,"CASH_ADV")+SUMIFS($G$4:$G$1008,$H$4:$H$1008,"BANK",$D$4:$D$1008,"DISCOUNT")+SUMIFS($G$4:$G$1008,$H$4:$H$1008,"BANK",$D$4:$D$1008,"WITHDRAWN")+SUMIFS($G$4:$G$1008,$H$4:$H$1008,"BANK",$D$4:$D$1008,"REPAID")+SUMIFS($G$4:$G$1008,$H$4:$H$1008,"BANK",$D$4:$D$1008,"GIVEN")+SUMIFS($G$4:$G$1008,$H$4:$H$1008,"BANK",$D$4:$D$1008,"MANDI")+SUMIFS($G$4:$G$1008,$H$4:$H$1008,"BANK",$D$4:$D$1008,"TRAVEL")+SUMIFS($G$4:$G$1008,$H$4:$H$1008,"BANK",$D$4:$D$1008,"FOOD")+SUMIFS($G$4:$G$1008,$H$4:$H$1008,"BANK",$D$4:$D$1008,"SALARY")+SUMIFS($G$4:$G$1008,$H$4:$H$1008,"BANK",$D$4:$D$1008,"BF_DISC")+SUMIFS($G$4:$G$1008,$H$4:$H$1008,"BANK",$D$4:$D$1008,"JB_PAID")+SUMIFS($G$4:$G$1008,$H$4:$H$1008,"BANK",$D$4:$D$1008,"MHN_PERSONAL")+SUMIFS($G$4:$G$1008,$H$4:$H$1008,"BANK",$D$4:$D$1008,"PAID")+SUMIFS($G$4:$G$1008,$H$4:$H$1008,"BANK",$D$4:$D$1008,"MISC")+SUMIFS($G$4:$G$1008,$H$4:$H$1008,"BANK",$D$4:$D$1008,"OTHER")+SUMIFS($G$4:$G$1008,$H$4:$H$1008,"UPI",$D$4:$D$1008,"PAYMENT")+SUMIFS($G$4:$G$1008,$H$4:$H$1008,"UPI",$D$4:$D$1008,"MOTOR")+SUMIFS($G$4:$G$1008,$H$4:$H$1008,"UPI",$D$4:$D$1008,"BHUSSA")+SUMIFS($G$4:$G$1008,$H$4:$H$1008,"UPI",$D$4:$D$1008,"GAWALI")+SUMIFS($G$4:$G$1008,$H$4:$H$1008,"UPI",$D$4:$D$1008,"CASH_ADV")+SUMIFS($G$4:$G$1008,$H$4:$H$1008,"UPI",$D$4:$D$1008,"DISCOUNT")+SUMIFS($G$4:$G$1008,$H$4:$H$1008,"UPI",$D$4:$D$1008,"WITHDRAWN")+SUMIFS($G$4:$G$1008,$H$4:$H$1008,"UPI",$D$4:$D$1008,"REPAID")+SUMIFS($G$4:$G$1008,$H$4:$H$1008,"UPI",$D$4:$D$1008,"GIVEN")+SUMIFS($G$4:$G$1008,$H$4:$H$1008,"UPI",$D$4:$D$1008,"MANDI")+SUMIFS($G$4:$G$1008,$H$4:$H$1008,"UPI",$D$4:$D$1008,"TRAVEL")+SUMIFS($G$4:$G$1008,$H$4:$H$1008,"UPI",$D$4:$D$1008,"FOOD")+SUMIFS($G$4:$G$1008,$H$4:$H$1008,"UPI",$D$4:$D$1008,"SALARY")+SUMIFS($G$4:$G$1008,$H$4:$H$1008,"UPI",$D$4:$D$1008,"BF_DISC")+SUMIFS($G$4:$G$1008,$H$4:$H$1008,"UPI",$D$4:$D$1008,"JB_PAID")+SUMIFS($G$4:$G$1008,$H$4:$H$1008,"UPI",$D$4:$D$1008,"MHN_PERSONAL")+SUMIFS($G$4:$G$1008,$H$4:$H$1008,"UPI",$D$4:$D$1008,"PAID")+SUMIFS($G$4:$G$1008,$H$4:$H$1008,"UPI",$D$4:$D$1008,"MISC")+SUMIFS($G$4:$G$1008,$H$4:$H$1008,"UPI",$D$4:$D$1008,"OTHER")+SUMIFS($G$4:$G$1008,$H$4:$H$1008,"TRANSFER",$D$4:$D$1008,"PAYMENT")+SUMIFS($G$4:$G$1008,$H$4:$H$1008,"TRANSFER",$D$4:$D$1008,"MOTOR")+SUMIFS($G$4:$G$1008,$H$4:$H$1008,"TRANSFER",$D$4:$D$1008,"BHUSSA")+SUMIFS($G$4:$G$1008,$H$4:$H$1008,"TRANSFER",$D$4:$D$1008,"GAWALI")+SUMIFS($G$4:$G$1008,$H$4:$H$1008,"TRANSFER",$D$4:$D$1008,"CASH_ADV")+SUMIFS($G$4:$G$1008,$H$4:$H$1008,"TRANSFER",$D$4:$D$1008,"DISCOUNT")+SUMIFS($G$4:$G$1008,$H$4:$H$1008,"TRANSFER",$D$4:$D$1008,"WITHDRAWN")+SUMIFS($G$4:$G$1008,$H$4:$H$1008,"TRANSFER",$D$4:$D$1008,"REPAID")+SUMIFS($G$4:$G$1008,$H$4:$H$1008,"TRANSFER",$D$4:$D$1008,"GIVEN")+SUMIFS($G$4:$G$1008,$H$4:$H$1008,"TRANSFER",$D$4:$D$1008,"MANDI")+SUMIFS($G$4:$G$1008,$H$4:$H$1008,"TRANSFER",$D$4:$D$1008,"TRAVEL")+SUMIFS($G$4:$G$1008,$H$4:$H$1008,"TRANSFER",$D$4:$D$1008,"FOOD")+SUMIFS($G$4:$G$1008,$H$4:$H$1008,"TRANSFER",$D$4:$D$1008,"SALARY")+SUMIFS($G$4:$G$1008,$H$4:$H$1008,"TRANSFER",$D$4:$D$1008,"BF_DISC")+SUMIFS($G$4:$G$1008,$H$4:$H$1008,"TRANSFER",$D$4:$D$1008,"JB_PAID")+SUMIFS($G$4:$G$1008,$H$4:$H$1008,"TRANSFER",$D$4:$D$1008,"MHN_PERSONAL")+SUMIFS($G$4:$G$1008,$H$4:$H$1008,"TRANSFER",$D$4:$D$1008,"PAID")+SUMIFS($G$4:$G$1008,$H$4:$H$1008,"TRANSFER",$D$4:$D$1008,"MISC")+SUMIFS($G$4:$G$1008,$H$4:$H$1008,"TRANSFER",$D$4:$D$1008,"OTHER") -> 1507354
A7: 4 | B7: 46107 | C7: DUKANDAR | D7: RECEIPT | E7: MEHBOOB JOG | G7: 50000 | H7: CASH | I7: Cash IN | J7: =SUMIFS($G$4:$G$1008,$H$4:$H$1008,"CASH",$D$4:$D$1008,"RECEIPT")+SUMIFS($G$4:$G$1008,$H$4:$H$1008,"CASH",$D$4:$D$1008,"TAKEN")+SUMIFS($G$4:$G$1008,$H$4:$H$1008,"CASH",$D$4:$D$1008,"RECEIVED")+SUMIFS($G$4:$G$1008,$H$4:$H$1008,"CASH",$D$4:$D$1008,"PROVISION") -> 2833988
A8: 5 | B8: 46107 | C8: DUKANDAR | D8: RECEIPT | E8: MEHBOOB JOG | G8: 15000 | H8: BANK | I8: Bank IN | J8: =SUMIFS($G$4:$G$1008,$H$4:$H$1008,"BANK",$D$4:$D$1008,"RECEIPT")+SUMIFS($G$4:$G$1008,$H$4:$H$1008,"BANK",$D$4:$D$1008,"TAKEN")+SUMIFS($G$4:$G$1008,$H$4:$H$1008,"BANK",$D$4:$D$1008,"RECEIVED")+SUMIFS($G$4:$G$1008,$H$4:$H$1008,"BANK",$D$4:$D$1008,"PROVISION")+SUMIFS($G$4:$G$1008,$H$4:$H$1008,"UPI",$D$4:$D$1008,"RECEIPT")+SUMIFS($G$4:$G$1008,$H$4:$H$1008,"UPI",$D$4:$D$1008,"TAKEN")+SUMIFS($G$4:$G$1008,$H$4:$H$1008,"UPI",$D$4:$D$1008,"RECEIVED")+SUMIFS($G$4:$G$1008,$H$4:$H$1008,"UPI",$D$4:$D$1008,"PROVISION")+SUMIFS($G$4:$G$1008,$H$4:$H$1008,"TRANSFER",$D$4:$D$1008,"RECEIPT")+SUMIFS($G$4:$G$1008,$H$4:$H$1008,"TRANSFER",$D$4:$D$1008,"TAKEN")+SUMIFS($G$4:$G$1008,$H$4:$H$1008,"TRANSFER",$D$4:$D$1008,"RECEIVED")+SUMIFS($G$4:$G$1008,$H$4:$H$1008,"TRANSFER",$D$4:$D$1008,"PROVISION") -> 1319978
A9: 6 | B9: 46107 | C9: DUKANDAR | D9: RECEIPT | E9: ISLAM D | G9: 50000 | H9: BANK
A10: 7 | B10: 46107 | C10: DUKANDAR | D10: RECEIPT | E10: ISLAM D | G10: 50000 | H10: BANK | I10: CLOSING CASH | J10: =J2-J5+J7 -> 386735
A11: 8 | B11: 46107 | C11: DUKANDAR | D11: RECEIPT | E11: ARIF | G11: 100000 | H11: BANK | I11: CLOSING BANK | J11: =J3-J6+J8 -> 537228
A12: 9 | B12: 46107 | C12: DUKANDAR | D12: RECEIPT | E12: SAKIM | G12: 50000 | H12: BANK
A13: 10 | B13: 46107 | C13: DUKANDAR | D13: RECEIPT | E13: RAFIQ AHMED HAJI | G13: 100 | H13: BANK
A14: 11 | B14: 46107 | C14: DUKANDAR | D14: RECEIPT | E14: RAFIQ AHMED HAJI | G14: 100 | H14: BANK
A15: 12 | B15: 46107 | C15: DUKANDAR | D15: RECEIPT | E15: RAFIQ AHMED HAJI | G15: 49800 | H15: BANK
A16: 13 | B16: 46107 | C16: DUKANDAR | D16: RECEIPT | E16: RAFIQ AHMED HAJI | G16: 100 | H16: BANK
A17: 14 | B17: 46107 | C17: DUKANDAR | D17: RECEIPT | E17: RAFIQ AHMED HAJI | G17: 49900 | H17: BANK
A18: 15 | B18: 46107 | C18: DUKANDAR | D18: RECEIPT | E18: RAFIQ AHMED HAJI | F18: GPAY TO KMN | G18: 50000 | H18: CASH
A19: 16 | B19: 46107 | C19: DUKANDAR | D19: RECEIPT | E19: RAFIQ AHMED HAJI | F19: GPAY TO AYAAN | G19: 50000 | H19: CASH
A20: 17 | B20: 46107 | C20: ADVANCE | D20: GIVEN | E20: KMN | F20: C/O RAFIQ AHMED HAJI | G20: 50000 | H20: CASH
A21: 18 | B21: 46107 | C21: ADVANCE | D21: GIVEN | E21: AYAAN | F21: C/O RAFIQ AHMED HAJI | G21: 50000 | H21: CASH
A22: 19 | B22: 46107 | C22: DUKANDAR | D22: RECEIPT | E22: JAFER KASHIMIRA | G22: 50000 | H22: CASH
A23: 20 | B23: 46107 | C23: DUKANDAR | D23: RECEIPT | E23: NAWAZ V | G23: 148800 | H23: CASH
A24: 21 | B24: 46107 | C24: DUKANDAR | D24: RECEIPT | E24: CASH SALES | G24: 85000 | H24: CASH
A25: 22 | B25: 46107 | C25: DUKANDAR | D25: BF_DISC | E25: CASH SALES | G25: 200 | H25: CASH
A26: 23 | B26: 46107 | C26: ADVANCE | D26: RECEIVED | E26: SHAKIL GHODEGAON | G26: 100000 | H26: CASH
A27: 24 | B27: 46107 | C27: DUKANDAR | D27: RECEIPT | E27: MEHMOOD MADH | G27: 20000 | H27: CASH
A28: 25 | B28: 46107 | C28: DUKANDAR | D28: RECEIPT | E28: SHARIK | G28: 150000 | H28: CASH
A29: 26 | B29: 46107 | C29: ADVANCE | D29: RECEIVED | E29: AYAAN | F29: PAID TO JUNAID | G29: 100000 | H29: CASH
A30: 27 | B30: 46107 | C30: ADVANCE | D30: RECEIVED | E30: AYAAN | G30: 100000 | H30: CASH
A31: 28 | B31: 46106 | C31: BEPAARI | D31: PAYMENT | E31: ABUL HASAN | G31: 7550 | H31: BANK
A32: 29 | B32: 46107 | C32: EXPENSE | D32: TRAVEL | F32: OLA | G32: 750 | H32: BANK
A33: 30 | B33: 46107 | C33: BEPAARI | D33: PAYMENT | E33: USMAN | G33: 40000 | H33: BANK
A34: 31 | B34: 46107 | C34: BEPAARI | D34: MOTOR | E34: ANAS RAJ | G34: 7920 | H34: BANK
A35: 32 | B35: 46107 | C35: BEPAARI | D35: MOTOR | E35: SHARIF RAJ | G35: 2640 | H35: BANK
A36: 33 | B36: 46107 | C36: BEPAARI | D36: MOTOR | E36: JUNAID | G36: 5520 | H36: BANK
A37: 34 | B37: 46107 | C37: BEPAARI | D37: MOTOR | E37: CHINTU SHUJALPUR | G37: 7200 | H37: BANK
A38: 35 | B38: 46107 | C38: BEPAARI | D38: PAYMENT | E38: ABUL HASAN | G38: 100000 | H38: BANK
A39: 36 | B39: 46107 | C39: EXPENSE | D39: TRAVEL | F39: OLA | G39: 693 | H39: BANK
A40: 37 | B40: 46107 | C40: BEPAARI | D40: PAYMENT | E40: JUNAID | G40: 50000 | H40: CASH
...

Sheet Bepaari_Ledger
A1: BEPAARI LEDGER
A2: Commission = Flat ₹/Goat if set, otherwise Comm%
A4: Sr | B4: Bepaari | C4: Comm% | D4: Flat₹ | E4: Opening | F4: Gross Sales | G4: Qty | H4: Commission | I4: KK | J4: JB | K4: Motor | L4: Bhussa | M4: Gawali | N4: Cash/Adv | O4: Other | P4: Tot.Deduct | Q4: Net Payable | R4: Payments | S4: BALANCE
A5: 1 | B5: =IF(Masters!$B$3="","",Masters!$B$3) -> ABUL HASAN | C5: =IF(B5="","",Masters!$C$3) -> 4 | D5: =IF(B5="","",IF(Masters!$D$3="","",Masters!$D$3)) | E5: =IF(B5="",0,Masters!$E$3) -> 7550 | F5: =SUMIF(Daily_Sales!$C$4:$C$503,B5,Daily_Sales!$G$4:$G$503) -> 742000 | G5: =SUMIF(Daily_Sales!$C$4:$C$503,B5,Daily_Sales!$E$4:$E$503) -> 62 | H5: =IF(B5="",0,IF(D5<>"",D5*G5,F5*C5/100)) -> 29680 | I5: =IF(G5>0,Masters!$Y$3,0) -> 100 | J5: =G5*Masters!$Y$4 -> 620 | K5: =SUMIFS(Cash_Book!$G$4:$G$1008,Cash_Book!$C$4:$C$1008,"BEPAARI",Cash_Book!$D$4:$D$1008,"MOTOR",Cash_Book!$E$4:$E$1008,B5) -> 15120 | L5: =SUMIFS(Cash_Book!$G$4:$G$1008,Cash_Book!$C$4:$C$1008,"BEPAARI",Cash_Book!$D$4:$D$1008,"BHUSSA",Cash_Book!$E$4:$E$1008,B5) -> 300 | M5: =SUMIFS(Cash_Book!$G$4:$G$1008,Cash_Book!$C$4:$C$1008,"BEPAARI",Cash_Book!$D$4:$D$1008,"GAWALI",Cash_Book!$E$4:$E$1008,B5) -> 3780 | N5: =SUMIFS(Cash_Book!$G$4:$G$1008,Cash_Book!$C$4:$C$1008,"BEPAARI",Cash_Book!$D$4:$D$1008,"CASH_ADV",Cash_Book!$E$4:$E$1008,B5) -> 0 | O5: =SUMIFS(Cash_Book!$G$4:$G$1008,Cash_Book!$C$4:$C$1008,"BEPAARI",Cash_Book!$D$4:$D$1008,"OTHER",Cash_Book!$E$4:$E$1008,B5) -> 0 | P5: =SUM(H5:O5) -> 49600 | Q5: =IF(B5="","",F5-P5+E5) -> 699950 | R5: =SUMIFS(Cash_Book!$G$4:$G$1008,Cash_Book!$C$4:$C$1008,"BEPAARI",Cash_Book!$D$4:$D$1008,"PAYMENT",Cash_Book!$E$4:$E$1008,B5) -> 556524 | S5: =IF(B5="","",Q5-R5) -> 143426
A6: 2 | B6: =IF(Masters!$B$4="","",Masters!$B$4) -> SHARAFAT | C6: =IF(B6="","",Masters!$C$4) -> 4 | D6: =IF(B6="","",IF(Masters!$D$4="","",Masters!$D$4)) | E6: =IF(B6="",0,Masters!$E$4) -> 0 | F6: =SUMIF(Daily_Sales!$C$4:$C$503,B6,Daily_Sales!$G$4:$G$503) -> 0 | G6: =SUMIF(Daily_Sales!$C$4:$C$503,B6,Daily_Sales!$E$4:$E$503) -> 0 | H6: =IF(B6="",0,IF(D6<>"",D6*G6,F6*C6/100)) -> 0 | I6: =IF(G6>0,Masters!$Y$3,0) -> 0 | J6: =G6*Masters!$Y$4 -> 0 | K6: =SUMIFS(Cash_Book!$G$4:$G$1008,Cash_Book!$C$4:$C$1008,"BEPAARI",Cash_Book!$D$4:$D$1008,"MOTOR",Cash_Book!$E$4:$E$1008,B6) -> 0 | L6: =SUMIFS(Cash_Book!$G$4:$G$1008,Cash_Book!$C$4:$C$1008,"BEPAARI",Cash_Book!$D$4:$D$1008,"BHUSSA",Cash_Book!$E$4:$E$1008,B6) -> 0 | M6: =SUMIFS(Cash_Book!$G$4:$G$1008,Cash_Book!$C$4:$C$1008,"BEPAARI",Cash_Book!$D$4:$D$1008,"GAWALI",Cash_Book!$E$4:$E$1008,B6) -> 0 | N6: =SUMIFS(Cash_Book!$G$4:$G$1008,Cash_Book!$C$4:$C$1008,"BEPAARI",Cash_Book!$D$4:$D$1008,"CASH_ADV",Cash_Book!$E$4:$E$1008,B6) -> 0 | O6: =SUMIFS(Cash_Book!$G$4:$G$1008,Cash_Book!$C$4:$C$1008,"BEPAARI",Cash_Book!$D$4:$D$1008,"OTHER",Cash_Book!$E$4:$E$1008,B6) -> 0 | P6: =SUM(H6:O6) -> 0 | Q6: =IF(B6="","",F6-P6+E6) -> 0 | R6: =SUMIFS(Cash_Book!$G$4:$G$1008,Cash_Book!$C$4:$C$1008,"BEPAARI",Cash_Book!$D$4:$D$1008,"PAYMENT",Cash_Book!$E$4:$E$1008,B6) -> 0 | S6: =IF(B6="","",Q6-R6) -> 0
A7: 3 | B7: =IF(Masters!$B$5="","",Masters!$B$5) -> JUNAID | C7: =IF(B7="","",Masters!$C$5) -> 4 | D7: =IF(B7="","",IF(Masters!$D$5="","",Masters!$D$5)) | E7: =IF(B7="",0,Masters!$E$5) -> 0 | F7: =SUMIF(Daily_Sales!$C$4:$C$503,B7,Daily_Sales!$G$4:$G$503) -> 858950 | G7: =SUMIF(Daily_Sales!$C$4:$C$503,B7,Daily_Sales!$E$4:$E$503) -> 94 | H7: =IF(B7="",0,IF(D7<>"",D7*G7,F7*C7/100)) -> 34358 | I7: =IF(G7>0,Masters!$Y$3,0) -> 100 | J7: =G7*Masters!$Y$4 -> 940 | K7: =SUMIFS(Cash_Book!$G$4:$G$1008,Cash_Book!$C$4:$C$1008,"BEPAARI",Cash_Book!$D$4:$D$1008,"MOTOR",Cash_Book!$E$4:$E$1008,B7) -> 11760 | L7: =SUMIFS(Cash_Book!$G$4:$G$1008,Cash_Book!$C$4:$C$1008,"BEPAARI",Cash_Book!$D$4:$D$1008,"BHUSSA",Cash_Book!$E$4:$E$1008,B7) -> 250 | M7: =SUMIFS(Cash_Book!$G$4:$G$1008,Cash_Book!$C$4:$C$1008,"BEPAARI",Cash_Book!$D$4:$D$1008,"GAWALI",Cash_Book!$E$4:$E$1008,B7) -> 5640 | N7: =SUMIFS(Cash_Book!$G$4:$G$1008,Cash_Book!$C$4:$C$1008,"BEPAARI",Cash_Book!$D$4:$D$1008,"CASH_ADV",Cash_Book!$E$4:$E$1008,B7) -> 0 | O7: =SUMIFS(Cash_Book!$G$4:$G$1008,Cash_Book!$C$4:$C$1008,"BEPAARI",Cash_Book!$D$4:$D$1008,"OTHER",Cash_Book!$E$4:$E$1008,B7) -> 0 | P7: =SUM(H7:O7) -> 53048 | Q7: =IF(B7="","",F7-P7+E7) -> 805902 | R7: =SUMIFS(Cash_Book!$G$4:$G$1008,Cash_Book!$C$4:$C$1008,"BEPAARI",Cash_Book!$D$4:$D$1008,"PAYMENT",Cash_Book!$E$4:$E$1008,B7) -> 610500 | S7: =IF(B7="","",Q7-R7) -> 195402
A8: 4 | B8: =IF(Masters!$B$6="","",Masters!$B$6) -> ANNU SHARIF | C8: =IF(B8="","",Masters!$C$6) -> 4 | D8: =IF(B8="","",IF(Masters!$D$6="","",Masters!$D$6)) | E8: =IF(B8="",0,Masters!$E$6) -> 0 | F8: =SUMIF(Daily_Sales!$C$4:$C$503,B8,Daily_Sales!$G$4:$G$503) -> 0 | G8: =SUMIF(Daily_Sales!$C$4:$C$503,B8,Daily_Sales!$E$4:$E$503) -> 0 | H8: =IF(B8="",0,IF(D8<>"",D8*G8,F8*C8/100)) -> 0 | I8: =IF(G8>0,Masters!$Y$3,0) -> 0 | J8: =G8*Masters!$Y$4 -> 0 | K8: =SUMIFS(Cash_Book!$G$4:$G$1008,Cash_Book!$C$4:$C$1008,"BEPAARI",Cash_Book!$D$4:$D$1008,"MOTOR",Cash_Book!$E$4:$E$1008,B8) -> 0 | L8: =SUMIFS(Cash_Book!$G$4:$G$1008,Cash_Book!$C$4:$C$1008,"BEPAARI",Cash_Book!$D$4:$D$1008,"BHUSSA",Cash_Book!$E$4:$E$1008,B8) -> 0 | M8: =SUMIFS(Cash_Book!$G$4:$G$1008,Cash_Book!$C$4:$C$1008,"BEPAARI",Cash_Book!$D$4:$D$1008,"GAWALI",Cash_Book!$E$4:$E$1008,B8) -> 0 | N8: =SUMIFS(Cash_Book!$G$4:$G$1008,Cash_Book!$C$4:$C$1008,"BEPAARI",Cash_Book!$D$4:$D$1008,"CASH_ADV",Cash_Book!$E$4:$E$1008,B8) -> 0 | O8: =SUMIFS(Cash_Book!$G$4:$G$1008,Cash_Book!$C$4:$C$1008,"BEPAARI",Cash_Book!$D$4:$D$1008,"OTHER",Cash_Book!$E$4:$E$1008,B8) -> 0 | P8: =SUM(H8:O8) -> 0 | Q8: =IF(B8="","",F8-P8+E8) -> 0 | R8: =SUMIFS(Cash_Book!$G$4:$G$1008,Cash_Book!$C$4:$C$1008,"BEPAARI",Cash_Book!$D$4:$D$1008,"PAYMENT",Cash_Book!$E$4:$E$1008,B8) -> 0 | S8: =IF(B8="","",Q8-R8) -> 0
A9: 5 | B9: =IF(Masters!$B$7="","",Masters!$B$7) -> GAYYUR | C9: =IF(B9="","",Masters!$C$7) -> 4 | D9: =IF(B9="","",IF(Masters!$D$7="","",Masters!$D$7)) | E9: =IF(B9="",0,Masters!$E$7) -> 142530 | F9: =SUMIF(Daily_Sales!$C$4:$C$503,B9,Daily_Sales!$G$4:$G$503) -> 439750 | G9: =SUMIF(Daily_Sales!$C$4:$C$503,B9,Daily_Sales!$E$4:$E$503) -> 37 | H9: =IF(B9="",0,IF(D9<>"",D9*G9,F9*C9/100)) -> 17590 | I9: =IF(G9>0,Masters!$Y$3,0) -> 100 | J9: =G9*Masters!$Y$4 -> 370 | K9: =SUMIFS(Cash_Book!$G$4:$G$1008,Cash_Book!$C$4:$C$1008,"BEPAARI",Cash_Book!$D$4:$D$1008,"MOTOR",Cash_Book!$E$4:$E$1008,B9) -> 10320 | L9: =SUMIFS(Cash_Book!$G$4:$G$1008,Cash_Book!$C$4:$C$1008,"BEPAARI",Cash_Book!$D$4:$D$1008,"BHUSSA",Cash_Book!$E$4:$E$1008,B9) -> 0 | M9: =SUMIFS(Cash_Book!$G$4:$G$1008,Cash_Book!$C$4:$C$1008,"BEPAARI",Cash_Book!$D$4:$D$1008,"GAWALI",Cash_Book!$E$4:$E$1008,B9) -> 8660 | N9: =SUMIFS(Cash_Book!$G$4:$G$1008,Cash_Book!$C$4:$C$1008,"BEPAARI",Cash_Book!$D$4:$D$1008,"CASH_ADV",Cash_Book!$E$4:$E$1008,B9) -> 0 | O9: =SUMIFS(Cash_Book!$G$4:$G$1008,Cash_Book!$C$4:$C$1008,"BEPAARI",Cash_Book!$D$4:$D$1008,"OTHER",Cash_Book!$E$4:$E$1008,B9) -> 0 | P9: =SUM(H9:O9) -> 37040 | Q9: =IF(B9="","",F9-P9+E9) -> 545240 | R9: =SUMIFS(Cash_Book!$G$4:$G$1008,Cash_Book!$C$4:$C$1008,"BEPAARI",Cash_Book!$D$4:$D$1008,"PAYMENT",Cash_Book!$E$4:$E$1008,B9) -> 282530 | S9: =IF(B9="","",Q9-R9) -> 262710
A10: 6 | B10: =IF(Masters!$B$8="","",Masters!$B$8) -> KISHOR | C10: =IF(B10="","",Masters!$C$8) -> 4 | D10: =IF(B10="","",IF(Masters!$D$8="","",Masters!$D$8)) | E10: =IF(B10="",0,Masters!$E$8) -> -152964 | F10: =SUMIF(Daily_Sales!$C$4:$C$503,B10,Daily_Sales!$G$4:$G$503) -> 464000 | G10: =SUMIF(Daily_Sales!$C$4:$C$503,B10,Daily_Sales!$E$4:$E$503) -> 32 | H10: =IF(B10="",0,IF(D10<>"",D10*G10,F10*C10/100)) -> 18560 | I10: =IF(G10>0,Masters!$Y$3,0) -> 100 | J10: =G10*Masters!$Y$4 -> 320 | K10: =SUMIFS(Cash_Book!$G$4:$G$1008,Cash_Book!$C$4:$C$1008,"BEPAARI",Cash_Book!$D$4:$D$1008,"MOTOR",Cash_Book!$E$4:$E$1008,B10) -> 7680 | L10: =SUMIFS(Cash_Book!$G$4:$G$1008,Cash_Book!$C$4:$C$1008,"BEPAARI",Cash_Book!$D$4:$D$1008,"BHUSSA",Cash_Book!$E$4:$E$1008,B10) -> 150 | M10: =SUMIFS(Cash_Book!$G$4:$G$1008,Cash_Book!$C$4:$C$1008,"BEPAARI",Cash_Book!$D$4:$D$1008,"GAWALI",Cash_Book!$E$4:$E$1008,B10) -> 1920 | N10: =SUMIFS(Cash_Book!$G$4:$G$1008,Cash_Book!$C$4:$C$1008,"BEPAARI",Cash_Book!$D$4:$D$1008,"CASH_ADV",Cash_Book!$E$4:$E$1008,B10) -> 0 | O10: =SUMIFS(Cash_Book!$G$4:$G$1008,Cash_Book!$C$4:$C$1008,"BEPAARI",Cash_Book!$D$4:$D$1008,"OTHER",Cash_Book!$E$4:$E$1008,B10) -> 0 | P10: =SUM(H10:O10) -> 28730 | Q10: =IF(B10="","",F10-P10+E10) -> 282306 | R10: =SUMIFS(Cash_Book!$G$4:$G$1008,Cash_Book!$C$4:$C$1008,"BEPAARI",Cash_Book!$D$4:$D$1008,"PAYMENT",Cash_Book!$E$4:$E$1008,B10) -> 280000 | S10: =IF(B10="","",Q10-R10) -> 2306
A11: 7 | B11: =IF(Masters!$B$9="","",Masters!$B$9) -> MAULANA | C11: =IF(B11="","",Masters!$C$9) -> 4 | D11: =IF(B11="","",IF(Masters!$D$9="","",Masters!$D$9)) | E11: =IF(B11="",0,Masters!$E$9) -> 35330 | F11: =SUMIF(Daily_Sales!$C$4:$C$503,B11,Daily_Sales!$G$4:$G$503) -> 444350 | G11: =SUMIF(Daily_Sales!$C$4:$C$503,B11,Daily_Sales!$E$4:$E$503) -> 41 | H11: =IF(B11="",0,IF(D11<>"",D11*G11,F11*C11/100)) -> 17774 | I11: =IF(G11>0,Masters!$Y$3,0) -> 100 | J11: =G11*Masters!$Y$4 -> 410 | K11: =SUMIFS(Cash_Book!$G$4:$G$1008,Cash_Book!$C$4:$C$1008,"BEPAARI",Cash_Book!$D$4:$D$1008,"MOTOR",Cash_Book!$E$4:$E$1008,B11) -> 10100 | L11: =SUMIFS(Cash_Book!$G$4:$G$1008,Cash_Book!$C$4:$C$1008,"BEPAARI",Cash_Book!$D$4:$D$1008,"BHUSSA",Cash_Book!$E$4:$E$1008,B11) -> 0 | M11: =SUMIFS(Cash_Book!$G$4:$G$1008,Cash_Book!$C$4:$C$1008,"BEPAARI",Cash_Book!$D$4:$D$1008,"GAWALI",Cash_Book!$E$4:$E$1008,B11) -> 2460 | N11: =SUMIFS(Cash_Book!$G$4:$G$1008,Cash_Book!$C$4:$C$1008,"BEPAARI",Cash_Book!$D$4:$D$1008,"CASH_ADV",Cash_Book!$E$4:$E$1008,B11) -> 0 | O11: =SUMIFS(Cash_Book!$G$4:$G$1008,Cash_Book!$C$4:$C$1008,"BEPAARI",Cash_Book!$D$4:$D$1008,"OTHER",Cash_Book!$E$4:$E$1008,B11) -> 0 | P11: =SUM(H11:O11) -> 30844 | Q11: =IF(B11="","",F11-P11+E11) -> 448836 | R11: =SUMIFS(Cash_Book!$G$4:$G$1008,Cash_Book!$C$4:$C$1008,"BEPAARI",Cash_Book!$D$4:$D$1008,"PAYMENT",Cash_Book!$E$4:$E$1008,B11) -> 300000 | S11: =IF(B11="","",Q11-R11) -> 148836
A12: 8 | B12: =IF(Masters!$B$10="","",Masters!$B$10) -> SALIM RAJ | C12: =IF(B12="","",Masters!$C$10) -> 4 | D12: =IF(B12="","",IF(Masters!$D$10="","",Masters!$D$10)) | E12: =IF(B12="",0,Masters!$E$10) -> 0 | F12: =SUMIF(Daily_Sales!$C$4:$C$503,B12,Daily_Sales!$G$4:$G$503) -> 195500 | G12: =SUMIF(Daily_Sales!$C$4:$C$503,B12,Daily_Sales!$E$4:$E$503) -> 17 | H12: =IF(B12="",0,IF(D12<>"",D12*G12,F12*C12/100)) -> 7820 | I12: =IF(G12>0,Masters!$Y$3,0) -> 100 | J12: =G12*Masters!$Y$4 -> 170 | K12: =SUMIFS(Cash_Book!$G$4:$G$1008,Cash_Book!$C$4:$C$1008,"BEPAARI",Cash_Book!$D$4:$D$1008,"MOTOR",Cash_Book!$E$4:$E$1008,B12) -> 4080 | L12: =SUMIFS(Cash_Book!$G$4:$G$1008,Cash_Book!$C$4:$C$1008,"BEPAARI",Cash_Book!$D$4:$D$1008,"BHUSSA",Cash_Book!$E$4:$E$1008,B12) -> 0 | M12: =SUMIFS(Cash_Book!$G$4:$G$1008,Cash_Book!$C$4:$C$1008,"BEPAARI",Cash_Book!$D$4:$D$1008,"GAWALI",Cash_Book!$E$4:$E$1008,B12) -> 1020 | N12: =SUMIFS(Cash_Book!$G$4:$G$1008,Cash_Book!$C$4:$C$1008,"BEPAARI",Cash_Book!$D$4:$D$1008,"CASH_ADV",Cash_Book!$E$4:$E$1008,B12) -> 0 | O12: =SUMIFS(Cash_Book!$G$4:$G$1008,Cash_Book!$C$4:$C$1008,"BEPAARI",Cash_Book!$D$4:$D$1008,"OTHER",Cash_Book!$E$4:$E$1008,B12) -> 0 | P12: =SUM(H12:O12) -> 13190 | Q12: =IF(B12="","",F12-P12+E12) -> 182310 | R12: =SUMIFS(Cash_Book!$G$4:$G$1008,Cash_Book!$C$4:$C$1008,"BEPAARI",Cash_Book!$D$4:$D$1008,"PAYMENT",Cash_Book!$E$4:$E$1008,B12) -> 0 | S12: =IF(B12="","",Q12-R12) -> 182310
A13: 9 | B13: =IF(Masters!$B$11="","",Masters!$B$11) -> ANAS RAJ | C13: =IF(B13="","",Masters!$C$11) -> 4 | D13: =IF(B13="","",IF(Masters!$D$11="","",Masters!$D$11)) | E13: =IF(B13="",0,Masters!$E$11) -> 0 | F13: =SUMIF(Daily_Sales!$C$4:$C$503,B13,Daily_Sales!$G$4:$G$503) -> 334600 | G13: =SUMIF(Daily_Sales!$C$4:$C$503,B13,Daily_Sales!$E$4:$E$503) -> 33 | H13: =IF(B13="",0,IF(D13<>"",D13*G13,F13*C13/100)) -> 13384 | I13: =IF(G13>0,Masters!$Y$3,0) -> 100 | J13: =G13*Masters!$Y$4 -> 330 | K13: =SUMIFS(Cash_Book!$G$4:$G$1008,Cash_Book!$C$4:$C$1008,"BEPAARI",Cash_Book!$D$4:$D$1008,"MOTOR",Cash_Book!$E$4:$E$1008,B13) -> 7920 | L13: =SUMIFS(Cash_Book!$G$4:$G$1008,Cash_Book!$C$4:$C$1008,"BEPAARI",Cash_Book!$D$4:$D$1008,"BHUSSA",Cash_Book!$E$4:$E$1008,B13) -> 200 | M13: =SUMIFS(Cash_Book!$G$4:$G$1008,Cash_Book!$C$4:$C$1008,"BEPAARI",Cash_Book!$D$4:$D$1008,"GAWALI",Cash_Book!$E$4:$E$1008,B13) -> 1980 | N13: =SUMIFS(Cash_Book!$G$4:$G$1008,Cash_Book!$C$4:$C$1008,"BEPAARI",Cash_Book!$D$4:$D$1008,"CASH_ADV",Cash_Book!$E$4:$E$1008,B13) -> 0 | O13: =SUMIFS(Cash_Book!$G$4:$G$1008,Cash_Book!$C$4:$C$1008,"BEPAARI",Cash_Book!$D$4:$D$1008,"OTHER",Cash_Book!$E$4:$E$1008,B13) -> 0 | P13: =SUM(H13:O13) -> 23914 | Q13: =IF(B13="","",F13-P13+E13) -> 310686 | R13: =SUMIFS(Cash_Book!$G$4:$G$1008,Cash_Book!$C$4:$C$1008,"BEPAARI",Cash_Book!$D$4:$D$1008,"PAYMENT",Cash_Book!$E$4:$E$1008,B13) -> 310686 | S13: =IF(B13="","",Q13-R13) -> 0
A14: 10 | B14: =IF(Masters!$B$12="","",Masters!$B$12) -> AYAZ | C14: =IF(B14="","",Masters!$C$12) -> 4 | D14: =IF(B14="","",IF(Masters!$D$12="","",Masters!$D$12)) | E14: =IF(B14="",0,Masters!$E$12) -> 1530 | F14: =SUMIF(Daily_Sales!$C$4:$C$503,B14,Daily_Sales!$G$4:$G$503) -> 0 | G14: =SUMIF(Daily_Sales!$C$4:$C$503,B14,Daily_Sales!$E$4:$E$503) -> 0 | H14: =IF(B14="",0,IF(D14<>"",D14*G14,F14*C14/100)) -> 0 | I14: =IF(G14>0,Masters!$Y$3,0) -> 0 | J14: =G14*Masters!$Y$4 -> 0 | K14: =SUMIFS(Cash_Book!$G$4:$G$1008,Cash_Book!$C$4:$C$1008,"BEPAARI",Cash_Book!$D$4:$D$1008,"MOTOR",Cash_Book!$E$4:$E$1008,B14) -> 0 | L14: =SUMIFS(Cash_Book!$G$4:$G$1008,Cash_Book!$C$4:$C$1008,"BEPAARI",Cash_Book!$D$4:$D$1008,"BHUSSA",Cash_Book!$E$4:$E$1008,B14) -> 0 | M14: =SUMIFS(Cash_Book!$G$4:$G$1008,Cash_Book!$C$4:$C$1008,"BEPAARI",Cash_Book!$D$4:$D$1008,"GAWALI",Cash_Book!$E$4:$E$1008,B14) -> 0 | N14: =SUMIFS(Cash_Book!$G$4:$G$1008,Cash_Book!$C$4:$C$1008,"BEPAARI",Cash_Book!$D$4:$D$1008,"CASH_ADV",Cash_Book!$E$4:$E$1008,B14) -> 0 | O14: =SUMIFS(Cash_Book!$G$4:$G$1008,Cash_Book!$C$4:$C$1008,"BEPAARI",Cash_Book!$D$4:$D$1008,"OTHER",Cash_Book!$E$4:$E$1008,B14) -> 0 | P14: =SUM(H14:O14) -> 0 | Q14: =IF(B14="","",F14-P14+E14) -> 1530 | R14: =SUMIFS(Cash_Book!$G$4:$G$1008,Cash_Book!$C$4:$C$1008,"BEPAARI",Cash_Book!$D$4:$D$1008,"PAYMENT",Cash_Book!$E$4:$E$1008,B14) -> 0 | S14: =IF(B14="","",Q14-R14) -> 1530
A15: 11 | B15: =IF(Masters!$B$13="","",Masters!$B$13) -> NEERAJ | C15: =IF(B15="","",Masters!$C$13) -> 4 | D15: =IF(B15="","",IF(Masters!$D$13="","",Masters!$D$13)) | E15: =IF(B15="",0,Masters!$E$13) -> 0 | F15: =SUMIF(Daily_Sales!$C$4:$C$503,B15,Daily_Sales!$G$4:$G$503) -> 320800 | G15: =SUMIF(Daily_Sales!$C$4:$C$503,B15,Daily_Sales!$E$4:$E$503) -> 35 | H15: =IF(B15="",0,IF(D15<>"",D15*G15,F15*C15/100)) -> 12832 | I15: =IF(G15>0,Masters!$Y$3,0) -> 100 | J15: =G15*Masters!$Y$4 -> 350 | K15: =SUMIFS(Cash_Book!$G$4:$G$1008,Cash_Book!$C$4:$C$1008,"BEPAARI",Cash_Book!$D$4:$D$1008,"MOTOR",Cash_Book!$E$4:$E$1008,B15) -> 8400 | L15: =SUMIFS(Cash_Book!$G$4:$G$1008,Cash_Book!$C$4:$C$1008,"BEPAARI",Cash_Book!$D$4:$D$1008,"BHUSSA",Cash_Book!$E$4:$E$1008,B15) -> 0 | M15: =SUMIFS(Cash_Book!$G$4:$G$1008,Cash_Book!$C$4:$C$1008,"BEPAARI",Cash_Book!$D$4:$D$1008,"GAWALI",Cash_Book!$E$4:$E$1008,B15) -> 5300 | N15: =SUMIFS(Cash_Book!$G$4:$G$1008,Cash_Book!$C$4:$C$1008,"BEPAARI",Cash_Book!$D$4:$D$1008,"CASH_ADV",Cash_Book!$E$4:$E$1008,B15) -> 0 | O15: =SUMIFS(Cash_Book!$G$4:$G$1008,Cash_Book!$C$4:$C$1008,"BEPAARI",Cash_Book!$D$4:$D$1008,"OTHER",Cash_Book!$E$4:$E$1008,B15) -> 0 | P15: =SUM(H15:O15) -> 26982 | Q15: =IF(B15="","",F15-P15+E15) -> 293818 | R15: =SUMIFS(Cash_Book!$G$4:$G$1008,Cash_Book!$C$4:$C$1008,"BEPAARI",Cash_Book!$D$4:$D$1008,"PAYMENT",Cash_Book!$E$4:$E$1008,B15) -> 232670 | S15: =IF(B15="","",Q15-R15) -> 61148
A16: 12 | B16: =IF(Masters!$B$14="","",Masters!$B$14) -> CHINTU SHUJALPUR | C16: =IF(B16="","",Masters!$C$14) -> 4 | D16: =IF(B16="","",IF(Masters!$D$14="","",Masters!$D$14)) | E16: =IF(B16="",0,Masters!$E$14) -> 0 | F16: =SUMIF(Daily_Sales!$C$4:$C$503,B16,Daily_Sales!$G$4:$G$503) -> 574300 | G16: =SUMIF(Daily_Sales!$C$4:$C$503,B16,Daily_Sales!$E$4:$E$503) -> 58 | H16: =IF(B16="",0,IF(D16<>"",D16*G16,F16*C16/100)) -> 22972 | I16: =IF(G16>0,Masters!$Y$3,0) -> 100 | J16: =G16*Masters!$Y$4 -> 580 | K16: =SUMIFS(Cash_Book!$G$4:$G$1008,Cash_Book!$C$4:$C$1008,"BEPAARI",Cash_Book!$D$4:$D$1008,"MOTOR",Cash_Book!$E$4:$E$1008,B16) -> 15600 | L16: =SUMIFS(Cash_Book!$G$4:$G$1008,Cash_Book!$C$4:$C$1008,"BEPAARI",Cash_Book!$D$4:$D$1008,"BHUSSA",Cash_Book!$E$4:$E$1008,B16) -> 400 | M16: =SUMIFS(Cash_Book!$G$4:$G$1008,Cash_Book!$C$4:$C$1008,"BEPAARI",Cash_Book!$D$4:$D$1008,"GAWALI",Cash_Book!$E$4:$E$1008,B16) -> 3540 | N16: =SUMIFS(Cash_Book!$G$4:$G$1008,Cash_Book!$C$4:$C$1008,"BEPAARI",Cash_Book!$D$4:$D$1008,"CASH_ADV",Cash_Book!$E$4:$E$1008,B16) -> 0 | O16: =SUMIFS(Cash_Book!$G$4:$G$1008,Cash_Book!$C$4:$C$1008,"BEPAARI",Cash_Book!$D$4:$D$1008,"OTHER",Cash_Book!$E$4:$E$1008,B16) -> 0 | P16: =SUM(H16:O16) -> 43192 | Q16: =IF(B16="","",F16-P16+E16) -> 531108 | R16: =SUMIFS(Cash_Book!$G$4:$G$1008,Cash_Book!$C$4:$C$1008,"BEPAARI",Cash_Book!$D$4:$D$1008,"PAYMENT",Cash_Book!$E$4:$E$1008,B16) -> 460024 | S16: =IF(B16="","",Q16-R16) -> 71084
A17: 13 | B17: =IF(Masters!$B$15="","",Masters!$B$15) -> SANNA | C17: =IF(B17="","",Masters!$C$15) -> 4 | D17: =IF(B17="","",IF(Masters!$D$15="","",Masters!$D$15)) | E17: =IF(B17="",0,Masters!$E$15) -> -14048 | F17: =SUMIF(Daily_Sales!$C$4:$C$503,B17,Daily_Sales!$G$4:$G$503) -> 0 | G17: =SUMIF(Daily_Sales!$C$4:$C$503,B17,Daily_Sales!$E$4:$E$503) -> 0 | H17: =IF(B17="",0,IF(D17<>"",D17*G17,F17*C17/100)) -> 0 | I17: =IF(G17>0,Masters!$Y$3,0) -> 0 | J17: =G17*Masters!$Y$4 -> 0 | K17: =SUMIFS(Cash_Book!$G$4:$G$1008,Cash_Book!$C$4:$C$1008,"BEPAARI",Cash_Book!$D$4:$D$1008,"MOTOR",Cash_Book!$E$4:$E$1008,B17) -> 0 | L17: =SUMIFS(Cash_Book!$G$4:$G$1008,Cash_Book!$C$4:$C$1008,"BEPAARI",Cash_Book!$D$4:$D$1008,"BHUSSA",Cash_Book!$E$4:$E$1008,B17) -> 0 | M17: =SUMIFS(Cash_Book!$G$4:$G$1008,Cash_Book!$C$4:$C$1008,"BEPAARI",Cash_Book!$D$4:$D$1008,"GAWALI",Cash_Book!$E$4:$E$1008,B17) -> 0 | N17: =SUMIFS(Cash_Book!$G$4:$G$1008,Cash_Book!$C$4:$C$1008,"BEPAARI",Cash_Book!$D$4:$D$1008,"CASH_ADV",Cash_Book!$E$4:$E$1008,B17) -> 0 | O17: =SUMIFS(Cash_Book!$G$4:$G$1008,Cash_Book!$C$4:$C$1008,"BEPAARI",Cash_Book!$D$4:$D$1008,"OTHER",Cash_Book!$E$4:$E$1008,B17) -> 0 | P17: =SUM(H17:O17) -> 0 | Q17: =IF(B17="","",F17-P17+E17) -> -14048 | R17: =SUMIFS(Cash_Book!$G$4:$G$1008,Cash_Book!$C$4:$C$1008,"BEPAARI",Cash_Book!$D$4:$D$1008,"PAYMENT",Cash_Book!$E$4:$E$1008,B17) -> 0 | S17: =IF(B17="","",Q17-R17) -> -14048
A18: 14 | B18: =IF(Masters!$B$16="","",Masters!$B$16) -> WAHID | C18: =IF(B18="","",Masters!$C$16) -> 4 | D18: =IF(B18="","",IF(Masters!$D$16="","",Masters!$D$16)) | E18: =IF(B18="",0,Masters!$E$16) -> -4661 | F18: =SUMIF(Daily_Sales!$C$4:$C$503,B18,Daily_Sales!$G$4:$G$503) -> 0 | G18: =SUMIF(Daily_Sales!$C$4:$C$503,B18,Daily_Sales!$E$4:$E$503) -> 0 | H18: =IF(B18="",0,IF(D18<>"",D18*G18,F18*C18/100)) -> 0 | I18: =IF(G18>0,Masters!$Y$3,0) -> 0 | J18: =G18*Masters!$Y$4 -> 0 | K18: =SUMIFS(Cash_Book!$G$4:$G$1008,Cash_Book!$C$4:$C$1008,"BEPAARI",Cash_Book!$D$4:$D$1008,"MOTOR",Cash_Book!$E$4:$E$1008,B18) -> 0 | L18: =SUMIFS(Cash_Book!$G$4:$G$1008,Cash_Book!$C$4:$C$1008,"BEPAARI",Cash_Book!$D$4:$D$1008,"BHUSSA",Cash_Book!$E$4:$E$1008,B18) -> 0 | M18: =SUMIFS(Cash_Book!$G$4:$G$1008,Cash_Book!$C$4:$C$1008,"BEPAARI",Cash_Book!$D$4:$D$1008,"GAWALI",Cash_Book!$E$4:$E$1008,B18) -> 0 | N18: =SUMIFS(Cash_Book!$G$4:$G$1008,Cash_Book!$C$4:$C$1008,"BEPAARI",Cash_Book!$D$4:$D$1008,"CASH_ADV",Cash_Book!$E$4:$E$1008,B18) -> 0 | O18: =SUMIFS(Cash_Book!$G$4:$G$1008,Cash_Book!$C$4:$C$1008,"BEPAARI",Cash_Book!$D$4:$D$1008,"OTHER",Cash_Book!$E$4:$E$1008,B18) -> 0 | P18: =SUM(H18:O18) -> 0 | Q18: =IF(B18="","",F18-P18+E18) -> -4661 | R18: =SUMIFS(Cash_Book!$G$4:$G$1008,Cash_Book!$C$4:$C$1008,"BEPAARI",Cash_Book!$D$4:$D$1008,"PAYMENT",Cash_Book!$E$4:$E$1008,B18) -> 0 | S18: =IF(B18="","",Q18-R18) -> -4661
A19: 15 | B19: =IF(Masters!$B$17="","",Masters!$B$17) -> MANSOOR | C19: =IF(B19="","",Masters!$C$17) -> 4 | D19: =IF(B19="","",IF(Masters!$D$17="","",Masters!$D$17)) | E19: =IF(B19="",0,Masters!$E$17) -> -9845 | F19: =SUMIF(Daily_Sales!$C$4:$C$503,B19,Daily_Sales!$G$4:$G$503) -> 0 | G19: =SUMIF(Daily_Sales!$C$4:$C$503,B19,Daily_Sales!$E$4:$E$503) -> 0 | H19: =IF(B19="",0,IF(D19<>"",D19*G19,F19*C19/100)) -> 0 | I19: =IF(G19>0,Masters!$Y$3,0) -> 0 | J19: =G19*Masters!$Y$4 -> 0 | K19: =SUMIFS(Cash_Book!$G$4:$G$1008,Cash_Book!$C$4:$C$1008,"BEPAARI",Cash_Book!$D$4:$D$1008,"MOTOR",Cash_Book!$E$4:$E$1008,B19) -> 0 | L19: =SUMIFS(Cash_Book!$G$4:$G$1008,Cash_Book!$C$4:$C$1008,"BEPAARI",Cash_Book!$D$4:$D$1008,"BHUSSA",Cash_Book!$E$4:$E$1008,B19) -> 0 | M19: =SUMIFS(Cash_Book!$G$4:$G$1008,Cash_Book!$C$4:$C$1008,"BEPAARI",Cash_Book!$D$4:$D$1008,"GAWALI",Cash_Book!$E$4:$E$1008,B19) -> 0 | N19: =SUMIFS(Cash_Book!$G$4:$G$1008,Cash_Book!$C$4:$C$1008,"BEPAARI",Cash_Book!$D$4:$D$1008,"CASH_ADV",Cash_Book!$E$4:$E$1008,B19) -> 0 | O19: =SUMIFS(Cash_Book!$G$4:$G$1008,Cash_Book!$C$4:$C$1008,"BEPAARI",Cash_Book!$D$4:$D$1008,"OTHER",Cash_Book!$E$4:$E$1008,B19) -> 0 | P19: =SUM(H19:O19) -> 0 | Q19: =IF(B19="","",F19-P19+E19) -> -9845 | R19: =SUMIFS(Cash_Book!$G$4:$G$1008,Cash_Book!$C$4:$C$1008,"BEPAARI",Cash_Book!$D$4:$D$1008,"PAYMENT",Cash_Book!$E$4:$E$1008,B19) -> 0 | S19: =IF(B19="","",Q19-R19) -> -9845
A20: 16 | B20: =IF(Masters!$B$18="","",Masters!$B$18) -> AYAZ PREVIOUS BAL | C20: =IF(B20="","",Masters!$C$18) -> 4 | D20: =IF(B20="","",IF(Masters!$D$18="","",Masters!$D$18)) | E20: =IF(B20="",0,Masters!$E$18) -> -88000 | F20: =SUMIF(Daily_Sales!$C$4:$C$503,B20,Daily_Sales!$G$4:$G$503) -> 0 | G20: =SUMIF(Daily_Sales!$C$4:$C$503,B20,Daily_Sales!$E$4:$E$503) -> 0 | H20: =IF(B20="",0,IF(D20<>"",D20*G20,F20*C20/100)) -> 0 | I20: =IF(G20>0,Masters!$Y$3,0) -> 0 | J20: =G20*Masters!$Y$4 -> 0 | K20: =SUMIFS(Cash_Book!$G$4:$G$1008,Cash_Book!$C$4:$C$1008,"BEPAARI",Cash_Book!$D$4:$D$1008,"MOTOR",Cash_Book!$E$4:$E$1008,B20) -> 0 | L20: =SUMIFS(Cash_Book!$G$4:$G$1008,Cash_Book!$C$4:$C$1008,"BEPAARI",Cash_Book!$D$4:$D$1008,"BHUSSA",Cash_Book!$E$4:$E$1008,B20) -> 0 | M20: =SUMIFS(Cash_Book!$G$4:$G$1008,Cash_Book!$C$4:$C$1008,"BEPAARI",Cash_Book!$D$4:$D$1008,"GAWALI",Cash_Book!$E$4:$E$1008,B20) -> 0 | N20: =SUMIFS(Cash_Book!$G$4:$G$1008,Cash_Book!$C$4:$C$1008,"BEPAARI",Cash_Book!$D$4:$D$1008,"CASH_ADV",Cash_Book!$E$4:$E$1008,B20) -> 0 | O20: =SUMIFS(Cash_Book!$G$4:$G$1008,Cash_Book!$C$4:$C$1008,"BEPAARI",Cash_Book!$D$4:$D$1008,"OTHER",Cash_Book!$E$4:$E$1008,B20) -> 0 | P20: =SUM(H20:O20) -> 0 | Q20: =IF(B20="","",F20-P20+E20) -> -88000 | R20: =SUMIFS(Cash_Book!$G$4:$G$1008,Cash_Book!$C$4:$C$1008,"BEPAARI",Cash_Book!$D$4:$D$1008,"PAYMENT",Cash_Book!$E$4:$E$1008,B20) -> 0 | S20: =IF(B20="","",Q20-R20) -> -88000
A21: 17 | B21: =IF(Masters!$B$19="","",Masters!$B$19) -> SHAKIL SHUJALPUR | C21: =IF(B21="","",Masters!$C$19) -> 4 | D21: =IF(B21="","",IF(Masters!$D$19="","",Masters!$D$19)) | E21: =IF(B21="",0,Masters!$E$19) -> 660 | F21: =SUMIF(Daily_Sales!$C$4:$C$503,B21,Daily_Sales!$G$4:$G$503) -> 0 | G21: =SUMIF(Daily_Sales!$C$4:$C$503,B21,Daily_Sales!$E$4:$E$503) -> 0 | H21: =IF(B21="",0,IF(D21<>"",D21*G21,F21*C21/100)) -> 0 | I21: =IF(G21>0,Masters!$Y$3,0) -> 0 | J21: =G21*Masters!$Y$4 -> 0 | K21: =SUMIFS(Cash_Book!$G$4:$G$1008,Cash_Book!$C$4:$C$1008,"BEPAARI",Cash_Book!$D$4:$D$1008,"MOTOR",Cash_Book!$E$4:$E$1008,B21) -> 0 | L21: =SUMIFS(Cash_Book!$G$4:$G$1008,Cash_Book!$C$4:$C$1008,"BEPAARI",Cash_Book!$D$4:$D$1008,"BHUSSA",Cash_Book!$E$4:$E$1008,B21) -> 0 | M21: =SUMIFS(Cash_Book!$G$4:$G$1008,Cash_Book!$C$4:$C$1008,"BEPAARI",Cash_Book!$D$4:$D$1008,"GAWALI",Cash_Book!$E$4:$E$1008,B21) -> 0 | N21: =SUMIFS(Cash_Book!$G$4:$G$1008,Cash_Book!$C$4:$C$1008,"BEPAARI",Cash_Book!$D$4:$D$1008,"CASH_ADV",Cash_Book!$E$4:$E$1008,B21) -> 0 | O21: =SUMIFS(Cash_Book!$G$4:$G$1008,Cash_Book!$C$4:$C$1008,"BEPAARI",Cash_Book!$D$4:$D$1008,"OTHER",Cash_Book!$E$4:$E$1008,B21) -> 0 | P21: =SUM(H21:O21) -> 0 | Q21: =IF(B21="","",F21-P21+E21) -> 660 | R21: =SUMIFS(Cash_Book!$G$4:$G$1008,Cash_Book!$C$4:$C$1008,"BEPAARI",Cash_Book!$D$4:$D$1008,"PAYMENT",Cash_Book!$E$4:$E$1008,B21) -> 0 | S21: =IF(B21="","",Q21-R21) -> 660
A22: 18 | B22: =IF(Masters!$B$20="","",Masters!$B$20) -> USMAN | C22: =IF(B22="","",Masters!$C$20) -> 4 | D22: =IF(B22="","",IF(Masters!$D$20="","",Masters!$D$20)) | E22: =IF(B22="",0,Masters!$E$20) -> 40440 | F22: =SUMIF(Daily_Sales!$C$4:$C$503,B22,Daily_Sales!$G$4:$G$503) -> 225000 | G22: =SUMIF(Daily_Sales!$C$4:$C$503,B22,Daily_Sales!$E$4:$E$503) -> 15 | H22: =IF(B22="",0,IF(D22<>"",D22*G22,F22*C22/100)) -> 9000 | I22: =IF(G22>0,Masters!$Y$3,0) -> 100 | J22: =G22*Masters!$Y$4 -> 150 | K22: =SUMIFS(Cash_Book!$G$4:$G$1008,Cash_Book!$C$4:$C$1008,"BEPAARI",Cash_Book!$D$4:$D$1008,"MOTOR",Cash_Book!$E$4:$E$1008,B22) -> 8090 | L22: =SUMIFS(Cash_Book!$G$4:$G$1008,Cash_Book!$C$4:$C$1008,"BEPAARI",Cash_Book!$D$4:$D$1008,"BHUSSA",Cash_Book!$E$4:$E$1008,B22) -> 130 | M22: =SUMIFS(Cash_Book!$G$4:$G$1008,Cash_Book!$C$4:$C$1008,"BEPAARI",Cash_Book!$D$4:$D$1008,"GAWALI",Cash_Book!$E$4:$E$1008,B22) -> 1980 | N22: =SUMIFS(Cash_Book!$G$4:$G$1008,Cash_Book!$C$4:$C$1008,"BEPAARI",Cash_Book!$D$4:$D$1008,"CASH_ADV",Cash_Book!$E$4:$E$1008,B22) -> 0 | O22: =SUMIFS(Cash_Book!$G$4:$G$1008,Cash_Book!$C$4:$C$1008,"BEPAARI",Cash_Book!$D$4:$D$1008,"OTHER",Cash_Book!$E$4:$E$1008,B22) -> 0 | P22: =SUM(H22:O22) -> 19450 | Q22: =IF(B22="","",F22-P22+E22) -> 245990 | R22: =SUMIFS(Cash_Book!$G$4:$G$1008,Cash_Book!$C$4:$C$1008,"BEPAARI",Cash_Book!$D$4:$D$1008,"PAYMENT",Cash_Book!$E$4:$E$1008,B22) -> 240000 | S22: =IF(B22="","",Q22-R22) -> 5990
A23: 19 | B23: =IF(Masters!$B$21="","",Masters!$B$21) -> JUNAID AMANAT | C23: =IF(B23="","",Masters!$C$21) -> 4 | D23: =IF(B23="","",IF(Masters!$D$21="","",Masters!$D$21)) | E23: =IF(B23="",0,Masters!$E$21) -> -100000 | F23: =SUMIF(Daily_Sales!$C$4:$C$503,B23,Daily_Sales!$G$4:$G$503) -> 0 | G23: =SUMIF(Daily_Sales!$C$4:$C$503,B23,Daily_Sales!$E$4:$E$503) -> 0 | H23: =IF(B23="",0,IF(D23<>"",D23*G23,F23*C23/100)) -> 0 | I23: =IF(G23>0,Masters!$Y$3,0) -> 0 | J23: =G23*Masters!$Y$4 -> 0 | K23: =SUMIFS(Cash_Book!$G$4:$G$1008,Cash_Book!$C$4:$C$1008,"BEPAARI",Cash_Book!$D$4:$D$1008,"MOTOR",Cash_Book!$E$4:$E$1008,B23) -> 0 | L23: =SUMIFS(Cash_Book!$G$4:$G$1008,Cash_Book!$C$4:$C$1008,"BEPAARI",Cash_Book!$D$4:$D$1008,"BHUSSA",Cash_Book!$E$4:$E$1008,B23) -> 0 | M23: =SUMIFS(Cash_Book!$G$4:$G$1008,Cash_Book!$C$4:$C$1008,"BEPAARI",Cash_Book!$D$4:$D$1008,"GAWALI",Cash_Book!$E$4:$E$1008,B23) -> 0 | N23: =SUMIFS(Cash_Book!$G$4:$G$1008,Cash_Book!$C$4:$C$1008,"BEPAARI",Cash_Book!$D$4:$D$1008,"CASH_ADV",Cash_Book!$E$4:$E$1008,B23) -> 0 | O23: =SUMIFS(Cash_Book!$G$4:$G$1008,Cash_Book!$C$4:$C$1008,"BEPAARI",Cash_Book!$D$4:$D$1008,"OTHER",Cash_Book!$E$4:$E$1008,B23) -> 0 | P23: =SUM(H23:O23) -> 0 | Q23: =IF(B23="","",F23-P23+E23) -> -100000 | R23: =SUMIFS(Cash_Book!$G$4:$G$1008,Cash_Book!$C$4:$C$1008,"BEPAARI",Cash_Book!$D$4:$D$1008,"PAYMENT",Cash_Book!$E$4:$E$1008,B23) -> 0 | S23: =IF(B23="","",Q23-R23) -> -100000
A24: 20 | B24: =IF(Masters!$B$22="","",Masters!$B$22) -> SHARIF RAJ | C24: =IF(B24="","",Masters!$C$22) -> 4 | D24: =IF(B24="","",IF(Masters!$D$22="","",Masters!$D$22)) | E24: =IF(B24="",0,Masters!$E$22) -> 0 | F24: =SUMIF(Daily_Sales!$C$4:$C$503,B24,Daily_Sales!$G$4:$G$503) -> 362750 | G24: =SUMIF(Daily_Sales!$C$4:$C$503,B24,Daily_Sales!$E$4:$E$503) -> 42 | H24: =IF(B24="",0,IF(D24<>"",D24*G24,F24*C24/100)) -> 14510 | I24: =IF(G24>0,Masters!$Y$3,0) -> 100 | J24: =G24*Masters!$Y$4 -> 420 | K24: =SUMIFS(Cash_Book!$G$4:$G$1008,Cash_Book!$C$4:$C$1008,"BEPAARI",Cash_Book!$D$4:$D$1008,"MOTOR",Cash_Book!$E$4:$E$1008,B24) -> 10080 | L24: =SUMIFS(Cash_Book!$G$4:$G$1008,Cash_Book!$C$4:$C$1008,"BEPAARI",Cash_Book!$D$4:$D$1008,"BHUSSA",Cash_Book!$E$4:$E$1008,B24) -> 100 | M24: =SUMIFS(Cash_Book!$G$4:$G$1008,Cash_Book!$C$4:$C$1008,"BEPAARI",Cash_Book!$D$4:$D$1008,"GAWALI",Cash_Book!$E$4:$E$1008,B24) -> 2520 | N24: =SUMIFS(Cash_Book!$G$4:$G$1008,Cash_Book!$C$4:$C$1008,"BEPAARI",Cash_Book!$D$4:$D$1008,"CASH_ADV",Cash_Book!$E$4:$E$1008,B24) -> 0 | O24: =SUMIFS(Cash_Book!$G$4:$G$1008,Cash_Book!$C$4:$C$1008,"BEPAARI",Cash_Book!$D$4:$D$1008,"OTHER",Cash_Book!$E$4:$E$1008,B24) -> 0 | P24: =SUM(H24:O24) -> 27730 | Q24: =IF(B24="","",F24-P24+E24) -> 335020 | R24: =SUMIFS(Cash_Book!$G$4:$G$1008,Cash_Book!$C$4:$C$1008,"BEPAARI",Cash_Book!$D$4:$D$1008,"PAYMENT",Cash_Book!$E$4:$E$1008,B24) -> 304630 | S24: =IF(B24="","",Q24-R24) -> 30390
A25: 21 | B25: =IF(Masters!$B$23="","",Masters!$B$23) | C25: =IF(B25="","",Masters!$C$23) | D25: =IF(B25="","",IF(Masters!$D$23="","",Masters!$D$23)) | E25: =IF(B25="",0,Masters!$E$23) -> 0 | F25: =SUMIF(Daily_Sales!$C$4:$C$503,B25,Daily_Sales!$G$4:$G$503) -> 0 | G25: =SUMIF(Daily_Sales!$C$4:$C$503,B25,Daily_Sales!$E$4:$E$503) -> 0 | H25: =IF(B25="",0,IF(D25<>"",D25*G25,F25*C25/100)) -> 0 | I25: =IF(G25>0,Masters!$Y$3,0) -> 0 | J25: =G25*Masters!$Y$4 -> 0 | K25: =SUMIFS(Cash_Book!$G$4:$G$1008,Cash_Book!$C$4:$C$1008,"BEPAARI",Cash_Book!$D$4:$D$1008,"MOTOR",Cash_Book!$E$4:$E$1008,B25) -> 0 | L25: =SUMIFS(Cash_Book!$G$4:$G$1008,Cash_Book!$C$4:$C$1008,"BEPAARI",Cash_Book!$D$4:$D$1008,"BHUSSA",Cash_Book!$E$4:$E$1008,B25) -> 0 | M25: =SUMIFS(Cash_Book!$G$4:$G$1008,Cash_Book!$C$4:$C$1008,"BEPAARI",Cash_Book!$D$4:$D$1008,"GAWALI",Cash_Book!$E$4:$E$1008,B25) -> 0 | N25: =SUMIFS(Cash_Book!$G$4:$G$1008,Cash_Book!$C$4:$C$1008,"BEPAARI",Cash_Book!$D$4:$D$1008,"CASH_ADV",Cash_Book!$E$4:$E$1008,B25) -> 0 | O25: =SUMIFS(Cash_Book!$G$4:$G$1008,Cash_Book!$C$4:$C$1008,"BEPAARI",Cash_Book!$D$4:$D$1008,"OTHER",Cash_Book!$E$4:$E$1008,B25) -> 0 | P25: =SUM(H25:O25) -> 0 | Q25: =IF(B25="","",F25-P25+E25) | R25: =SUMIFS(Cash_Book!$G$4:$G$1008,Cash_Book!$C$4:$C$1008,"BEPAARI",Cash_Book!$D$4:$D$1008,"PAYMENT",Cash_Book!$E$4:$E$1008,B25) -> 0 | S25: =IF(B25="","",Q25-R25)
A26: 22 | B26: =IF(Masters!$B$24="","",Masters!$B$24) | C26: =IF(B26="","",Masters!$C$24) | D26: =IF(B26="","",IF(Masters!$D$24="","",Masters!$D$24)) | E26: =IF(B26="",0,Masters!$E$24) -> 0 | F26: =SUMIF(Daily_Sales!$C$4:$C$503,B26,Daily_Sales!$G$4:$G$503) -> 0 | G26: =SUMIF(Daily_Sales!$C$4:$C$503,B26,Daily_Sales!$E$4:$E$503) -> 0 | H26: =IF(B26="",0,IF(D26<>"",D26*G26,F26*C26/100)) -> 0 | I26: =IF(G26>0,Masters!$Y$3,0) -> 0 | J26: =G26*Masters!$Y$4 -> 0 | K26: =SUMIFS(Cash_Book!$G$4:$G$1008,Cash_Book!$C$4:$C$1008,"BEPAARI",Cash_Book!$D$4:$D$1008,"MOTOR",Cash_Book!$E$4:$E$1008,B26) -> 0 | L26: =SUMIFS(Cash_Book!$G$4:$G$1008,Cash_Book!$C$4:$C$1008,"BEPAARI",Cash_Book!$D$4:$D$1008,"BHUSSA",Cash_Book!$E$4:$E$1008,B26) -> 0 | M26: =SUMIFS(Cash_Book!$G$4:$G$1008,Cash_Book!$C$4:$C$1008,"BEPAARI",Cash_Book!$D$4:$D$1008,"GAWALI",Cash_Book!$E$4:$E$1008,B26) -> 0 | N26: =SUMIFS(Cash_Book!$G$4:$G$1008,Cash_Book!$C$4:$C$1008,"BEPAARI",Cash_Book!$D$4:$D$1008,"CASH_ADV",Cash_Book!$E$4:$E$1008,B26) -> 0 | O26: =SUMIFS(Cash_Book!$G$4:$G$1008,Cash_Book!$C$4:$C$1008,"BEPAARI",Cash_Book!$D$4:$D$1008,"OTHER",Cash_Book!$E$4:$E$1008,B26) -> 0 | P26: =SUM(H26:O26) -> 0 | Q26: =IF(B26="","",F26-P26+E26) | R26: =SUMIFS(Cash_Book!$G$4:$G$1008,Cash_Book!$C$4:$C$1008,"BEPAARI",Cash_Book!$D$4:$D$1008,"PAYMENT",Cash_Book!$E$4:$E$1008,B26) -> 0 | S26: =IF(B26="","",Q26-R26)
A27: 23 | B27: =IF(Masters!$B$25="","",Masters!$B$25) | C27: =IF(B27="","",Masters!$C$25) | D27: =IF(B27="","",IF(Masters!$D$25="","",Masters!$D$25)) | E27: =IF(B27="",0,Masters!$E$25) -> 0 | F27: =SUMIF(Daily_Sales!$C$4:$C$503,B27,Daily_Sales!$G$4:$G$503) -> 0 | G27: =SUMIF(Daily_Sales!$C$4:$C$503,B27,Daily_Sales!$E$4:$E$503) -> 0 | H27: =IF(B27="",0,IF(D27<>"",D27*G27,F27*C27/100)) -> 0 | I27: =IF(G27>0,Masters!$Y$3,0) -> 0 | J27: =G27*Masters!$Y$4 -> 0 | K27: =SUMIFS(Cash_Book!$G$4:$G$1008,Cash_Book!$C$4:$C$1008,"BEPAARI",Cash_Book!$D$4:$D$1008,"MOTOR",Cash_Book!$E$4:$E$1008,B27) -> 0 | L27: =SUMIFS(Cash_Book!$G$4:$G$1008,Cash_Book!$C$4:$C$1008,"BEPAARI",Cash_Book!$D$4:$D$1008,"BHUSSA",Cash_Book!$E$4:$E$1008,B27) -> 0 | M27: =SUMIFS(Cash_Book!$G$4:$G$1008,Cash_Book!$C$4:$C$1008,"BEPAARI",Cash_Book!$D$4:$D$1008,"GAWALI",Cash_Book!$E$4:$E$1008,B27) -> 0 | N27: =SUMIFS(Cash_Book!$G$4:$G$1008,Cash_Book!$C$4:$C$1008,"BEPAARI",Cash_Book!$D$4:$D$1008,"CASH_ADV",Cash_Book!$E$4:$E$1008,B27) -> 0 | O27: =SUMIFS(Cash_Book!$G$4:$G$1008,Cash_Book!$C$4:$C$1008,"BEPAARI",Cash_Book!$D$4:$D$1008,"OTHER",Cash_Book!$E$4:$E$1008,B27) -> 0 | P27: =SUM(H27:O27) -> 0 | Q27: =IF(B27="","",F27-P27+E27) | R27: =SUMIFS(Cash_Book!$G$4:$G$1008,Cash_Book!$C$4:$C$1008,"BEPAARI",Cash_Book!$D$4:$D$1008,"PAYMENT",Cash_Book!$E$4:$E$1008,B27) -> 0 | S27: =IF(B27="","",Q27-R27)
A28: 24 | B28: =IF(Masters!$B$26="","",Masters!$B$26) | C28: =IF(B28="","",Masters!$C$26) | D28: =IF(B28="","",IF(Masters!$D$26="","",Masters!$D$26)) | E28: =IF(B28="",0,Masters!$E$26) -> 0 | F28: =SUMIF(Daily_Sales!$C$4:$C$503,B28,Daily_Sales!$G$4:$G$503) -> 0 | G28: =SUMIF(Daily_Sales!$C$4:$C$503,B28,Daily_Sales!$E$4:$E$503) -> 0 | H28: =IF(B28="",0,IF(D28<>"",D28*G28,F28*C28/100)) -> 0 | I28: =IF(G28>0,Masters!$Y$3,0) -> 0 | J28: =G28*Masters!$Y$4 -> 0 | K28: =SUMIFS(Cash_Book!$G$4:$G$1008,Cash_Book!$C$4:$C$1008,"BEPAARI",Cash_Book!$D$4:$D$1008,"MOTOR",Cash_Book!$E$4:$E$1008,B28) -> 0 | L28: =SUMIFS(Cash_Book!$G$4:$G$1008,Cash_Book!$C$4:$C$1008,"BEPAARI",Cash_Book!$D$4:$D$1008,"BHUSSA",Cash_Book!$E$4:$E$1008,B28) -> 0 | M28: =SUMIFS(Cash_Book!$G$4:$G$1008,Cash_Book!$C$4:$C$1008,"BEPAARI",Cash_Book!$D$4:$D$1008,"GAWALI",Cash_Book!$E$4:$E$1008,B28) -> 0 | N28: =SUMIFS(Cash_Book!$G$4:$G$1008,Cash_Book!$C$4:$C$1008,"BEPAARI",Cash_Book!$D$4:$D$1008,"CASH_ADV",Cash_Book!$E$4:$E$1008,B28) -> 0 | O28: =SUMIFS(Cash_Book!$G$4:$G$1008,Cash_Book!$C$4:$C$1008,"BEPAARI",Cash_Book!$D$4:$D$1008,"OTHER",Cash_Book!$E$4:$E$1008,B28) -> 0 | P28: =SUM(H28:O28) -> 0 | Q28: =IF(B28="","",F28-P28+E28) | R28: =SUMIFS(Cash_Book!$G$4:$G$1008,Cash_Book!$C$4:$C$1008,"BEPAARI",Cash_Book!$D$4:$D$1008,"PAYMENT",Cash_Book!$E$4:$E$1008,B28) -> 0 | S28: =IF(B28="","",Q28-R28)
A29: 25 | B29: =IF(Masters!$B$27="","",Masters!$B$27) | C29: =IF(B29="","",Masters!$C$27) | D29: =IF(B29="","",IF(Masters!$D$27="","",Masters!$D$27)) | E29: =IF(B29="",0,Masters!$E$27) -> 0 | F29: =SUMIF(Daily_Sales!$C$4:$C$503,B29,Daily_Sales!$G$4:$G$503) -> 0 | G29: =SUMIF(Daily_Sales!$C$4:$C$503,B29,Daily_Sales!$E$4:$E$503) -> 0 | H29: =IF(B29="",0,IF(D29<>"",D29*G29,F29*C29/100)) -> 0 | I29: =IF(G29>0,Masters!$Y$3,0) -> 0 | J29: =G29*Masters!$Y$4 -> 0 | K29: =SUMIFS(Cash_Book!$G$4:$G$1008,Cash_Book!$C$4:$C$1008,"BEPAARI",Cash_Book!$D$4:$D$1008,"MOTOR",Cash_Book!$E$4:$E$1008,B29) -> 0 | L29: =SUMIFS(Cash_Book!$G$4:$G$1008,Cash_Book!$C$4:$C$1008,"BEPAARI",Cash_Book!$D$4:$D$1008,"BHUSSA",Cash_Book!$E$4:$E$1008,B29) -> 0 | M29: =SUMIFS(Cash_Book!$G$4:$G$1008,Cash_Book!$C$4:$C$1008,"BEPAARI",Cash_Book!$D$4:$D$1008,"GAWALI",Cash_Book!$E$4:$E$1008,B29) -> 0 | N29: =SUMIFS(Cash_Book!$G$4:$G$1008,Cash_Book!$C$4:$C$1008,"BEPAARI",Cash_Book!$D$4:$D$1008,"CASH_ADV",Cash_Book!$E$4:$E$1008,B29) -> 0 | O29: =SUMIFS(Cash_Book!$G$4:$G$1008,Cash_Book!$C$4:$C$1008,"BEPAARI",Cash_Book!$D$4:$D$1008,"OTHER",Cash_Book!$E$4:$E$1008,B29) -> 0 | P29: =SUM(H29:O29) -> 0 | Q29: =IF(B29="","",F29-P29+E29) | R29: =SUMIFS(Cash_Book!$G$4:$G$1008,Cash_Book!$C$4:$C$1008,"BEPAARI",Cash_Book!$D$4:$D$1008,"PAYMENT",Cash_Book!$E$4:$E$1008,B29) -> 0 | S29: =IF(B29="","",Q29-R29)
A30: 26 | B30: =IF(Masters!$B$28="","",Masters!$B$28) | C30: =IF(B30="","",Masters!$C$28) | D30: =IF(B30="","",IF(Masters!$D$28="","",Masters!$D$28)) | E30: =IF(B30="",0,Masters!$E$28) -> 0 | F30: =SUMIF(Daily_Sales!$C$4:$C$503,B30,Daily_Sales!$G$4:$G$503) -> 0 | G30: =SUMIF(Daily_Sales!$C$4:$C$503,B30,Daily_Sales!$E$4:$E$503) -> 0 | H30: =IF(B30="",0,IF(D30<>"",D30*G30,F30*C30/100)) -> 0 | I30: =IF(G30>0,Masters!$Y$3,0) -> 0 | J30: =G30*Masters!$Y$4 -> 0 | K30: =SUMIFS(Cash_Book!$G$4:$G$1008,Cash_Book!$C$4:$C$1008,"BEPAARI",Cash_Book!$D$4:$D$1008,"MOTOR",Cash_Book!$E$4:$E$1008,B30) -> 0 | L30: =SUMIFS(Cash_Book!$G$4:$G$1008,Cash_Book!$C$4:$C$1008,"BEPAARI",Cash_Book!$D$4:$D$1008,"BHUSSA",Cash_Book!$E$4:$E$1008,B30) -> 0 | M30: =SUMIFS(Cash_Book!$G$4:$G$1008,Cash_Book!$C$4:$C$1008,"BEPAARI",Cash_Book!$D$4:$D$1008,"GAWALI",Cash_Book!$E$4:$E$1008,B30) -> 0 | N30: =SUMIFS(Cash_Book!$G$4:$G$1008,Cash_Book!$C$4:$C$1008,"BEPAARI",Cash_Book!$D$4:$D$1008,"CASH_ADV",Cash_Book!$E$4:$E$1008,B30) -> 0 | O30: =SUMIFS(Cash_Book!$G$4:$G$1008,Cash_Book!$C$4:$C$1008,"BEPAARI",Cash_Book!$D$4:$D$1008,"OTHER",Cash_Book!$E$4:$E$1008,B30) -> 0 | P30: =SUM(H30:O30) -> 0 | Q30: =IF(B30="","",F30-P30+E30) | R30: =SUMIFS(Cash_Book!$G$4:$G$1008,Cash_Book!$C$4:$C$1008,"BEPAARI",Cash_Book!$D$4:$D$1008,"PAYMENT",Cash_Book!$E$4:$E$1008,B30) -> 0 | S30: =IF(B30="","",Q30-R30)
A31: 27 | B31: =IF(Masters!$B$29="","",Masters!$B$29) | C31: =IF(B31="","",Masters!$C$29) | D31: =IF(B31="","",IF(Masters!$D$29="","",Masters!$D$29)) | E31: =IF(B31="",0,Masters!$E$29) -> 0 | F31: =SUMIF(Daily_Sales!$C$4:$C$503,B31,Daily_Sales!$G$4:$G$503) -> 0 | G31: =SUMIF(Daily_Sales!$C$4:$C$503,B31,Daily_Sales!$E$4:$E$503) -> 0 | H31: =IF(B31="",0,IF(D31<>"",D31*G31,F31*C31/100)) -> 0 | I31: =IF(G31>0,Masters!$Y$3,0) -> 0 | J31: =G31*Masters!$Y$4 -> 0 | K31: =SUMIFS(Cash_Book!$G$4:$G$1008,Cash_Book!$C$4:$C$1008,"BEPAARI",Cash_Book!$D$4:$D$1008,"MOTOR",Cash_Book!$E$4:$E$1008,B31) -> 0 | L31: =SUMIFS(Cash_Book!$G$4:$G$1008,Cash_Book!$C$4:$C$1008,"BEPAARI",Cash_Book!$D$4:$D$1008,"BHUSSA",Cash_Book!$E$4:$E$1008,B31) -> 0 | M31: =SUMIFS(Cash_Book!$G$4:$G$1008,Cash_Book!$C$4:$C$1008,"BEPAARI",Cash_Book!$D$4:$D$1008,"GAWALI",Cash_Book!$E$4:$E$1008,B31) -> 0 | N31: =SUMIFS(Cash_Book!$G$4:$G$1008,Cash_Book!$C$4:$C$1008,"BEPAARI",Cash_Book!$D$4:$D$1008,"CASH_ADV",Cash_Book!$E$4:$E$1008,B31) -> 0 | O31: =SUMIFS(Cash_Book!$G$4:$G$1008,Cash_Book!$C$4:$C$1008,"BEPAARI",Cash_Book!$D$4:$D$1008,"OTHER",Cash_Book!$E$4:$E$1008,B31) -> 0 | P31: =SUM(H31:O31) -> 0 | Q31: =IF(B31="","",F31-P31+E31) | R31: =SUMIFS(Cash_Book!$G$4:$G$1008,Cash_Book!$C$4:$C$1008,"BEPAARI",Cash_Book!$D$4:$D$1008,"PAYMENT",Cash_Book!$E$4:$E$1008,B31) -> 0 | S31: =IF(B31="","",Q31-R31)
