Workbook
Name BEPAARI: Masters!$B$3:$B$52
Name DUKANDAR: Masters!$I$3:$I$52
Name CAPITAL: Masters!$O$3:$O$32
Name LOAN: Masters!$O$3:$O$32
Name AMANAT: Masters!$O$3:$O$32
Name ADVANCE: Masters!$T$3:$T$22
Name EXPENSE: Lookups!$B$3:$B$3
Name ZAKAT: Lookups!$B$3:$B$3
Name DRAWINGS: Lookups!$B$3:$B$3
Name OTHER: Lookups!$B$3:$B$3
Name ST_BEPAARI: Lookups!$D$3:$D$8
Name ST_DUKANDAR: Lookups!$E$3:$E$5
Name ST_CAPITAL: Lookups!$F$3:$F$5
Name ST_LOAN: Lookups!$G$3:$G$4
Name ST_AMANAT: Lookups!$G$3:$G$4
Name ST_ADVANCE: Lookups!$H$3:$H$4
Name ST_EXPENSE: Lookups!$I$3:$I$14
Name ST_ZAKAT: Lookups!$J$3:$J$4
Name ST_DRAWINGS: Lookups!$K$3:$K$4
Name ST_OTHER: Lookups!$L$3:$L$4

Sheet Lookups
A1: LOOKUP TABLES (Do not edit)
B2: NO_PARTY | D2: ST_BEPAARI | E2: ST_DUKANDAR | F2: ST_CAPITAL | G2: ST_LOAN | H2: ST_ADVANCE | I2: ST_EXPENSE | J2: ST_ZAKAT | K2: ST_DRAWINGS | L2: ST_OTHER
B3: - | D3: PAYMENT | E3: RECEIPT | F3: TAKEN | G3: TAKEN | H3: GIVEN | I3: MANDI | J3: PROVISION | K3: MHN_PERSONAL | L3: MISC
D4: MOTOR | E4: DISCOUNT | F4: WITHDRAWN | G4: REPAID | H4: RECEIVED | I4: TRAVEL | J4: PAID | K4: ADJUSTED | L4: OTHER
D5: BHUSSA | E5: OTHER | F5: PROFIT_TO_CAP | I5: FOOD
D6: GAWALI | I6: SALARY
D7: CASH_ADV | I7: BF_DISC
D8: OTHER | I8: JB_PAID
I9: JB_WITHDRAW
I10: KK_WITHDRAW
I11: COMM_WITHDRAW
I12: PROFIT_WITHDRAW
I13: MISC
I14: OTHER

Sheet Masters
A1: BEPAARI MASTER | I1: DUKANDAR MASTER | O1: CAPITAL/LOAN/AMANAT | T1: ADVANCE PARTIES | X1: SETTINGS & OPENING BALANCES
A2: Sr | B2: Bepaari Name | C2: Comm% | D2: Flat ₹/Goat | E2: Opening Bal | F2: Phone | G2: Remarks | I2: Sr | J2: Dukandar Name | K2: Opening Bal | L2: Phone | M2: Remarks | O2: Sr | P2: Party Name | Q2: Opening Bal | R2: Type | T2: Sr | U2: Party Name | V2: Opening Bal | X2: Commission Rate (%) | Y2: 4
A3: 1 | B3: ABUL HASAN | C3: 4 | E3: 7550 | I3: 1 | J3: SAKIM | K3: 113500 | O3: 1 | P3: MHN CAPITAL | Q3: 4469981 | R3: CAPITAL | T3: 1 | X3: KK Fixed (₹/Bepari) | Y3: 25
A4: 2 | B4: SHARAFAT | C4: 4 | E4: 0 | I4: 2 | J4: SHARIK | K4: 879000 | O4: 2 | P4: SHAKIL GHODEGAON AMANAT | Q4: 2000000 | R4: AMANAT | T4: 2 | X4: JB Rate (₹/Goat) | Y4: 1
A5: 3 | B5: JUNAID | C5: 4 | E5: 0 | I5: 3 | J5: YUNUS | K5: 94931 | O5: 3 | T5: 3
A6: 4 | B6: ANNU SHARIF | C6: 4 | E6: 0 | I6: 4 | J6: MUDASSIR | K6: 516778 | O6: 4 | T6: 4 | X6: Opening Cash | Y6: 394906
A7: 5 | B7: GAYYUR | C7: 4 | E7: 142530 | I7: 5 | J7: ARIF | K7: 187650 | O7: 5 | T7: 5 | X7: Opening Bank | Y7: 724604
A8: 6 | B8: KISHOR | C8: 4 | E8: -152964 | I8: 6 | J8: SHOEB BYCULLA | K8: 0 | O8: 6 | T8: 6
A9: 7 | B9: MAULANA | C9: 4 | E9: 35330 | I9: 7 | J9: ISLAM D | K9: 100000 | O9: 7 | T9: 7 | X9: --- B/F LIABILITIES ---
A10: 8 | B10: SALIM RAJ | C10: 4 | E10: 0 | I10: 8 | J10: MEHMOOD MADH | K10: 15000 | O10: 8 | T10: 8 | X10: JB Opening (B/F) | Y10: 17100
A11: 9 | B11: ANAS RAJ | C11: 4 | E11: 0 | I11: 9 | J11: MOBIN CHIPLUN | K11: 486250 | O11: 9 | T11: 9 | X11: KK Opening (B/F) | Y11: 10100
A12: 10 | B12: AYAZ | C12: 4 | E12: 1530 | I12: 10 | J12: JALIL | K12: 90950 | O12: 10 | T12: 10 | X12: Zakat Opening (B/F) | Y12: 73111
A13: 11 | B13: NEERAJ | C13: 4 | E13: 0 | I13: 11 | J13: IRFAN JOGESHWARI | K13: 0 | O13: 11 | T13: 11 | X13: Commission Opening (B/F) | Y13: 358808
A14: 12 | B14: CHINTU SHUJALPUR | C14: 4 | E14: 0 | I14: 12 | J14: YUNUS DOMBIVLI | K14: 59662 | O14: 12 | T14: 12
A15: 13 | B15: SANNA | C15: 4 | E15: -14048 | I15: 13 | J15: IFTEKHAR PUNE | K15: 2000 | O15: 13 | T15: 13 | X15: --- B/F ASSETS ---
A16: 14 | B16: WAHID | C16: 4 | E16: -4661 | I16: 14 | J16: LALA/ASIF | K16: 0 | O16: 14 | T16: 14 | X16: Mandi Exp Opening (B/F) | Y16: 17450
A17: 15 | B17: MANSOOR | C17: 4 | E17: -9845 | I17: 15 | J17: JAFER KASHIMIRA | K17: 92500 | O17: 15 | T17: 15 | X17: BF Discount Opening (B/F) | Y17: 24816
A18: 16 | B18: AYAZ PREVIOUS BAL | C18: 4 | E18: -88000 | I18: 16 | J18: HANIF KALAM | K18: 0 | O18: 16 | T18: 16 | X18: MHN Personal Opening (B/F) | Y18: 294265
A19: 17 | B19: SHAKIL SHUJALPUR | C19: 4 | E19: 660 | I19: 17 | J19: SAUD K | K19: 0 | O19: 17 | T19: 17
A20: 18 | B20: USMAN | C20: 4 | E20: 40440 | I20: 18 | J20: AKRAM | K20: 0 | O20: 18 | T20: 18
A21: 19 | C21: 4 | I21: 19 | J21: WAHID | K21: 4000 | O21: 19 | T21: 19
A22: 20 | C22: 4 | I22: 20 | J22: VAZIR | K22: 134750 | O22: 20 | T22: 20
A23: 21 | C23: 4 | I23: 21 | J23: ISMAIL SOPARA | K23: 0 | O23: 21
A24: 22 | C24: 4 | I24: 22 | J24: ARIF CHINCHOTI | K24: 0 | O24: 22
A25: 23 | C25: 4 | I25: 23 | J25: NADEEM BHIWANDI | K25: 265000 | O25: 23
A26: 24 | C26: 4 | I26: 24 | J26: GABBAR | K26: 33050 | O26: 24
A27: 25 | C27: 4 | I27: 25 | J27: BABU GABBAR | K27: 50000 | O27: 25
A28: 26 | C28: 4 | I28: 26 | J28: BABU TALOJA | K28: 2600 | O28: 26
A29: 27 | C29: 4 | I29: 27 | J29: SHAKIL KON | K29: 34000 | O29: 27
A30: 28 | C30: 4 | I30: 28 | J30: PARVEZ | K30: 0 | O30: 28
A31: 29 | C31: 4 | I31: 29 | J31: I CHO CHO | K31: 20500 | O31: 29
A32: 30 | C32: 4 | I32: 30 | J32: MD VIRAR | K32: 1900 | O32: 30
A33: 31 | C33: 4 | I33: 31 | J33: MAYA | K33: 11000
A34: 32 | C34: 4 | I34: 32 | J34: NAEEM THORPE | K34: 0
A35: 33 | C35: 4 | I35: 33 | J35: CHAND | K35: 59000
A36: 34 | C36: 4 | I36: 34 | J36: ASIF GOREGAON | K36: 57550
A37: 35 | C37: 4 | I37: 35 | J37: SOHAIL MAROL | K37: 0
A38: 36 | C38: 4 | I38: 36 | J38: ANEES KM | K38: 70000
A39: 37 | C39: 4 | I39: 37 | J39: RAFIQ AHMED HAJI | K39: 356250
A40: 38 | C40: 4 | I40: 38 | J40: ABP - MAJEED THANA | K40: 0
...

Sheet Daily_Sales
A1: DAILY SALES (Bepaari to Dukandar)
A3: Sr | B3: Date | C3: Bepaari | D3: Dukandar | E3: Qty | F3: Rate | G3: Gross | H3: Discount | I3: Net
A4: 1 | G4: =IF(E4="","",E4*F4) | I4: =IF(G4="","",G4-IF(H4="",0,H4))
A5: 2 | G5: =IF(E5="","",E5*F5) | I5: =IF(G5="","",G5-IF(H5="",0,H5))
A6: 3 | G6: =IF(E6="","",E6*F6) | I6: =IF(G6="","",G6-IF(H6="",0,H6))
A7: 4 | G7: =IF(E7="","",E7*F7) | I7: =IF(G7="","",G7-IF(H7="",0,H7))
A8: 5 | G8: =IF(E8="","",E8*F8) | I8: =IF(G8="","",G8-IF(H8="",0,H8))
A9: 6 | G9: =IF(E9="","",E9*F9) | I9: =IF(G9="","",G9-IF(H9="",0,H9))
A10: 7 | G10: =IF(E10="","",E10*F10) | I10: =IF(G10="","",G10-IF(H10="",0,H10))
A11: 8 | G11: =IF(E11="","",E11*F11) | I11: =IF(G11="","",G11-IF(H11="",0,H11))
A12: 9 | G12: =IF(E12="","",E12*F12) | I12: =IF(G12="","",G12-IF(H12="",0,H12))
A13: 10 | G13: =IF(E13="","",E13*F13) | I13: =IF(G13="","",G13-IF(H13="",0,H13))
A14: 11 | G14: =IF(E14="","",E14*F14) | I14: =IF(G14="","",G14-IF(H14="",0,H14))
A15: 12 | G15: =IF(E15="","",E15*F15) | I15: =IF(G15="","",G15-IF(H15="",0,H15))
... A503: 500 | G503: =IF(E503="","",E503*F503) | I503: =IF(G503="","",G503-IF(H503="",0,H503))

Sheet Cash_Book
A1: CASH BOOK (All Transactions) | J1: CASH/BANK SUMMARY
A2: Select TYPE first → Sub-Type & Party dropdowns update automatically | I2: Opening Cash | J2: =Masters!$Y$6
A3: Sr | B3: Date | C3: Type | D3: Sub-Type | E3: Party | F3: Particulars | G3: Amount | H3: Mode | I3: Opening Bank | J3: =Masters!$Y$7
A4: 1
A5: 2 | I5: Cash OUT | J5: =SUMIFS(G:G,H:H,"CASH",D:D,"PAYMENT")+SUMIFS(G:G,H:H,"CASH",D:D,"MOTOR")+SUMIFS(G:G,H:H,"CASH",D:D,"BHUSSA")+SUMIFS(G:G,H:H,"CASH",D:D,"GAWALI")+SUMIFS(G:G,H:H,"CASH",D:D,"CASH_ADV")+SUMIFS(G:G,H:H,"CASH",D:D,"DISCOUNT")+SUMIFS(G:G,H:H,"CASH",D:D,"WITHDRAWN")+SUMIFS(G:G,H:H,"CASH",D:D,"REPAID")+SUMIFS(G:G,H:H,"CASH",D:D,"GIVEN")+SUMIFS(G:G,H:H,"CASH",D:D,"MANDI")+SUMIFS(G:G,H:H,"CASH",D:D,"TRAVEL")+SUMIFS(G:G,H:H,"CASH",D:D,"FOOD")+SUMIFS(G:G,H:H,"CASH",D:D,"SALARY")+SUMIFS(G:G,H:H,"CASH",D:D,"BF_DISC")+SUMIFS(G:G,H:H,"CASH",D:D,"JB_PAID")+SUMIFS(G:G,H:H,"CASH",D:D,"JB_WITHDRAW")+SUMIFS(G:G,H:H,"CASH",D:D,"KK_WITHDRAW")+SUMIFS(G:G,H:H,"CASH",D:D,"COMM_WITHDRAW")+SUMIFS(G:G,H:H,"CASH",D:D,"PROFIT_WITHDRAW")+SUMIFS(G:G,H:H,"CASH",D:D,"PAID")+SUMIFS(G:G,H:H,"CASH",D:D,"MISC")+SUMIFS(G:G,H:H,"CASH",D:D,"OTHER")+SUMIFS(G:G,H:H,"CASH",D:D,"MHN_PERSONAL")+SUMIFS(G:G,H:H,"CASH",D:D,"ADJUSTED")+SUMIFS(G:G,H:H,"CASH",D:D,"PROFIT_TO_CAP")
A6: 3 | I6: Bank OUT | J6: =SUMIFS(G:G,H:H,"BANK",D:D,"PAYMENT")+SUMIFS(G:G,H:H,"BANK",D:D,"MOTOR")+SUMIFS(G:G,H:H,"BANK",D:D,"BHUSSA")+SUMIFS(G:G,H:H,"BANK",D:D,"GAWALI")+SUMIFS(G:G,H:H,"BANK",D:D,"CASH_ADV")+SUMIFS(G:G,H:H,"BANK",D:D,"DISCOUNT")+SUMIFS(G:G,H:H,"BANK",D:D,"WITHDRAWN")+SUMIFS(G:G,H:H,"BANK",D:D,"REPAID")+SUMIFS(G:G,H:H,"BANK",D:D,"GIVEN")+SUMIFS(G:G,H:H,"BANK",D:D,"MANDI")+SUMIFS(G:G,H:H,"BANK",D:D,"TRAVEL")+SUMIFS(G:G,H:H,"BANK",D:D,"FOOD")+SUMIFS(G:G,H:H,"BANK",D:D,"SALARY")+SUMIFS(G:G,H:H,"BANK",D:D,"BF_DISC")+SUMIFS(G:G,H:H,"BANK",D:D,"JB_PAID")+SUMIFS(G:G,H:H,"BANK",D:D,"JB_WITHDRAW")+SUMIFS(G:G,H:H,"BANK",D:D,"KK_WITHDRAW")+SUMIFS(G:G,H:H,"BANK",D:D,"COMM_WITHDRAW")+SUMIFS(G:G,H:H,"BANK",D:D,"PROFIT_WITHDRAW")+SUMIFS(G:G,H:H,"BANK",D:D,"PAID")+SUMIFS(G:G,H:H,"BANK",D:D,"MISC")+SUMIFS(G:G,H:H,"BANK",D:D,"OTHER")+SUMIFS(G:G,H:H,"BANK",D:D,"MHN_PERSONAL")+SUMIFS(G:G,H:H,"BANK",D:D,"ADJUSTED")+SUMIFS(G:G,H:H,"BANK",D:D,"PROFIT_TO_CAP")+SUMIFS(G:G,H:H,"UPI",D:D,"PAYMENT")+SUMIFS(G:G,H:H,"UPI",D:D,"MOTOR")+SUMIFS(G:G,H:H,"UPI",D:D,"BHUSSA")+SUMIFS(G:G,H:H,"UPI",D:D,"GAWALI")+SUMIFS(G:G,H:H,"UPI",D:D,"CASH_ADV")+SUMIFS(G:G,H:H,"UPI",D:D,"DISCOUNT")+SUMIFS(G:G,H:H,"UPI",D:D,"WITHDRAWN")+SUMIFS(G:G,H:H,"UPI",D:D,"REPAID")+SUMIFS(G:G,H:H,"UPI",D:D,"GIVEN")+SUMIFS(G:G,H:H,"UPI",D:D,"MANDI")+SUMIFS(G:G,H:H,"UPI",D:D,"TRAVEL")+SUMIFS(G:G,H:H,"UPI",D:D,"FOOD")+SUMIFS(G:G,H:H,"UPI",D:D,"SALARY")+SUMIFS(G:G,H:H,"UPI",D:D,"BF_DISC")+SUMIFS(G:G,H:H,"UPI",D:D,"JB_PAID")+SUMIFS(G:G,H:H,"UPI",D:D,"JB_WITHDRAW")+SUMIFS(G:G,H:H,"UPI",D:D,"KK_WITHDRAW")+SUMIFS(G:G,H:H,"UPI",D:D,"COMM_WITHDRAW")+SUMIFS(G:G,H:H,"UPI",D:D,"PROFIT_WITHDRAW")+SUMIFS(G:G,H:H,"UPI",D:D,"PAID")+SUMIFS(G:G,H:H,"UPI",D:D,"MISC")+SUMIFS(G:G,H:H,"UPI",D:D,"OTHER")+SUMIFS(G:G,H:H,"UPI",D:D,"MHN_PERSONAL")+SUMIFS(G:G,H:H,"UPI",D:D,"ADJUSTED")+SUMIFS(G:G,H:H,"UPI",D:D,"PROFIT_TO_CAP")+SUMIFS(G:G,H:H,"TRANSFER",D:D,"PAYMENT")+SUMIFS(G:G,H:H,"TRANSFER",D:D,"MOTOR")+SUMIFS(G:G,H:H,"TRANSFER",D:D,"BHUSSA")+SUMIFS(G:G,H:H,"TRANSFER",D:D,"GAWALI")+SUMIFS(G:G,H:H,"TRANSFER",D:D,"CASH_ADV")+SUMIFS(G:G,H:H,"TRANSFER",D:D,"DISCOUNT")+SUMIFS(G:G,H:H,"TRANSFER",D:D,"WITHDRAWN")+SUMIFS(G:G,H:H,"TRANSFER",D:D,"REPAID")+SUMIFS(G:G,H:H,"TRANSFER",D:D,"GIVEN")+SUMIFS(G:G,H:H,"TRANSFER",D:D,"MANDI")+SUMIFS(G:G,H:H,"TRANSFER",D:D,"TRAVEL")+SUMIFS(G:G,H:H,"TRANSFER",D:D,"FOOD")+SUMIFS(G:G,H:H,"TRANSFER",D:D,"SALARY")+SUMIFS(G:G,H:H,"TRANSFER",D:D,"BF_DISC")+SUMIFS(G:G,H:H,"TRANSFER",D:D,"JB_PAID")+SUMIFS(G:G,H:H,"TRANSFER",D:D,"JB_WITHDRAW")+SUMIFS(G:G,H:H,"TRANSFER",D:D,"KK_WITHDRAW")+SUMIFS(G:G,H:H,"TRANSFER",D:D,"COMM_WITHDRAW")+SUMIFS(G:G,H:H,"TRANSFER",D:D,"PROFIT_WITHDRAW")+SUMIFS(G:G,H:H,"TRANSFER",D:D,"PAID")+SUMIFS(G:G,H:H,"TRANSFER",D:D,"MISC")+SUMIFS(G:G,H:H,"TRANSFER",D:D,"OTHER")+SUMIFS(G:G,H:H,"TRANSFER",D:D,"MHN_PERSONAL")+SUMIFS(G:G,H:H,"TRANSFER",D:D,"ADJUSTED")+SUMIFS(G:G,H:H,"TRANSFER",D:D,"PROFIT_TO_CAP")
A7: 4 | I7: Cash IN | J7: =SUMIFS(G:G,H:H,"CASH",D:D,"RECEIPT")+SUMIFS(G:G,H:H,"CASH",D:D,"TAKEN")+SUMIFS(G:G,H:H,"CASH",D:D,"RECEIVED")+SUMIFS(G:G,H:H,"CASH",D:D,"PROVISION")
A8: 5 | I8: Bank IN | J8: =SUMIFS(G:G,H:H,"BANK",D:D,"RECEIPT")+SUMIFS(G:G,H:H,"BANK",D:D,"TAKEN")+SUMIFS(G:G,H:H,"BANK",D:D,"RECEIVED")+SUMIFS(G:G,H:H,"BANK",D:D,"PROVISION")+SUMIFS(G:G,H:H,"UPI",D:D,"RECEIPT")+SUMIFS(G:G,H:H,"UPI",D:D,"TAKEN")+SUMIFS(G:G,H:H,"UPI",D:D,"RECEIVED")+SUMIFS(G:G,H:H,"UPI",D:D,"PROVISION")+SUMIFS(G:G,H:H,"TRANSFER",D:D,"RECEIPT")+SUMIFS(G:G,H:H,"TRANSFER",D:D,"TAKEN")+SUMIFS(G:G,H:H,"TRANSFER",D:D,"RECEIVED")+SUMIFS(G:G,H:H,"TRANSFER",D:D,"PROVISION")
A9: 6
A10: 7 | I10: CLOSING CASH | J10: =J2-J5+J7
A11: 8 | I11: CLOSING BANK | J11: =J3-J6+J8
A12: 9
A13: 10
A14: 11
A15: 12
A16: 13
A17: 14
A18: 15
A19: 16
A20: 17
A21: 18
A22: 19
A23: 20
... A1003: 1000

Sheet JV_Entries
A1: JOURNAL VOUCHER ENTRIES (Internal Adjustments)
A2: Use for: Dukandar-to-Dukandar transfers, Bepaari adjustments, any non-cash internal entries
A4: Sr | B4: Date | C4: Debit Type | D4: Debit Party | E4: Credit Type | F4: Credit Party | G4: Amount | H4: Narration
A5: 1
A6: 2
A7: 3
A8: 4
A9: 5
A10: 6
A11: 7
A12: 8
A13: 9
A14: 10
A15: 11
A16: 12
... A104: 100

Sheet Adjustments
A1: MANUAL ADJUSTMENTS (Corrections & Overrides)
A2: Use for: Opening balance corrections, error fixes, any manual override
A4: Sr | B4: Date | C4: Account Type | D4: Party | E4: DR/CR | F4: Amount | G4: Narration
A5: 1
A6: 2
A7: 3
A8: 4
A9: 5
A10: 6
A11: 7
A12: 8
A13: 9
A14: 10
A15: 11
A16: 12
... A104: 100

Sheet Bepaari_Ledger
A1: BEPAARI LEDGER
A2: Commission = Flat ₹/Goat if set, otherwise Comm%
A4: Sr | B4: Bepaari | C4: Comm% | D4: Flat₹ | E4: Opening | F4: Gross Sales | G4: Qty | H4: Commission | I4: KK | J4: JB | K4: Motor | L4: Bhussa | M4: Gawali | N4: Cash/Adv | O4: Other | P4: Tot.Deduct | Q4: Net Payable | R4: Payments | S4: JV Adj | T4: BALANCE
A5: 1 | B5: =IF(Masters!$B$3="","",Masters!$B$3) | C5: =IF(B5="","",Masters!$C$3) | D5: =IF(B5="","",IF(Masters!$D$3="","",Masters!$D$3)) | E5: =IF(B5="",0,Masters!$E$3) | F5: =SUMIF(Daily_Sales!$C:$C,B5,Daily_Sales!$G:$G) | G5: =SUMIF(Daily_Sales!$C:$C,B5,Daily_Sales!$E:$E) | H5: =IF(B5="",0,IF(D5<>"",D5*G5,F5*C5/100)) | I5: =IF(G5>0,Masters!$Y$3,0) | J5: =G5*Masters!$Y$4 | K5: =SUMIFS(Cash_Book!$G:$G,Cash_Book!$C:$C,"BEPAARI",Cash_Book!$D:$D,"MOTOR",Cash_Book!$E:$E,B5) | L5: =SUMIFS(Cash_Book!$G:$G,Cash_Book!$C:$C,"BEPAARI",Cash_Book!$D:$D,"BHUSSA",Cash_Book!$E:$E,B5) | M5: =SUMIFS(Cash_Book!$G:$G,Cash_Book!$C:$C,"BEPAARI",Cash_Book!$D:$D,"GAWALI",Cash_Book!$E:$E,B5) | N5: =SUMIFS(Cash_Book!$G:$G,Cash_Book!$C:$C,"BEPAARI",Cash_Book!$D:$D,"CASH_ADV",Cash_Book!$E:$E,B5) | O5: =SUMIFS(Cash_Book!$G:$G,Cash_Book!$C:$C,"BEPAARI",Cash_Book!$D:$D,"OTHER",Cash_Book!$E:$E,B5) | P5: =SUM(H5:O5) | Q5: =IF(B5="","",F5-P5+E5) | R5: =SUMIFS(Cash_Book!$G:$G,Cash_Book!$C:$C,"BEPAARI",Cash_Book!$D:$D,"PAYMENT",Cash_Book!$E:$E,B5) | S5: =SUMIFS(JV_Entries!$G:$G,JV_Entries!$C:$C,"BEPAARI",JV_Entries!$D:$D,B5)-SUMIFS(JV_Entries!$G:$G,JV_Entries!$E:$E,"BEPAARI",JV_Entries!$F:$F,B5) | T5: =IF(B5="","",Q5-R5+S5)
A6: 2 | B6: =IF(Masters!$B$4="","",Masters!$B$4) | C6: =IF(B6="","",Masters!$C$4) | D6: =IF(B6="","",IF(Masters!$D$4="","",Masters!$D$4)) | E6: =IF(B6="",0,Masters!$E$4) | F6: =SUMIF(Daily_Sales!$C:$C,B6,Daily_Sales!$G:$G) | G6: =SUMIF(Daily_Sales!$C:$C,B6,Daily_Sales!$E:$E) | H6: =IF(B6="",0,IF(D6<>"",D6*G6,F6*C6/100)) | I6: =IF(G6>0,Masters!$Y$3,0) | J6: =G6*Masters!$Y$4 | K6: =SUMIFS(Cash_Book!$G:$G,Cash_Book!$C:$C,"BEPAARI",Cash_Book!$D:$D,"MOTOR",Cash_Book!$E:$E,B6) | L6: =SUMIFS(Cash_Book!$G:$G,Cash_Book!$C:$C,"BEPAARI",Cash_Book!$D:$D,"BHUSSA",Cash_Book!$E:$E,B6) | M6: =SUMIFS(Cash_Book!$G:$G,Cash_Book!$C:$C,"BEPAARI",Cash_Book!$D:$D,"GAWALI",Cash_Book!$E:$E,B6) | N6: =SUMIFS(Cash_Book!$G:$G,Cash_Book!$C:$C,"BEPAARI",Cash_Book!$D:$D,"CASH_ADV",Cash_Book!$E:$E,B6) | O6: =SUMIFS(Cash_Book!$G:$G,Cash_Book!$C:$C,"BEPAARI",Cash_Book!$D:$D,"OTHER",Cash_Book!$E:$E,B6) | P6: =SUM(H6:O6) | Q6: =IF(B6="","",F6-P6+E6) | R6: =SUMIFS(Cash_Book!$G:$G,Cash_Book!$C:$C,"BEPAARI",Cash_Book!$D:$D,"PAYMENT",Cash_Book!$E:$E,B6) | S6: =SUMIFS(JV_Entries!$G:$G,JV_Entries!$C:$C,"BEPAARI",JV_Entries!$D:$D,B6)-SUMIFS(JV_Entries!$G:$G,JV_Entries!$E:$E,"BEPAARI",JV_Entries!$F:$F,B6) | T6: =IF(B6="","",Q6-R6+S6)
A7: 3 | B7: =IF(Masters!$B$5="","",Masters!$B$5) | C7: =IF(B7="","",Masters!$C$5) | D7: =IF(B7="","",IF(Masters!$D$5="","",Masters!$D$5)) | E7: =IF(B7="",0,Masters!$E$5) | F7: =SUMIF(Daily_Sales!$C:$C,B7,Daily_Sales!$G:$G) | G7: =SUMIF(Daily_Sales!$C:$C,B7,Daily_Sales!$E:$E) | H7: =IF(B7="",0,IF(D7<>"",D7*G7,F7*C7/100)) | I7: =IF(G7>0,Masters!$Y$3,0) | J7: =G7*Masters!$Y$4 | K7: =SUMIFS(Cash_Book!$G:$G,Cash_Book!$C:$C,"BEPAARI",Cash_Book!$D:$D,"MOTOR",Cash_Book!$E:$E,B7) | L7: =SUMIFS(Cash_Book!$G:$G,Cash_Book!$C:$C,"BEPAARI",Cash_Book!$D:$D,"BHUSSA",Cash_Book!$E:$E,B7) | M7: =SUMIFS(Cash_Book!$G:$G,Cash_Book!$C:$C,"BEPAARI",Cash_Book!$D:$D,"GAWALI",Cash_Book!$E:$E,B7) | N7: =SUMIFS(Cash_Book!$G:$G,Cash_Book!$C:$C,"BEPAARI",Cash_Book!$D:$D,"CASH_ADV",Cash_Book!$E:$E,B7) | O7: =SUMIFS(Cash_Book!$G:$G,Cash_Book!$C:$C,"BEPAARI",Cash_Book!$D:$D,"OTHER",Cash_Book!$E:$E,B7) | P7: =SUM(H7:O7) | Q7: =IF(B7="","",F7-P7+E7) | R7: =SUMIFS(Cash_Book!$G:$G,Cash_Book!$C:$C,"BEPAARI",Cash_Book!$D:$D,"PAYMENT",Cash_Book!$E:$E,B7) | S7: =SUMIFS(JV_Entries!$G:$G,JV_Entries!$C:$C,"BEPAARI",JV_Entries!$D:$D,B7)-SUMIFS(JV_Entries!$G:$G,JV_Entries!$E:$E,"BEPAARI",JV_Entries!$F:$F,B7) | T7: =IF(B7="","",Q7-R7+S7)
A8: 4 | B8: =IF(Masters!$B$6="","",Masters!$B$6) | C8: =IF(B8="","",Masters!$C$6) | D8: =IF(B8="","",IF(Masters!$D$6="","",Masters!$D$6)) | E8: =IF(B8="",0,Masters!$E$6) | F8: =SUMIF(Daily_Sales!$C:$C,B8,Daily_Sales!$G:$G) | G8: =SUMIF(Daily_Sales!$C:$C,B8,Daily_Sales!$E:$E) | H8: =IF(B8="",0,IF(D8<>"",D8*G8,F8*C8/100)) | I8: =IF(G8>0,Masters!$Y$3,0) | J8: =G8*Masters!$Y$4 | K8: =SUMIFS(Cash_Book!$G:$G,Cash_Book!$C:$C,"BEPAARI",Cash_Book!$D:$D,"MOTOR",Cash_Book!$E:$E,B8) | L8: =SUMIFS(Cash_Book!$G:$G,Cash_Book!$C:$C,"BEPAARI",Cash_Book!$D:$D,"BHUSSA",Cash_Book!$E:$E,B8) | M8: =SUMIFS(Cash_Book!$G:$G,Cash_Book!$C:$C,"BEPAARI",Cash_Book!$D:$D,"GAWALI",Cash_Book!$E:$E,B8) | N8: =SUMIFS(Cash_Book!$G:$G,Cash_Book!$C:$C,"BEPAARI",Cash_Book!$D:$D,"CASH_ADV",Cash_Book!$E:$E,B8) | O8: =SUMIFS(Cash_Book!$G:$G,Cash_Book!$C:$C,"BEPAARI",Cash_Book!$D:$D,"OTHER",Cash_Book!$E:$E,B8) | P8: =SUM(H8:O8) | Q8: =IF(B8="","",F8-P8+E8) | R8: =SUMIFS(Cash_Book!$G:$G,Cash_Book!$C:$C,"BEPAARI",Cash_Book!$D:$D,"PAYMENT",Cash_Book!$E:$E,B8) | S8: =SUMIFS(JV_Entries!$G:$G,JV_Entries!$C:$C,"BEPAARI",JV_Entries!$D:$D,B8)-SUMIFS(JV_Entries!$G:$G,JV_Entries!$E:$E,"BEPAARI",JV_Entries!$F:$F,B8) | T8: =IF(B8="","",Q8-R8+S8)
A9: 5 | B9: =IF(Masters!$B$7="","",Masters!$B$7) | C9: =IF(B9="","",Masters!$C$7) | D9: =IF(B9="","",IF(Masters!$D$7="","",Masters!$D$7)) | E9: =IF(B9="",0,Masters!$E$7) | F9: =SUMIF(Daily_Sales!$C:$C,B9,Daily_Sales!$G:$G) | G9: =SUMIF(Daily_Sales!$C:$C,B9,Daily_Sales!$E:$E) | H9: =IF(B9="",0,IF(D9<>"",D9*G9,F9*C9/100)) | I9: =IF(G9>0,Masters!$Y$3,0) | J9: =G9*Masters!$Y$4 | K9: =SUMIFS(Cash_Book!$G:$G,Cash_Book!$C:$C,"BEPAARI",Cash_Book!$D:$D,"MOTOR",Cash_Book!$E:$E,B9) | L9: =SUMIFS(Cash_Book!$G:$G,Cash_Book!$C:$C,"BEPAARI",Cash_Book!$D:$D,"BHUSSA",Cash_Book!$E:$E,B9) | M9: =SUMIFS(Cash_Book!$G:$G,Cash_Book!$C:$C,"BEPAARI",Cash_Book!$D:$D,"GAWALI",Cash_Book!$E:$E,B9) | N9: =SUMIFS(Cash_Book!$G:$G,Cash_Book!$C:$C,"BEPAARI",Cash_Book!$D:$D,"CASH_ADV",Cash_Book!$E:$E,B9) | O9: =SUMIFS(Cash_Book!$G:$G,Cash_Book!$C:$C,"BEPAARI",Cash_Book!$D:$D,"OTHER",Cash_Book!$E:$E,B9) | P9: =SUM(H9:O9) | Q9: =IF(B9="","",F9-P9+E9) | R9: =SUMIFS(Cash_Book!$G:$G,Cash_Book!$C:$C,"BEPAARI",Cash_Book!$D:$D,"PAYMENT",Cash_Book!$E:$E,B9) | S9: =SUMIFS(JV_Entries!$G:$G,JV_Entries!$C:$C,"BEPAARI",JV_Entries!$D:$D,B9)-SUMIFS(JV_Entries!$G:$G,JV_Entries!$E:$E,"BEPAARI",JV_Entries!$F:$F,B9) | T9: =IF(B9="","",Q9-R9+S9)
A10: 6 | B10: =IF(Masters!$B$8="","",Masters!$B$8) | C10: =IF(B10="","",Masters!$C$8) | D10: =IF(B10="","",IF(Masters!$D$8="","",Masters!$D$8)) | E10: =IF(B10="",0,Masters!$E$8) | F10: =SUMIF(Daily_Sales!$C:$C,B10,Daily_Sales!$G:$G) | G10: =SUMIF(Daily_Sales!$C:$C,B10,Daily_Sales!$E:$E) | H10: =IF(B10="",0,IF(D10<>"",D10*G10,F10*C10/100)) | I10: =IF(G10>0,Masters!$Y$3,0) | J10: =G10*Masters!$Y$4 | K10: =SUMIFS(Cash_Book!$G:$G,Cash_Book!$C:$C,"BEPAARI",Cash_Book!$D:$D,"MOTOR",Cash_Book!$E:$E,B10) | L10: =SUMIFS(Cash_Book!$G:$G,Cash_Book!$C:$C,"BEPAARI",Cash_Book!$D:$D,"BHUSSA",Cash_Book!$E:$E,B10) | M10: =SUMIFS(Cash_Book!$G:$G,Cash_Book!$C:$C,"BEPAARI",Cash_Book!$D:$D,"GAWALI",Cash_Book!$E:$E,B10) | N10: =SUMIFS(Cash_Book!$G:$G,Cash_Book!$C:$C,"BEPAARI",Cash_Book!$D:$D,"CASH_ADV",Cash_Book!$E:$E,B10) | O10: =SUMIFS(Cash_Book!$G:$G,Cash_Book!$C:$C,"BEPAARI",Cash_Book!$D:$D,"OTHER",Cash_Book!$E:$E,B10) | P10: =SUM(H10:O10) | Q10: =IF(B10="","",F10-P10+E10) | R10: =SUMIFS(Cash_Book!$G:$G,Cash_Book!$C:$C,"BEPAARI",Cash_Book!$D:$D,"PAYMENT",Cash_Book!$E:$E,B10) | S10: =SUMIFS(JV_Entries!$G:$G,JV_Entries!$C:$C,"BEPAARI",JV_Entries!$D:$D,B10)-SUMIFS(JV_Entries!$G:$G,JV_Entries!$E:$E,"BEPAARI",JV_Entries!$F:$F,B10) | T10: =IF(B10="","",Q10-R10+S10)
A11: 7 | B11: =IF(Masters!$B$9="","",Masters!$B$9) | C11: =IF(B11="","",Masters!$C$9) | D11: =IF(B11="","",IF(Masters!$D$9="","",Masters!$D$9)) | E11: =IF(B11="",0,Masters!$E$9) | F11: =SUMIF(Daily_Sales!$C:$C,B11,Daily_Sales!$G:$G) | G11: =SUMIF(Daily_Sales!$C:$C,B11,Daily_Sales!$E:$E) | H11: =IF(B11="",0,IF(D11<>"",D11*G11,F11*C11/100)) | I11: =IF(G11>0,Masters!$Y$3,0) | J11: =G11*Masters!$Y$4 | K11: =SUMIFS(Cash_Book!$G:$G,Cash_Book!$C:$C,"BEPAARI",Cash_Book!$D:$D,"MOTOR",Cash_Book!$E:$E,B11) | L11: =SUMIFS(Cash_Book!$G:$G,Cash_Book!$C:$C,"BEPAARI",Cash_Book!$D:$D,"BHUSSA",Cash_Book!$E:$E,B11) | M11: =SUMIFS(Cash_Book!$G:$G,Cash_Book!$C:$C,"BEPAARI",Cash_Book!$D:$D,"GAWALI",Cash_Book!$E:$E,B11) | N11: =SUMIFS(Cash_Book!$G:$G,Cash_Book!$C:$C,"BEPAARI",Cash_Book!$D:$D,"CASH_ADV",Cash_Book!$E:$E,B11) | O11: =SUMIFS(Cash_Book!$G:$G,Cash_Book!$C:$C,"BEPAARI",Cash_Book!$D:$D,"OTHER",Cash_Book!$E:$E,B11) | P11: =SUM(H11:O11) | Q11: =IF(B11="","",F11-P11+E11) | R11: =SUMIFS(Cash_Book!$G:$G,Cash_Book!$C:$C,"BEPAARI",Cash_Book!$D:$D,"PAYMENT",Cash_Book!$E:$E,B11) | S11: =SUMIFS(JV_Entries!$G:$G,JV_Entries!$C:$C,"BEPAARI",JV_Entries!$D:$D,B11)-SUMIFS(JV_Entries!$G:$G,JV_Entries!$E:$E,"BEPAARI",JV_Entries!$F:$F,B11) | T11: =IF(B11="","",Q11-R11+S11)
A12: 8 | B12: =IF(Masters!$B$10="","",Masters!$B$10) | C12: =IF(B12="","",Masters!$C$10) | D12: =IF(B12="","",IF(Masters!$D$10="","",Masters!$D$10)) | E12: =IF(B12="",0,Masters!$E$10) | F12: =SUMIF(Daily_Sales!$C:$C,B12,Daily_Sales!$G:$G) | G12: =SUMIF(Daily_Sales!$C:$C,B12,Daily_Sales!$E:$E) | H12: =IF(B12="",0,IF(D12<>"",D12*G12,F12*C12/100)) | I12: =IF(G12>0,Masters!$Y$3,0) | J12: =G12*Masters!$Y$4 | K12: =SUMIFS(Cash_Book!$G:$G,Cash_Book!$C:$C,"BEPAARI",Cash_Book!$D:$D,"MOTOR",Cash_Book!$E:$E,B12) | L12: =SUMIFS(Cash_Book!$G:$G,Cash_Book!$C:$C,"BEPAARI",Cash_Book!$D:$D,"BHUSSA",Cash_Book!$E:$E,B12) | M12: =SUMIFS(Cash_Book!$G:$G,Cash_Book!$C:$C,"BEPAARI",Cash_Book!$D:$D,"GAWALI",Cash_Book!$E:$E,B12) | N12: =SUMIFS(Cash_Book!$G:$G,Cash_Book!$C:$C,"BEPAARI",Cash_Book!$D:$D,"CASH_ADV",Cash_Book!$E:$E,B12) | O12: =SUMIFS(Cash_Book!$G:$G,Cash_Book!$C:$C,"BEPAARI",Cash_Book!$D:$D,"OTHER",Cash_Book!$E:$E,B12) | P12: =SUM(H12:O12) | Q12: =IF(B12="","",F12-P12+E12) | R12: =SUMIFS(Cash_Book!$G:$G,Cash_Book!$C:$C,"BEPAARI",Cash_Book!$D:$D,"PAYMENT",Cash_Book!$E:$E,B12) | S12: =SUMIFS(JV_Entries!$G:$G,JV_Entries!$C:$C,"BEPAARI",JV_Entries!$D:$D,B12)-SUMIFS(JV_Entries!$G:$G,JV_Entries!$E:$E,"BEPAARI",JV_Entries!$F:$F,B12) | T12: =IF(B12="","",Q12-R12+S12)
A13: 9 | B13: =IF(Masters!$B$11="","",Masters!$B$11) | C13: =IF(B13="","",Masters!$C$11) | D13: =IF(B13="","",IF(Masters!$D$11="","",Masters!$D$11)) | E13: =IF(B13="",0,Masters!$E$11) | F13: =SUMIF(Daily_Sales!$C:$C,B13,Daily_Sales!$G:$G) | G13: =SUMIF(Daily_Sales!$C:$C,B13,Daily_Sales!$E:$E) | H13: =IF(B13="",0,IF(D13<>"",D13*G13,F13*C13/100)) | I13: =IF(G13>0,Masters!$Y$3,0) | J13: =G13*Masters!$Y$4 | K13: =SUMIFS(Cash_Book!$G:$G,Cash_Book!$C:$C,"BEPAARI",Cash_Book!$D:$D,"MOTOR",Cash_Book!$E:$E,B13) | L13: =SUMIFS(Cash_Book!$G:$G,Cash_Book!$C:$C,"BEPAARI",Cash_Book!$D:$D,"BHUSSA",Cash_Book!$E:$E,B13) | M13: =SUMIFS(Cash_Book!$G:$G,Cash_Book!$C:$C,"BEPAARI",Cash_Book!$D:$D,"GAWALI",Cash_Book!$E:$E,B13) | N13: =SUMIFS(Cash_Book!$G:$G,Cash_Book!$C:$C,"BEPAARI",Cash_Book!$D:$D,"CASH_ADV",Cash_Book!$E:$E,B13) | O13: =SUMIFS(Cash_Book!$G:$G,Cash_Book!$C:$C,"BEPAARI",Cash_Book!$D:$D,"OTHER",Cash_Book!$E:$E,B13) | P13: =SUM(H13:O13) | Q13: =IF(B13="","",F13-P13+E13) | R13: =SUMIFS(Cash_Book!$G:$G,Cash_Book!$C:$C,"BEPAARI",Cash_Book!$D:$D,"PAYMENT",Cash_Book!$E:$E,B13) | S13: =SUMIFS(JV_Entries!$G:$G,JV_Entries!$C:$C,"BEPAARI",JV_Entries!$D:$D,B13)-SUMIFS(JV_Entries!$G:$G,JV_Entries!$E:$E,"BEPAARI",JV_Entries!$F:$F,B13) | T13: =IF(B13="","",Q13-R13+S13)
A14: 10 | B14: =IF(Masters!$B$12="","",Masters!$B$12) | C14: =IF(B14="","",Masters!$C$12) | D14: =IF(B14="","",IF(Masters!$D$12="","",Masters!$D$12)) | E14: =IF(B14="",0,Masters!$E$12) | F14: =SUMIF(Daily_Sales!$C:$C,B14,Daily_Sales!$G:$G) | G14: =SUMIF(Daily_Sales!$C:$C,B14,Daily_Sales!$E:$E) | H14: =IF(B14="",0,IF(D14<>"",D14*G14,F14*C14/100)) | I14: =IF(G14>0,Masters!$Y$3,0) | J14: =G14*Masters!$Y$4 | K14: =SUMIFS(Cash_Book!$G:$G,Cash_Book!$C:$C,"BEPAARI",Cash_Book!$D:$D,"MOTOR",Cash_Book!$E:$E,B14) | L14: =SUMIFS(Cash_Book!$G:$G,Cash_Book!$C:$C,"BEPAARI",Cash_Book!$D:$D,"BHUSSA",Cash_Book!$E:$E,B14) | M14: =SUMIFS(Cash_Book!$G:$G,Cash_Book!$C:$C,"BEPAARI",Cash_Book!$D:$D,"GAWALI",Cash_Book!$E:$E,B14) | N14: =SUMIFS(Cash_Book!$G:$G,Cash_Book!$C:$C,"BEPAARI",Cash_Book!$D:$D,"CASH_ADV",Cash_Book!$E:$E,B14) | O14: =SUMIFS(Cash_Book!$G:$G,Cash_Book!$C:$C,"BEPAARI",Cash_Book!$D:$D,"OTHER",Cash_Book!$E:$E,B14) | P14: =SUM(H14:O14) | Q14: =IF(B14="","",F14-P14+E14) | R14: =SUMIFS(Cash_Book!$G:$G,Cash_Book!$C:$C,"BEPAARI",Cash_Book!$D:$D,"PAYMENT",Cash_Book!$E:$E,B14) | S14: =SUMIFS(JV_Entries!$G:$G,JV_Entries!$C:$C,"BEPAARI",JV_Entries!$D:$D,B14)-SUMIFS(JV_Entries!$G:$G,JV_Entries!$E:$E,"BEPAARI",JV_Entries!$F:$F,B14) | T14: =IF(B14="","",Q14-R14+S14)
A15: 11 | B15: =IF(Masters!$B$13="","",Masters!$B$13) | C15: =IF(B15="","",Masters!$C$13) | D15: =IF(B15="","",IF(Masters!$D$13="","",Masters!$D$13)) | E15: =IF(B15="",0,Masters!$E$13) | F15: =SUMIF(Daily_Sales!$C:$C,B15,Daily_Sales!$G:$G) | G15: =SUMIF(Daily_Sales!$C:$C,B15,Daily_Sales!$E:$E) | H15: =IF(B15="",0,IF(D15<>"",D15*G15,F15*C15/100)) | I15: =IF(G15>0,Masters!$Y$3,0) | J15: =G15*Masters!$Y$4 | K15: =SUMIFS(Cash_Book!$G:$G,Cash_Book!$C:$C,"BEPAARI",Cash_Book!$D:$D,"MOTOR",Cash_Book!$E:$E,B15) | L15: =SUMIFS(Cash_Book!$G:$G,Cash_Book!$C:$C,"BEPAARI",Cash_Book!$D:$D,"BHUSSA",Cash_Book!$E:$E,B15) | M15: =SUMIFS(Cash_Book!$G:$G,Cash_Book!$C:$C,"BEPAARI",Cash_Book!$D:$D,"GAWALI",Cash_Book!$E:$E,B15) | N15: =SUMIFS(Cash_Book!$G:$G,Cash_Book!$C:$C,"BEPAARI",Cash_Book!$D:$D,"CASH_ADV",Cash_Book!$E:$E,B15) | O15: =SUMIFS(Cash_Book!$G:$G,Cash_Book!$C:$C,"BEPAARI",Cash_Book!$D:$D,"OTHER",Cash_Book!$E:$E,B15) | P15: =SUM(H15:O15) | Q15: =IF(B15="","",F15-P15+E15) | R15: =SUMIFS(Cash_Book!$G:$G,Cash_Book!$C:$C,"BEPAARI",Cash_Book!$D:$D,"PAYMENT",Cash_Book!$E:$E,B15) | S15: =SUMIFS(JV_Entries!$G:$G,JV_Entries!$C:$C,"BEPAARI",JV_Entries!$D:$D,B15)-SUMIFS(JV_Entries!$G:$G,JV_Entries!$E:$E,"BEPAARI",JV_Entries!$F:$F,B15) | T15: =IF(B15="","",Q15-R15+S15)
A16: 12 | B16: =IF(Masters!$B$14="","",Masters!$B$14) | C16: =IF(B16="","",Masters!$C$14) | D16: =IF(B16="","",IF(Masters!$D$14="","",Masters!$D$14)) | E16: =IF(B16="",0,Masters!$E$14) | F16: =SUMIF(Daily_Sales!$C:$C,B16,Daily_Sales!$G:$G) | G16: =SUMIF(Daily_Sales!$C:$C,B16,Daily_Sales!$E:$E) | H16: =IF(B16="",0,IF(D16<>"",D16*G16,F16*C16/100)) | I16: =IF(G16>0,Masters!$Y$3,0) | J16: =G16*Masters!$Y$4 | K16: =SUMIFS(Cash_Book!$G:$G,Cash_Book!$C:$C,"BEPAARI",Cash_Book!$D:$D,"MOTOR",Cash_Book!$E:$E,B16) | L16: =SUMIFS(Cash_Book!$G:$G,Cash_Book!$C:$C,"BEPAARI",Cash_Book!$D:$D,"BHUSSA",Cash_Book!$E:$E,B16) | M16: =SUMIFS(Cash_Book!$G:$G,Cash_Book!$C:$C,"BEPAARI",Cash_Book!$D:$D,"GAWALI",Cash_Book!$E:$E,B16) | N16: =SUMIFS(Cash_Book!$G:$G,Cash_Book!$C:$C,"BEPAARI",Cash_Book!$D:$D,"CASH_ADV",Cash_Book!$E:$E,B16) | O16: =SUMIFS(Cash_Book!$G:$G,Cash_Book!$C:$C,"BEPAARI",Cash_Book!$D:$D,"OTHER",Cash_Book!$E:$E,B16) | P16: =SUM(H16:O16) | Q16: =IF(B16="","",F16-P16+E16) | R16: =SUMIFS(Cash_Book!$G:$G,Cash_Book!$C:$C,"BEPAARI",Cash_Book!$D:$D,"PAYMENT",Cash_Book!$E:$E,B16) | S16: =SUMIFS(JV_Entries!$G:$G,JV_Entries!$C:$C,"BEPAARI",JV_Entries!$D:$D,B16)-SUMIFS(JV_Entries!$G:$G,JV_Entries!$E:$E,"BEPAARI",JV_Entries!$F:$F,B16) | T16: =IF(B16="","",Q16-R16+S16)
A17: 13 | B17: =IF(Masters!$B$15="","",Masters!$B$15) | C17: =IF(B17="","",Masters!$C$15) | D17: =IF(B17="","",IF(Masters!$D$15="","",Masters!$D$15)) | E17: =IF(B17="",0,Masters!$E$15) | F17: =SUMIF(Daily_Sales!$C:$C,B17,Daily_Sales!$G:$G) | G17: =SUMIF(Daily_Sales!$C:$C,B17,Daily_Sales!$E:$E) | H17: =IF(B17="",0,IF(D17<>"",D17*G17,F17*C17/100)) | I17: =IF(G17>0,Masters!$Y$3,0) | J17: =G17*Masters!$Y$4 | K17: =SUMIFS(Cash_Book!$G:$G,Cash_Book!$C:$C,"BEPAARI",Cash_Book!$D:$D,"MOTOR",Cash_Book!$E:$E,B17) | L17: =SUMIFS(Cash_Book!$G:$G,Cash_Book!$C:$C,"BEPAARI",Cash_Book!$D:$D,"BHUSSA",Cash_Book!$E:$E,B17) | M17: =SUMIFS(Cash_Book!$G:$G,Cash_Book!$C:$C,"BEPAARI",Cash_Book!$D:$D,"GAWALI",Cash_Book!$E:$E,B17) | N17: =SUMIFS(Cash_Book!$G:$G,Cash_Book!$C:$C,"BEPAARI",Cash_Book!$D:$D,"CASH_ADV",Cash_Book!$E:$E,B17) | O17: =SUMIFS(Cash_Book!$G:$G,Cash_Book!$C:$C,"BEPAARI",Cash_Book!$D:$D,"OTHER",Cash_Book!$E:$E,B17) | P17: =SUM(H17:O17) | Q17: =IF(B17="","",F17-P17+E17) | R17: =SUMIFS(Cash_Book!$G:$G,Cash_Book!$C:$C,"BEPAARI",Cash_Book!$D:$D,"PAYMENT",Cash_Book!$E:$E,B17) | S17: =SUMIFS(JV_Entries!$G:$G,JV_Entries!$C:$C,"BEPAARI",JV_Entries!$D:$D,B17)-SUMIFS(JV_Entries!$G:$G,JV_Entries!$E:$E,"BEPAARI",JV_Entries!$F:$F,B17) | T17: =IF(B17="","",Q17-R17+S17)
A18: 14 | B18: =IF(Masters!$B$16="","",Masters!$B$16) | C18: =IF(B18="","",Masters!$C$16) | D18: =IF(B18="","",IF(Masters!$D$16="","",Masters!$D$16)) | E18: =IF(B18="",0,Masters!$E$16) | F18: =SUMIF(Daily_Sales!$C:$C,B18,Daily_Sales!$G:$G) | G18: =SUMIF(Daily_Sales!$C:$C,B18,Daily_Sales!$E:$E) | H18: =IF(B18="",0,IF(D18<>"",D18*G18,F18*C18/100)) | I18: =IF(G18>0,Masters!$Y$3,0) | J18: =G18*Masters!$Y$4 | K18: =SUMIFS(Cash_Book!$G:$G,Cash_Book!$C:$C,"BEPAARI",Cash_Book!$D:$D,"MOTOR",Cash_Book!$E:$E,B18) | L18: =SUMIFS(Cash_Book!$G:$G,Cash_Book!$C:$C,"BEPAARI",Cash_Book!$D:$D,"BHUSSA",Cash_Book!$E:$E,B18) | M18: =SUMIFS(Cash_Book!$G:$G,Cash_Book!$C:$C,"BEPAARI",Cash_Book!$D:$D,"GAWALI",Cash_Book!$E:$E,B18) | N18: =SUMIFS(Cash_Book!$G:$G,Cash_Book!$C:$C,"BEPAARI",Cash_Book!$D:$D,"CASH_ADV",Cash_Book!$E:$E,B18) | O18: =SUMIFS(Cash_Book!$G:$G,Cash_Book!$C:$C,"BEPAARI",Cash_Book!$D:$D,"OTHER",Cash_Book!$E:$E,B18) | P18: =SUM(H18:O18) | Q18: =IF(B18="","",F18-P18+E18) | R18: =SUMIFS(Cash_Book!$G:$G,Cash_Book!$C:$C,"BEPAARI",Cash_Book!$D:$D,"PAYMENT",Cash_Book!$E:$E,B18) | S18: =SUMIFS(JV_Entries!$G:$G,JV_Entries!$C:$C,"BEPAARI",JV_Entries!$D:$D,B18)-SUMIFS(JV_Entries!$G:$G,JV_Entries!$E:$E,"BEPAARI",JV_Entries!$F:$F,B18) | T18: =IF(B18="","",Q18-R18+S18)
A19: 15 | B19: =IF(Masters!$B$17="","",Masters!$B$17) | C19: =IF(B19="","",Masters!$C$17) | D19: =IF(B19="","",IF(Masters!$D$17="","",Masters!$D$17)) | E19: =IF(B19="",0,Masters!$E$17) | F19: =SUMIF(Daily_Sales!$C:$C,B19,Daily_Sales!$G:$G) | G19: =SUMIF(Daily_Sales!$C:$C,B19,Daily_Sales!$E:$E) | H19: =IF(B19="",0,IF(D19<>"",D19*G19,F19*C19/100)) | I19: =IF(G19>0,Masters!$Y$3,0) | J19: =G19*Masters!$Y$4 | K19: =SUMIFS(Cash_Book!$G:$G,Cash_Book!$C:$C,"BEPAARI",Cash_Book!$D:$D,"MOTOR",Cash_Book!$E:$E,B19) | L19: =SUMIFS(Cash_Book!$G:$G,Cash_Book!$C:$C,"BEPAARI",Cash_Book!$D:$D,"BHUSSA",Cash_Book!$E:$E,B19) | M19: =SUMIFS(Cash_Book!$G:$G,Cash_Book!$C:$C,"BEPAARI",Cash_Book!$D:$D,"GAWALI",Cash_Book!$E:$E,B19) | N19: =SUMIFS(Cash_Book!$G:$G,Cash_Book!$C:$C,"BEPAARI",Cash_Book!$D:$D,"CASH_ADV",Cash_Book!$E:$E,B19) | O19: =SUMIFS(Cash_Book!$G:$G,Cash_Book!$C:$C,"BEPAARI",Cash_Book!$D:$D,"OTHER",Cash_Book!$E:$E,B19) | P19: =SUM(H19:O19) | Q19: =IF(B19="","",F19-P19+E19) | R19: =SUMIFS(Cash_Book!$G:$G,Cash_Book!$C:$C,"BEPAARI",Cash_Book!$D:$D,"PAYMENT",Cash_Book!$E:$E,B19) | S19: =SUMIFS(JV_Entries!$G:$G,JV_Entries!$C:$C,"BEPAARI",JV_Entries!$D:$D,B19)-SUMIFS(JV_Entries!$G:$G,JV_Entries!$E:$E,"BEPAARI",JV_Entries!$F:$F,B19) | T19: =IF(B19="","",Q19-R19+S19)
A20: 16 | B20: =IF(Masters!$B$18="","",Masters!$B$18) | C20: =IF(B20="","",Masters!$C$18) | D20: =IF(B20="","",IF(Masters!$D$18="","",Masters!$D$18)) | E20: =IF(B20="",0,Masters!$E$18) | F20: =SUMIF(Daily_Sales!$C:$C,B20,Daily_Sales!$G:$G) | G20: =SUMIF(Daily_Sales!$C:$C,B20,Daily_Sales!$E:$E) | H20: =IF(B20="",0,IF(D20<>"",D20*G20,F20*C20/100)) | I20: =IF(G20>0,Masters!$Y$3,0) | J20: =G20*Masters!$Y$4 | K20: =SUMIFS(Cash_Book!$G:$G,Cash_Book!$C:$C,"BEPAARI",Cash_Book!$D:$D,"MOTOR",Cash_Book!$E:$E,B20) | L20: =SUMIFS(Cash_Book!$G:$G,Cash_Book!$C:$C,"BEPAARI",Cash_Book!$D:$D,"BHUSSA",Cash_Book!$E:$E,B20) | M20: =SUMIFS(Cash_Book!$G:$G,Cash_Book!$C:$C,"BEPAARI",Cash_Book!$D:$D,"GAWALI",Cash_Book!$E:$E,B20) | N20: =SUMIFS(Cash_Book!$G:$G,Cash_Book!$C:$C,"BEPAARI",Cash_Book!$D:$D,"CASH_ADV",Cash_Book!$E:$E,B20) | O20: =SUMIFS(Cash_Book!$G:$G,Cash_Book!$C:$C,"BEPAARI",Cash_Book!$D:$D,"OTHER",Cash_Book!$E:$E,B20) | P20: =SUM(H20:O20) | Q20: =IF(B20="","",F20-P20+E20) | R20: =SUMIFS(Cash_Book!$G:$G,Cash_Book!$C:$C,"BEPAARI",Cash_Book!$D:$D,"PAYMENT",Cash_Book!$E:$E,B20) | S20: =SUMIFS(JV_Entries!$G:$G,JV_Entries!$C:$C,"BEPAARI",JV_Entries!$D:$D,B20)-SUMIFS(JV_Entries!$G:$G,JV_Entries!$E:$E,"BEPAARI",JV_Entries!$F:$F,B20) | T20: =IF(B20="","",Q20-R20+S20)
A21: 17 | B21: =IF(Masters!$B$19="","",Masters!$B$19) | C21: =IF(B21="","",Masters!$C$19) | D21: =IF(B21="","",IF(Masters!$D$19="","",Masters!$D$19)) | E21: =IF(B21="",0,Masters!$E$19) | F21: =SUMIF(Daily_Sales!$C:$C,B21,Daily_Sales!$G:$G) | G21: =SUMIF(Daily_Sales!$C:$C,B21,Daily_Sales!$E:$E) | H21: =IF(B21="",0,IF(D21<>"",D21*G21,F21*C21/100)) | I21: =IF(G21>0,Masters!$Y$3,0) | J21: =G21*Masters!$Y$4 | K21: =SUMIFS(Cash_Book!$G:$G,Cash_Book!$C:$C,"BEPAARI",Cash_Book!$D:$D,"MOTOR",Cash_Book!$E:$E,B21) | L21: =SUMIFS(Cash_Book!$G:$G,Cash_Book!$C:$C,"BEPAARI",Cash_Book!$D:$D,"BHUSSA",Cash_Book!$E:$E,B21) | M21: =SUMIFS(Cash_Book!$G:$G,Cash_Book!$C:$C,"BEPAARI",Cash_Book!$D:$D,"GAWALI",Cash_Book!$E:$E,B21) | N21: =SUMIFS(Cash_Book!$G:$G,Cash_Book!$C:$C,"BEPAARI",Cash_Book!$D:$D,"CASH_ADV",Cash_Book!$E:$E,B21) | O21: =SUMIFS(Cash_Book!$G:$G,Cash_Book!$C:$C,"BEPAARI",Cash_Book!$D:$D,"OTHER",Cash_Book!$E:$E,B21) | P21: =SUM(H21:O21) | Q21: =IF(B21="","",F21-P21+E21) | R21: =SUMIFS(Cash_Book!$G:$G,Cash_Book!$C:$C,"BEPAARI",Cash_Book!$D:$D,"PAYMENT",Cash_Book!$E:$E,B21) | S21: =SUMIFS(JV_Entries!$G:$G,JV_Entries!$C:$C,"BEPAARI",JV_Entries!$D:$D,B21)-SUMIFS(JV_Entries!$G:$G,JV_Entries!$E:$E,"BEPAARI",JV_Entries!$F:$F,B21) | T21: =IF(B21="","",Q21-R21+S21)
A22: 18 | B22: =IF(Masters!$B$20="","",Masters!$B$20) | C22: =IF(B22="","",Masters!$C$20) | D22: =IF(B22="","",IF(Masters!$D$20="","",Masters!$D$20)) | E22: =IF(B22="",0,Masters!$E$20) | F22: =SUMIF(Daily_Sales!$C:$C,B22,Daily_Sales!$G:$G) | G22: =SUMIF(Daily_Sales!$C:$C,B22,Daily_Sales!$E:$E) | H22: =IF(B22="",0,IF(D22<>"",D22*G22,F22*C22/100)) | I22: =IF(G22>0,Masters!$Y$3,0) | J22: =G22*Masters!$Y$4 | K22: =SUMIFS(Cash_Book!$G:$G,Cash_Book!$C:$C,"BEPAARI",Cash_Book!$D:$D,"MOTOR",Cash_Book!$E:$E,B22) | L22: =SUMIFS(Cash_Book!$G:$G,Cash_Book!$C:$C,"BEPAARI",Cash_Book!$D:$D,"BHUSSA",Cash_Book!$E:$E,B22) | M22: =SUMIFS(Cash_Book!$G:$G,Cash_Book!$C:$C,"BEPAARI",Cash_Book!$D:$D,"GAWALI",Cash_Book!$E:$E,B22) | N22: =SUMIFS(Cash_Book!$G:$G,Cash_Book!$C:$C,"BEPAARI",Cash_Book!$D:$D,"CASH_ADV",Cash_Book!$E:$E,B22) | O22: =SUMIFS(Cash_Book!$G:$G,Cash_Book!$C:$C,"BEPAARI",Cash_Book!$D:$D,"OTHER",Cash_Book!$E:$E,B22) | P22: =SUM(H22:O22) | Q22: =IF(B22="","",F22-P22+E22) | R22: =SUMIFS(Cash_Book!$G:$G,Cash_Book!$C:$C,"BEPAARI",Cash_Book!$D:$D,"PAYMENT",Cash_Book!$E:$E,B22) | S22: =SUMIFS(JV_Entries!$G:$G,JV_Entries!$C:$C,"BEPAARI",JV_Entries!$D:$D,B22)-SUMIFS(JV_Entries!$G:$G,JV_Entries!$E:$E,"BEPAARI",JV_Entries!$F:$F,B22) | T22: =IF(B22="","",Q22-R22+S22)
A23: 19 | B23: =IF(Masters!$B$21="","",Masters!$B$21) | C23: =IF(B23="","",Masters!$C$21) | D23: =IF(B23="","",IF(Masters!$D$21="","",Masters!$D$21)) | E23: =IF(B23="",0,Masters!$E$21) | F23: =SUMIF(Daily_Sales!$C:$C,B23,Daily_Sales!$G:$G) | G23: =SUMIF(Daily_Sales!$C:$C,B23,Daily_Sales!$E:$E) | H23: =IF(B23="",0,IF(D23<>"",D23*G23,F23*C23/100)) | I23: =IF(G23>0,Masters!$Y$3,0) | J23: =G23*Masters!$Y$4 | K23: =SUMIFS(Cash_Book!$G:$G,Cash_Book!$C:$C,"BEPAARI",Cash_Book!$D:$D,"MOTOR",Cash_Book!$E:$E,B23) | L23: =SUMIFS(Cash_Book!$G:$G,Cash_Book!$C:$C,"BEPAARI",Cash_Book!$D:$D,"BHUSSA",Cash_Book!$E:$E,B23) | M23: =SUMIFS(Cash_Book!$G:$G,Cash_Book!$C:$C,"BEPAARI",Cash_Book!$D:$D,"GAWALI",Cash_Book!$E:$E,B23) | N23: =SUMIFS(Cash_Book!$G:$G,Cash_Book!$C:$C,"BEPAARI",Cash_Book!$D:$D,"CASH_ADV",Cash_Book!$E:$E,B23) | O23: =SUMIFS(Cash_Book!$G:$G,Cash_Book!$C:$C,"BEPAARI",Cash_Book!$D:$D,"OTHER",Cash_Book!$E:$E,B23) | P23: =SUM(H23:O23) | Q23: =IF(B23="","",F23-P23+E23) | R23: =SUMIFS(Cash_Book!$G:$G,Cash_Book!$C:$C,"BEPAARI",Cash_Book!$D:$D,"PAYMENT",Cash_Book!$E:$E,B23) | S23: =SUMIFS(JV_Entries!$G:$G,JV_Entries!$C:$C,"BEPAARI",JV_Entries!$D:$D,B23)-SUMIFS(JV_Entries!$G:$G,JV_Entries!$E:$E,"BEPAARI",JV_Entries!$F:$F,B23) | T23: =IF(B23="","",Q23-R23+S23)
A24: 20 | B24: =IF(Masters!$B$22="","",Masters!$B$22) | C24: =IF(B24="","",Masters!$C$22) | D24: =IF(B24="","",IF(Masters!$D$22="","",Masters!$D$22)) | E24: =IF(B24="",0,Masters!$E$22) | F24: =SUMIF(Daily_Sales!$C:$C,B24,Daily_Sales!$G:$G) | G24: =SUMIF(Daily_Sales!$C:$C,B24,Daily_Sales!$E:$E) | H24: =IF(B24="",0,IF(D24<>"",D24*G24,F24*C24/100)) | I24: =IF(G24>0,Masters!$Y$3,0) | J24: =G24*Masters!$Y$4 | K24: =SUMIFS(Cash_Book!$G:$G,Cash_Book!$C:$C,"BEPAARI",Cash_Book!$D:$D,"MOTOR",Cash_Book!$E:$E,B24) | L24: =SUMIFS(Cash_Book!$G:$G,Cash_Book!$C:$C,"BEPAARI",Cash_Book!$D:$D,"BHUSSA",Cash_Book!$E:$E,B24) | M24: =SUMIFS(Cash_Book!$G:$G,Cash_Book!$C:$C,"BEPAARI",Cash_Book!$D:$D,"GAWALI",Cash_Book!$E:$E,B24) | N24: =SUMIFS(Cash_Book!$G:$G,Cash_Book!$C:$C,"BEPAARI",Cash_Book!$D:$D,"CASH_ADV",Cash_Book!$E:$E,B24) | O24: =SUMIFS(Cash_Book!$G:$G,Cash_Book!$C:$C,"BEPAARI",Cash_Book!$D:$D,"OTHER",Cash_Book!$E:$E,B24) | P24: =SUM(H24:O24) | Q24: =IF(B24="","",F24-P24+E24) | R24: =SUMIFS(Cash_Book!$G:$G,Cash_Book!$C:$C,"BEPAARI",Cash_Book!$D:$D,"PAYMENT",Cash_Book!$E:$E,B24) | S24: =SUMIFS(JV_Entries!$G:$G,JV_Entries!$C:$C,"BEPAARI",JV_Entries!$D:$D,B24)-SUMIFS(JV_Entries!$G:$G,JV_Entries!$E:$E,"BEPAARI",JV_Entries!$F:$F,B24) | T24: =IF(B24="","",Q24-R24+S24)
A25: 21 | B25: =IF(Masters!$B$23="","",Masters!$B$23) | C25: =IF(B25="","",Masters!$C$23) | D25: =IF(B25="","",IF(Masters!$D$23="","",Masters!$D$23)) | E25: =IF(B25="",0,Masters!$E$23) | F25: =SUMIF(Daily_Sales!$C:$C,B25,Daily_Sales!$G:$G) | G25: =SUMIF(Daily_Sales!$C:$C,B25,Daily_Sales!$E:$E) | H25: =IF(B25="",0,IF(D25<>"",D25*G25,F25*C25/100)) | I25: =IF(G25>0,Masters!$Y$3,0) | J25: =G25*Masters!$Y$4 | K25: =SUMIFS(Cash_Book!$G:$G,Cash_Book!$C:$C,"BEPAARI",Cash_Book!$D:$D,"MOTOR",Cash_Book!$E:$E,B25) | L25: =SUMIFS(Cash_Book!$G:$G,Cash_Book!$C:$C,"BEPAARI",Cash_Book!$D:$D,"BHUSSA",Cash_Book!$E:$E,B25) | M25: =SUMIFS(Cash_Book!$G:$G,Cash_Book!$C:$C,"BEPAARI",Cash_Book!$D:$D,"GAWALI",Cash_Book!$E:$E,B25) | N25: =SUMIFS(Cash_Book!$G:$G,Cash_Book!$C:$C,"BEPAARI",Cash_Book!$D:$D,"CASH_ADV",Cash_Book!$E:$E,B25) | O25: =SUMIFS(Cash_Book!$G:$G,Cash_Book!$C:$C,"BEPAARI",Cash_Book!$D:$D,"OTHER",Cash_Book!$E:$E,B25) | P25: =SUM(H25:O25) | Q25: =IF(B25="","",F25-P25+E25) | R25: =SUMIFS(Cash_Book!$G:$G,Cash_Book!$C:$C,"BEPAARI",Cash_Book!$D:$D,"PAYMENT",Cash_Book!$E:$E,B25) | S25: =SUMIFS(JV_Entries!$G:$G,JV_Entries!$C:$C,"BEPAARI",JV_Entries!$D:$D,B25)-SUMIFS(JV_Entries!$G:$G,JV_Entries!$E:$E,"BEPAARI",JV_Entries!$F:$F,B25) | T25: =IF(B25="","",Q25-R25+S25)
A26: 22 | B26: =IF(Masters!$B$24="","",Masters!$B$24) | C26: =IF(B26="","",Masters!$C$24) | D26: =IF(B26="","",IF(Masters!$D$24="","",Masters!$D$24)) | E26: =IF(B26="",0,Masters!$E$24) | F26: =SUMIF(Daily_Sales!$C:$C,B26,Daily_Sales!$G:$G) | G26: =SUMIF(Daily_Sales!$C:$C,B26,Daily_Sales!$E:$E) | H26: =IF(B26="",0,IF(D26<>"",D26*G26,F26*C26/100)) | I26: =IF(G26>0,Masters!$Y$3,0) | J26: =G26*Masters!$Y$4 | K26: =SUMIFS(Cash_Book!$G:$G,Cash_Book!$C:$C,"BEPAARI",Cash_Book!$D:$D,"MOTOR",Cash_Book!$E:$E,B26) | L26: =SUMIFS(Cash_Book!$G:$G,Cash_Book!$C:$C,"BEPAARI",Cash_Book!$D:$D,"BHUSSA",Cash_Book!$E:$E,B26) | M26: =SUMIFS(Cash_Book!$G:$G,Cash_Book!$C:$C,"BEPAARI",Cash_Book!$D:$D,"GAWALI",Cash_Book!$E:$E,B26) | N26: =SUMIFS(Cash_Book!$G:$G,Cash_Book!$C:$C,"BEPAARI",Cash_Book!$D:$D,"CASH_ADV",Cash_Book!$E:$E,B26) | O26: =SUMIFS(Cash_Book!$G:$G,Cash_Book!$C:$C,"BEPAARI",Cash_Book!$D:$D,"OTHER",Cash_Book!$E:$E,B26) | P26: =SUM(H26:O26) | Q26: =IF(B26="","",F26-P26+E26) | R26: =SUMIFS(Cash_Book!$G:$G,Cash_Book!$C:$C,"BEPAARI",Cash_Book!$D:$D,"PAYMENT",Cash_Book!$E:$E,B26) | S26: =SUMIFS(JV_Entries!$G:$G,JV_Entries!$C:$C,"BEPAARI",JV_Entries!$D:$D,B26)-SUMIFS(JV_Entries!$G:$G,JV_Entries!$E:$E,"BEPAARI",JV_Entries!$F:$F,B26) | T26: =IF(B26="","",Q26-R26+S26)
A27: 23 | B27: =IF(Masters!$B$25="","",Masters!$B$25) | C27: =IF(B27="","",Masters!$C$25) | D27: =IF(B27="","",IF(Masters!$D$25="","",Masters!$D$25)) | E27: =IF(B27="",0,Masters!$E$25) | F27: =SUMIF(Daily_Sales!$C:$C,B27,Daily_Sales!$G:$G) | G27: =SUMIF(Daily_Sales!$C:$C,B27,Daily_Sales!$E:$E) | H27: =IF(B27="",0,IF(D27<>"",D27*G27,F27*C27/100)) | I27: =IF(G27>0,Masters!$Y$3,0) | J27: =G27*Masters!$Y$4 | K27: =SUMIFS(Cash_Book!$G:$G,Cash_Book!$C:$C,"BEPAARI",Cash_Book!$D:$D,"MOTOR",Cash_Book!$E:$E,B27) | L27: =SUMIFS(Cash_Book!$G:$G,Cash_Book!$C:$C,"BEPAARI",Cash_Book!$D:$D,"BHUSSA",Cash_Book!$E:$E,B27) | M27: =SUMIFS(Cash_Book!$G:$G,Cash_Book!$C:$C,"BEPAARI",Cash_Book!$D:$D,"GAWALI",Cash_Book!$E:$E,B27) | N27: =SUMIFS(Cash_Book!$G:$G,Cash_Book!$C:$C,"BEPAARI",Cash_Book!$D:$D,"CASH_ADV",Cash_Book!$E:$E,B27) | O27: =SUMIFS(Cash_Book!$G:$G,Cash_Book!$C:$C,"BEPAARI",Cash_Book!$D:$D,"OTHER",Cash_Book!$E:$E,B27) | P27: =SUM(H27:O27) | Q27: =IF(B27="","",F27-P27+E27) | R27: =SUMIFS(Cash_Book!$G:$G,Cash_Book!$C:$C,"BEPAARI",Cash_Book!$D:$D,"PAYMENT",Cash_Book!$E:$E,B27) | S27: =SUMIFS(JV_Entries!$G:$G,JV_Entries!$C:$C,"BEPAARI",JV_Entries!$D:$D,B27)-SUMIFS(JV_Entries!$G:$G,JV_Entries!$E:$E,"BEPAARI",JV_Entries!$F:$F,B27) | T27: =IF(B27="","",Q27-R27+S27)
A28: 24 | B28: =IF(Masters!$B$26="","",Masters!$B$26) | C28: =IF(B28="","",Masters!$C$26) | D28: =IF(B28="","",IF(Masters!$D$26="","",Masters!$D$26)) | E28: =IF(B28="",0,Masters!$E$26) | F28: =SUMIF(Daily_Sales!$C:$C,B28,Daily_Sales!$G:$G) | G28: =SUMIF(Daily_Sales!$C:$C,B28,Daily_Sales!$E:$E) | H28: =IF(B28="",0,IF(D28<>"",D28*G28,F28*C28/100)) | I28: =IF(G28>0,Masters!$Y$3,0) | J28: =G28*Masters!$Y$4 | K28: =SUMIFS(Cash_Book!$G:$G,Cash_Book!$C:$C,"BEPAARI",Cash_Book!$D:$D,"MOTOR",Cash_Book!$E:$E,B28) | L28: =SUMIFS(Cash_Book!$G:$G,Cash_Book!$C:$C,"BEPAARI",Cash_Book!$D:$D,"BHUSSA",Cash_Book!$E:$E,B28) | M28: =SUMIFS(Cash_Book!$G:$G,Cash_Book!$C:$C,"BEPAARI",Cash_Book!$D:$D,"GAWALI",Cash_Book!$E:$E,B28) | N28: =SUMIFS(Cash_Book!$G:$G,Cash_Book!$C:$C,"BEPAARI",Cash_Book!$D:$D,"CASH_ADV",Cash_Book!$E:$E,B28) | O28: =SUMIFS(Cash_Book!$G:$G,Cash_Book!$C:$C,"BEPAARI",Cash_Book!$D:$D,"OTHER",Cash_Book!$E:$E,B28) | P28: =SUM(H28:O28) | Q28: =IF(B28="","",F28-P28+E28) | R28: =SUMIFS(Cash_Book!$G:$G,Cash_Book!$C:$C,"BEPAARI",Cash_Book!$D:$D,"PAYMENT",Cash_Book!$E:$E,B28) | S28: =SUMIFS(JV_Entries!$G:$G,JV_Entries!$C:$C,"BEPAARI",JV_Entries!$D:$D,B28)-SUMIFS(JV_Entries!$G:$G,JV_Entries!$E:$E,"BEPAARI",JV_Entries!$F:$F,B28) | T28: =IF(B28="","",Q28-R28+S28)
A29: 25 | B29: =IF(Masters!$B$27="","",Masters!$B$27) | C29: =IF(B29="","",Masters!$C$27) | D29: =IF(B29="","",IF(Masters!$D$27="","",Masters!$D$27)) | E29: =IF(B29="",0,Masters!$E$27) | F29: =SUMIF(Daily_Sales!$C:$C,B29,Daily_Sales!$G:$G) | G29: =SUMIF(Daily_Sales!$C:$C,B29,Daily_Sales!$E:$E) | H29: =IF(B29="",0,IF(D29<>"",D29*G29,F29*C29/100)) | I29: =IF(G29>0,Masters!$Y$3,0) | J29: =G29*Masters!$Y$4 | K29: =SUMIFS(Cash_Book!$G:$G,Cash_Book!$C:$C,"BEPAARI",Cash_Book!$D:$D,"MOTOR",Cash_Book!$E:$E,B29) | L29: =SUMIFS(Cash_Book!$G:$G,Cash_Book!$C:$C,"BEPAARI",Cash_Book!$D:$D,"BHUSSA",Cash_Book!$E:$E,B29) | M29: =SUMIFS(Cash_Book!$G:$G,Cash_Book!$C:$C,"BEPAARI",Cash_Book!$D:$D,"GAWALI",Cash_Book!$E:$E,B29) | N29: =SUMIFS(Cash_Book!$G:$G,Cash_Book!$C:$C,"BEPAARI",Cash_Book!$D:$D,"CASH_ADV",Cash_Book!$E:$E,B29) | O29: =SUMIFS(Cash_Book!$G:$G,Cash_Book!$C:$C,"BEPAARI",Cash_Book!$D:$D,"OTHER",Cash_Book!$E:$E,B29) | P29: =SUM(H29:O29) | Q29: =IF(B29="","",F29-P29+E29) | R29: =SUMIFS(Cash_Book!$G:$G,Cash_Book!$C:$C,"BEPAARI",Cash_Book!$D:$D,"PAYMENT",Cash_Book!$E:$E,B29) | S29: =SUMIFS(JV_Entries!$G:$G,JV_Entries!$C:$C,"BEPAARI",JV_Entries!$D:$D,B29)-SUMIFS(JV_Entries!$G:$G,JV_Entries!$E:$E,"BEPAARI",JV_Entries!$F:$F,B29) | T29: =IF(B29="","",Q29-R29+S29)
A30: 26 | B30: =IF(Masters!$B$28="","",Masters!$B$28) | C30: =IF(B30="","",Masters!$C$28) | D30: =IF(B30="","",IF(Masters!$D$28="","",Masters!$D$28)) | E30: =IF(B30="",0,Masters!$E$28) | F30: =SUMIF(Daily_Sales!$C:$C,B30,Daily_Sales!$G:$G) | G30: =SUMIF(Daily_Sales!$C:$C,B30,Daily_Sales!$E:$E) | H30: =IF(B30="",0,IF(D30<>"",D30*G30,F30*C30/100)) | I30: =IF(G30>0,Masters!$Y$3,0) | J30: =G30*Masters!$Y$4 | K30: =SUMIFS(Cash_Book!$G:$G,Cash_Book!$C:$C,"BEPAARI",Cash_Book!$D:$D,"MOTOR",Cash_Book!$E:$E,B30) | L30: =SUMIFS(Cash_Book!$G:$G,Cash_Book!$C:$C,"BEPAARI",Cash_Book!$D:$D,"BHUSSA",Cash_Book!$E:$E,B30) | M30: =SUMIFS(Cash_Book!$G:$G,Cash_Book!$C:$C,"BEPAARI",Cash_Book!$D:$D,"GAWALI",Cash_Book!$E:$E,B30) | N30: =SUMIFS(Cash_Book!$G:$G,Cash_Book!$C:$C,"BEPAARI",Cash_Book!$D:$D,"CASH_ADV",Cash_Book!$E:$E,B30) | O30: =SUMIFS(Cash_Book!$G:$G,Cash_Book!$C:$C,"BEPAARI",Cash_Book!$D:$D,"OTHER",Cash_Book!$E:$E,B30) | P30: =SUM(H30:O30) | Q30: =IF(B30="","",F30-P30+E30) | R30: =SUMIFS(Cash_Book!$G:$G,Cash_Book!$C:$C,"BEPAARI",Cash_Book!$D:$D,"PAYMENT",Cash_Book!$E:$E,B30) | S30: =SUMIFS(JV_Entries!$G:$G,JV_Entries!$C:$C,"BEPAARI",JV_Entries!$D:$D,B30)-SUMIFS(JV_Entries!$G:$G,JV_Entries!$E:$E,"BEPAARI",JV_Entries!$F:$F,B30) | T30: =IF(B30="","",Q30-R30+S30)
A31: 27 | B31: =IF(Masters!$B$29="","",Masters!$B$29) | C31: =IF(B31="","",Masters!$C$29) | D31: =IF(B31="","",IF(Masters!$D$29="","",Masters!$D$29)) | E31: =IF(B31="",0,Masters!$E$29) | F31: =SUMIF(Daily_Sales!$C:$C,B31,Daily_Sales!$G:$G) | G31: =SUMIF(Daily_Sales!$C:$C,B31,Daily_Sales!$E:$E) | H31: =IF(B31="",0,IF(D31<>"",D31*G31,F31*C31/100)) | I31: =IF(G31>0,Masters!$Y$3,0) | J31: =G31*Masters!$Y$4 | K31: =SUMIFS(Cash_Book!$G:$G,Cash_Book!$C:$C,"BEPAARI",Cash_Book!$D:$D,"MOTOR",Cash_Book!$E:$E,B31) | L31: =SUMIFS(Cash_Book!$G:$G,Cash_Book!$C:$C,"BEPAARI",Cash_Book!$D:$D,"BHUSSA",Cash_Book!$E:$E,B31) | M31: =SUMIFS(Cash_Book!$G:$G,Cash_Book!$C:$C,"BEPAARI",Cash_Book!$D:$D,"GAWALI",Cash_Book!$E:$E,B31) | N31: =SUMIFS(Cash_Book!$G:$G,Cash_Book!$C:$C,"BEPAARI",Cash_Book!$D:$D,"CASH_ADV",Cash_Book!$E:$E,B31) | O31: =SUMIFS(Cash_Book!$G:$G,Cash_Book!$C:$C,"BEPAARI",Cash_Book!$D:$D,"OTHER",Cash_Book!$E:$E,B31) | P31: =SUM(H31:O31) | Q31: =IF(B31="","",F31-P31+E31) | R31: =SUMIFS(Cash_Book!$G:$G,Cash_Book!$C:$C,"BEPAARI",Cash_Book!$D:$D,"PAYMENT",Cash_Book!$E:$E,B31) | S31: =SUMIFS(JV_Entries!$G:$G,JV_Entries!$C:$C,"BEPAARI",JV_Entries!$D:$D,B31)-SUMIFS(JV_Entries!$G:$G,JV_Entries!$E:$E,"BEPAARI",JV_Entries!$F:$F,B31) | T31: =IF(B31="","",Q31-R31+S31)
A32: 28 | B32: =IF(Masters!$B$30="","",Masters!$B$30) | C32: =IF(B32="","",Masters!$C$30) | D32: =IF(B32="","",IF(Masters!$D$30="","",Masters!$D$30)) | E32: =IF(B32="",0,Masters!$E$30) | F32: =SUMIF(Daily_Sales!$C:$C,B32,Daily_Sales!$G:$G) | G32: =SUMIF(Daily_Sales!$C:$C,B32,Daily_Sales!$E:$E) | H32: =IF(B32="",0,IF(D32<>"",D32*G32,F32*C32/100)) | I32: =IF(G32>0,Masters!$Y$3,0) | J32: =G32*Masters!$Y$4 | K32: =SUMIFS(Cash_Book!$G:$G,Cash_Book!$C:$C,"BEPAARI",Cash_Book!$D:$D,"MOTOR",Cash_Book!$E:$E,B32) | L32: =SUMIFS(Cash_Book!$G:$G,Cash_Book!$C:$C,"BEPAARI",Cash_Book!$D:$D,"BHUSSA",Cash_Book!$E:$E,B32) | M32: =SUMIFS(Cash_Book!$G:$G,Cash_Book!$C:$C,"BEPAARI",Cash_Book!$D:$D,"GAWALI",Cash_Book!$E:$E,B32) | N32: =SUMIFS(Cash_Book!$G:$G,Cash_Book!$C:$C,"BEPAARI",Cash_Book!$D:$D,"CASH_ADV",Cash_Book!$E:$E,B32) | O32: =SUMIFS(Cash_Book!$G:$G,Cash_Book!$C:$C,"BEPAARI",Cash_Book!$D:$D,"OTHER",Cash_Book!$E:$E,B32) | P32: =SUM(H32:O32) | Q32: =IF(B32="","",F32-P32+E32) | R32: =SUMIFS(Cash_Book!$G:$G,Cash_Book!$C:$C,"BEPAARI",Cash_Book!$D:$D,"PAYMENT",Cash_Book!$E:$E,B32) | S32: =SUMIFS(JV_Entries!$G:$G,JV_Entries!$C:$C,"BEPAARI",JV_Entries!$D:$D,B32)-SUMIFS(JV_Entries!$G:$G,JV_Entries!$E:$E,"BEPAARI",JV_Entries!$F:$F,B32) | T32: =IF(B32="","",Q32-R32+S32)
A33: 29 | B33: =IF(Masters!$B$31="","",Masters!$B$31) | C33: =IF(B33="","",Masters!$C$31) | D33: =IF(B33="","",IF(Masters!$D$31="","",Masters!$D$31)) | E33: =IF(B33="",0,Masters!$E$31) | F33: =SUMIF(Daily_Sales!$C:$C,B33,Daily_Sales!$G:$G) | G33: =SUMIF(Daily_Sales!$C:$C,B33,Daily_Sales!$E:$E) | H33: =IF(B33="",0,IF(D33<>"",D33*G33,F33*C33/100)) | I33: =IF(G33>0,Masters!$Y$3,0) | J33: =G33*Masters!$Y$4 | K33: =SUMIFS(Cash_Book!$G:$G,Cash_Book!$C:$C,"BEPAARI",Cash_Book!$D:$D,"MOTOR",Cash_Book!$E:$E,B33) | L33: =SUMIFS(Cash_Book!$G:$G,Cash_Book!$C:$C,"BEPAARI",Cash_Book!$D:$D,"BHUSSA",Cash_Book!$E:$E,B33) | M33: =SUMIFS(Cash_Book!$G:$G,Cash_Book!$C:$C,"BEPAARI",Cash_Book!$D:$D,"GAWALI",Cash_Book!$E:$E,B33) | N33: =SUMIFS(Cash_Book!$G:$G,Cash_Book!$C:$C,"BEPAARI",Cash_Book!$D:$D,"CASH_ADV",Cash_Book!$E:$E,B33) | O33: =SUMIFS(Cash_Book!$G:$G,Cash_Book!$C:$C,"BEPAARI",Cash_Book!$D:$D,"OTHER",Cash_Book!$E:$E,B33) | P33: =SUM(H33:O33) | Q33: =IF(B33="","",F33-P33+E33) | R33: =SUMIFS(Cash_Book!$G:$G,Cash_Book!$C:$C,"BEPAARI",Cash_Book!$D:$D,"PAYMENT",Cash_Book!$E:$E,B33) | S33: =SUMIFS(JV_Entries!$G:$G,JV_Entries!$C:$C,"BEPAARI",JV_Entries!$D:$D,B33)-SUMIFS(JV_Entries!$G:$G,JV_Entries!$E:$E,"BEPAARI",JV_Entries!$F:$F,B33) | T33: =IF(B33="","",Q33-R33+S33)
A34: 30 | B34: =IF(Masters!$B$32="","",Masters!$B$32) | C34: =IF(B34="","",Masters!$C$32) | D34: =IF(B34="","",IF(Masters!$D$32="","",Masters!$D$32)) | E34: =IF(B34="",0,Masters!$E$32) | F34: =SUMIF(Daily_Sales!$C:$C,B34,Daily_Sales!$G:$G) | G34: =SUMIF(Daily_Sales!$C:$C,B34,Daily_Sales!$E:$E) | H34: =IF(B34="",0,IF(D34<>"",D34*G34,F34*C34/100)) | I34: =IF(G34>0,Masters!$Y$3,0) | J34: =G34*Masters!$Y$4 | K34: =SUMIFS(Cash_Book!$G:$G,Cash_Book!$C:$C,"BEPAARI",Cash_Book!$D:$D,"MOTOR",Cash_Book!$E:$E,B34) | L34: =SUMIFS(Cash_Book!$G:$G,Cash_Book!$C:$C,"BEPAARI",Cash_Book!$D:$D,"BHUSSA",Cash_Book!$E:$E,B34) | M34: =SUMIFS(Cash_Book!$G:$G,Cash_Book!$C:$C,"BEPAARI",Cash_Book!$D:$D,"GAWALI",Cash_Book!$E:$E,B34) | N34: =SUMIFS(Cash_Book!$G:$G,Cash_Book!$C:$C,"BEPAARI",Cash_Book!$D:$D,"CASH_ADV",Cash_Book!$E:$E,B34) | O34: =SUMIFS(Cash_Book!$G:$G,Cash_Book!$C:$C,"BEPAARI",Cash_Book!$D:$D,"OTHER",Cash_Book!$E:$E,B34) | P34: =SUM(H34:O34) | Q34: =IF(B34="","",F34-P34+E34) | R34: =SUMIFS(Cash_Book!$G:$G,Cash_Book!$C:$C,"BEPAARI",Cash_Book!$D:$D,"PAYMENT",Cash_Book!$E:$E,B34) | S34: =SUMIFS(JV_Entries!$G:$G,JV_Entries!$C:$C,"BEPAARI",JV_Entries!$D:$D,B34)-SUMIFS(JV_Entries!$G:$G,JV_Entries!$E:$E,"BEPAARI",JV_Entries!$F:$F,B34) | T34: =IF(B34="","",Q34-R34+S34)
A35: 31 | B35: =IF(Masters!$B$33="","",Masters!$B$33) | C35: =IF(B35="","",Masters!$C$33) | D35: =IF(B35="","",IF(Masters!$D$33="","",Masters!$D$33)) | E35: =IF(B35="",0,Masters!$E$33) | F35: =SUMIF(Daily_Sales!$C:$C,B35,Daily_Sales!$G:$G) | G35: =SUMIF(Daily_Sales!$C:$C,B35,Daily_Sales!$E:$E) | H35: =IF(B35="",0,IF(D35<>"",D35*G35,F35*C35/100)) | I35: =IF(G35>0,Masters!$Y$3,0) | J35: =G35*Masters!$Y$4 | K35: =SUMIFS(Cash_Book!$G:$G,Cash_Book!$C:$C,"BEPAARI",Cash_Book!$D:$D,"MOTOR",Cash_Book!$E:$E,B35) | L35: =SUMIFS(Cash_Book!$G:$G,Cash_Book!$C:$C,"BEPAARI",Cash_Book!$D:$D,"BHUSSA",Cash_Book!$E:$E,B35) | M35: =SUMIFS(Cash_Book!$G:$G,Cash_Book!$C:$C,"BEPAARI",Cash_Book!$D:$D,"GAWALI",Cash_Book!$E:$E,B35) | N35: =SUMIFS(Cash_Book!$G:$G,Cash_Book!$C:$C,"BEPAARI",Cash_Book!$D:$D,"CASH_ADV",Cash_Book!$E:$E,B35) | O35: =SUMIFS(Cash_Book!$G:$G,Cash_Book!$C:$C,"BEPAARI",Cash_Book!$D:$D,"OTHER",Cash_Book!$E:$E,B35) | P35: =SUM(H35:O35) | Q35: =IF(B35="","",F35-P35+E35) | R35: =SUMIFS(Cash_Book!$G:$G,Cash_Book!$C:$C,"BEPAARI",Cash_Book!$D:$D,"PAYMENT",Cash_Book!$E:$E,B35) | S35: =SUMIFS(JV_Entries!$G:$G,JV_Entries!$C:$C,"BEPAARI",JV_Entries!$D:$D,B35)-SUMIFS(JV_Entries!$G:$G,JV_Entries!$E:$E,"BEPAARI",JV_Entries!$F:$F,B35) | T35: =IF(B35="","",Q35-R35+S35)
A36: 32 | B36: =IF(Masters!$B$34="","",Masters!$B$34) | C36: =IF(B36="","",Masters!$C$34) | D36: =IF(B36="","",IF(Masters!$D$34="","",Masters!$D$34)) | E36: =IF(B36="",0,Masters!$E$34) | F36: =SUMIF(Daily_Sales!$C:$C,B36,Daily_Sales!$G:$G) | G36: =SUMIF(Daily_Sales!$C:$C,B36,Daily_Sales!$E:$E) | H36: =IF(B36="",0,IF(D36<>"",D36*G36,F36*C36/100)) | I36: =IF(G36>0,Masters!$Y$3,0) | J36: =G36*Masters!$Y$4 | K36: =SUMIFS(Cash_Book!$G:$G,Cash_Book!$C:$C,"BEPAARI",Cash_Book!$D:$D,"MOTOR",Cash_Book!$E:$E,B36) | L36: =SUMIFS(Cash_Book!$G:$G,Cash_Book!$C:$C,"BEPAARI",Cash_Book!$D:$D,"BHUSSA",Cash_Book!$E:$E,B36) | M36: =SUMIFS(Cash_Book!$G:$G,Cash_Book!$C:$C,"BEPAARI",Cash_Book!$D:$D,"GAWALI",Cash_Book!$E:$E,B36) | N36: =SUMIFS(Cash_Book!$G:$G,Cash_Book!$C:$C,"BEPAARI",Cash_Book!$D:$D,"CASH_ADV",Cash_Book!$E:$E,B36) | O36: =SUMIFS(Cash_Book!$G:$G,Cash_Book!$C:$C,"BEPAARI",Cash_Book!$D:$D,"OTHER",Cash_Book!$E:$E,B36) | P36: =SUM(H36:O36) | Q36: =IF(B36="","",F36-P36+E36) | R36: =SUMIFS(Cash_Book!$G:$G,Cash_Book!$C:$C,"BEPAARI",Cash_Book!$D:$D,"PAYMENT",Cash_Book!$E:$E,B36) | S36: =SUMIFS(JV_Entries!$G:$G,JV_Entries!$C:$C,"BEPAARI",JV_Entries!$D:$D,B36)-SUMIFS(JV_Entries!$G:$G,JV_Entries!$E:$E,"BEPAARI",JV_Entries!$F:$F,B36) | T36: =IF(B36="","",Q36-R36+S36)
A37: 33 | B37: =IF(Masters!$B$35="","",Masters!$B$35) | C37: =IF(B37="","",Masters!$C$35) | D37: =IF(B37="","",IF(Masters!$D$35="","",Masters!$D$35)) | E37: =IF(B37="",0,Masters!$E$35) | F37: =SUMIF(Daily_Sales!$C:$C,B37,Daily_Sales!$G:$G) | G37: =SUMIF(Daily_Sales!$C:$C,B37,Daily_Sales!$E:$E) | H37: =IF(B37="",0,IF(D37<>"",D37*G37,F37*C37/100)) | I37: =IF(G37>0,Masters!$Y$3,0) | J37: =G37*Masters!$Y$4 | K37: =SUMIFS(Cash_Book!$G:$G,Cash_Book!$C:$C,"BEPAARI",Cash_Book!$D:$D,"MOTOR",Cash_Book!$E:$E,B37) | L37: =SUMIFS(Cash_Book!$G:$G,Cash_Book!$C:$C,"BEPAARI",Cash_Book!$D:$D,"BHUSSA",Cash_Book!$E:$E,B37) | M37: =SUMIFS(Cash_Book!$G:$G,Cash_Book!$C:$C,"BEPAARI",Cash_Book!$D:$D,"GAWALI",Cash_Book!$E:$E,B37) | N37: =SUMIFS(Cash_Book!$G:$G,Cash_Book!$C:$C,"BEPAARI",Cash_Book!$D:$D,"CASH_ADV",Cash_Book!$E:$E,B37) | O37: =SUMIFS(Cash_Book!$G:$G,Cash_Book!$C:$C,"BEPAARI",Cash_Book!$D:$D,"OTHER",Cash_Book!$E:$E,B37) | P37: =SUM(H37:O37) | Q37: =IF(B37="","",F37-P37+E37) | R37: =SUMIFS(Cash_Book!$G:$G,Cash_Book!$C:$C,"BEPAARI",Cash_Book!$D:$D,"PAYMENT",Cash_Book!$E:$E,B37) | S37: =SUMIFS(JV_Entries!$G:$G,JV_Entries!$C:$C,"BEPAARI",JV_Entries!$D:$D,B37)-SUMIFS(JV_Entries!$G:$G,JV_Entries!$E:$E,"BEPAARI",JV_Entries!$F:$F,B37) | T37: =IF(B37="","",Q37-R37+S37)
A38: 34 | B38: =IF(Masters!$B$36="","",Masters!$B$36) | C38: =IF(B38="","",Masters!$C$36) | D38: =IF(B38="","",IF(Masters!$D$36="","",Masters!$D$36)) | E38: =IF(B38="",0,Masters!$E$36) | F38: =SUMIF(Daily_Sales!$C:$C,B38,Daily_Sales!$G:$G) | G38: =SUMIF(Daily_Sales!$C:$C,B38,Daily_Sales!$E:$E) | H38: =IF(B38="",0,IF(D38<>"",D38*G38,F38*C38/100)) | I38: =IF(G38>0,Masters!$Y$3,0) | J38: =G38*Masters!$Y$4 | K38: =SUMIFS(Cash_Book!$G:$G,Cash_Book!$C:$C,"BEPAARI",Cash_Book!$D:$D,"MOTOR",Cash_Book!$E:$E,B38) | L38: =SUMIFS(Cash_Book!$G:$G,Cash_Book!$C:$C,"BEPAARI",Cash_Book!$D:$D,"BHUSSA",Cash_Book!$E:$E,B38) | M38: =SUMIFS(Cash_Book!$G:$G,Cash_Book!$C:$C,"BEPAARI",Cash_Book!$D:$D,"GAWALI",Cash_Book!$E:$E,B38) | N38: =SUMIFS(Cash_Book!$G:$G,Cash_Book!$C:$C,"BEPAARI",Cash_Book!$D:$D,"CASH_ADV",Cash_Book!$E:$E,B38) | O38: =SUMIFS(Cash_Book!$G:$G,Cash_Book!$C:$C,"BEPAARI",Cash_Book!$D:$D,"OTHER",Cash_Book!$E:$E,B38) | P38: =SUM(H38:O38) | Q38: =IF(B38="","",F38-P38+E38) | R38: =SUMIFS(Cash_Book!$G:$G,Cash_Book!$C:$C,"BEPAARI",Cash_Book!$D:$D,"PAYMENT",Cash_Book!$E:$E,B38) | S38: =SUMIFS(JV_Entries!$G:$G,JV_Entries!$C:$C,"BEPAARI",JV_Entries!$D:$D,B38)-SUMIFS(JV_Entries!$G:$G,JV_Entries!$E:$E,"BEPAARI",JV_Entries!$F:$F,B38) | T38: =IF(B38="","",Q38-R38+S38)
A39: 35 | B39: =IF(Masters!$B$37="","",Masters!$B$37) | C39: =IF(B39="","",Masters!$C$37) | D39: =IF(B39="","",IF(Masters!$D$37="","",Masters!$D$37)) | E39: =IF(B39="",0,Masters!$E$37) | F39: =SUMIF(Daily_Sales!$C:$C,B39,Daily_Sales!$G:$G) | G39: =SUMIF(Daily_Sales!$C:$C,B39,Daily_Sales!$E:$E) | H39: =IF(B39="",0,IF(D39<>"",D39*G39,F39*C39/100)) | I39: =IF(G39>0,Masters!$Y$3,0) | J39: =G39*Masters!$Y$4 | K39: =SUMIFS(Cash_Book!$G:$G,Cash_Book!$C:$C,"BEPAARI",Cash_Book!$D:$D,"MOTOR",Cash_Book!$E:$E,B39) | L39: =SUMIFS(Cash_Book!$G:$G,Cash_Book!$C:$C,"BEPAARI",Cash_Book!$D:$D,"BHUSSA",Cash_Book!$E:$E,B39) | M39: =SUMIFS(Cash_Book!$G:$G,Cash_Book!$C:$C,"BEPAARI",Cash_Book!$D:$D,"GAWALI",Cash_Book!$E:$E,B39) | N39: =SUMIFS(Cash_Book!$G:$G,Cash_Book!$C:$C,"BEPAARI",Cash_Book!$D:$D,"CASH_ADV",Cash_Book!$E:$E,B39) | O39: =SUMIFS(Cash_Book!$G:$G,Cash_Book!$C:$C,"BEPAARI",Cash_Book!$D:$D,"OTHER",Cash_Book!$E:$E,B39) | P39: =SUM(H39:O39) | Q39: =IF(B39="","",F39-P39+E39) | R39: =SUMIFS(Cash_Book!$G:$G,Cash_Book!$C:$C,"BEPAARI",Cash_Book!$D:$D,"PAYMENT",Cash_Book!$E:$E,B39) | S39: =SUMIFS(JV_Entries!$G:$G,JV_Entries!$C:$C,"BEPAARI",JV_Entries!$D:$D,B39)-SUMIFS(JV_Entries!$G:$G,JV_Entries!$E:$E,"BEPAARI",JV_Entries!$F:$F,B39) | T39: =IF(B39="","",Q39-R39+S39)
A40: 36 | B40: =IF(Masters!$B$38="","",Masters!$B$38) | C40: =IF(B40="","",Masters!$C$38) | D40: =IF(B40="","",IF(Masters!$D$38="","",Masters!$D$38)) | E40: =IF(B40="",0,Masters!$E$38) | F40: =SUMIF(Daily_Sales!$C:$C,B40,Daily_Sales!$G:$G) | G40: =SUMIF(Daily_Sales!$C:$C,B40,Daily_Sales!$E:$E) | H40: =IF(B40="",0,IF(D40<>"",D40*G40,F40*C40/100)) | I40: =IF(G40>0,Masters!$Y$3,0) | J40: =G40*Masters!$Y$4 | K40: =SUMIFS(Cash_Book!$G:$G,Cash_Book!$C:$C,"BEPAARI",Cash_Book!$D:$D,"MOTOR",Cash_Book!$E:$E,B40) | L40: =SUMIFS(Cash_Book!$G:$G,Cash_Book!$C:$C,"BEPAARI",Cash_Book!$D:$D,"BHUSSA",Cash_Book!$E:$E,B40) | M40: =SUMIFS(Cash_Book!$G:$G,Cash_Book!$C:$C,"BEPAARI",Cash_Book!$D:$D,"GAWALI",Cash_Book!$E:$E,B40) | N40: =SUMIFS(Cash_Book!$G:$G,Cash_Book!$C:$C,"BEPAARI",Cash_Book!$D:$D,"CASH_ADV",Cash_Book!$E:$E,B40) | O40: =SUMIFS(Cash_Book!$G:$G,Cash_Book!$C:$C,"BEPAARI",Cash_Book!$D:$D,"OTHER",Cash_Book!$E:$E,B40) | P40: =SUM(H40:O40) | Q40: =IF(B40="","",F40-P40+E40) | R40: =SUMIFS(Cash_Book!$G:$G,Cash_Book!$C:$C,"BEPAARI",Cash_Book!$D:$D,"PAYMENT",Cash_Book!$E:$E,B40) | S40: =SUMIFS(JV_Entries!$G:$G,JV_Entries!$C:$C,"BEPAARI",JV_Entries!$D:$D,B40)-SUMIFS(JV_Entries!$G:$G,JV_Entries!$E:$E,"BEPAARI",JV_Entries!$F:$F,B40) | T40: =IF(B40="","",Q40-R40+S40)
A41: 37 | B41: =IF(Masters!$B$39="","",Masters!$B$39) | C41: =IF(B41="","",Masters!$C$39) | D41: =IF(B41="","",IF(Masters!$D$39="","",Masters!$D$39)) | E41: =IF(B41="",0,Masters!$E$39) | F41: =SUMIF(Daily_Sales!$C:$C,B41,Daily_Sales!$G:$G) | G41: =SUMIF(Daily_Sales!$C:$C,B41,Daily_Sales!$E:$E) | H41: =IF(B41="",0,IF(D41<>"",D41*G41,F41*C41/100)) | I41: =IF(G41>0,Masters!$Y$3,0) | J41: =G41*Masters!$Y$4 | K41: =SUMIFS(Cash_Book!$G:$G,Cash_Book!$C:$C,"BEPAARI",Cash_Book!$D:$D,"MOTOR",Cash_Book!$E:$E,B41) | L41: =SUMIFS(Cash_Book!$G:$G,Cash_Book!$C:$C,"BEPAARI",Cash_Book!$D:$D,"BHUSSA",Cash_Book!$E:$E,B41) | M41: =SUMIFS(Cash_Book!$G:$G,Cash_Book!$C:$C,"BEPAARI",Cash_Book!$D:$D,"GAWALI",Cash_Book!$E:$E,B41) | N41: =SUMIFS(Cash_Book!$G:$G,Cash_Book!$C:$C,"BEPAARI",Cash_Book!$D:$D,"CASH_ADV",Cash_Book!$E:$E,B41) | O41: =SUMIFS(Cash_Book!$G:$G,Cash_Book!$C:$C,"BEPAARI",Cash_Book!$D:$D,"OTHER",Cash_Book!$E:$E,B41) | P41: =SUM(H41:O41) | Q41: =IF(B41="","",F41-P41+E41) | R41: =SUMIFS(Cash_Book!$G:$G,Cash_Book!$C:$C,"BEPAARI",Cash_Book!$D:$D,"PAYMENT",Cash_Book!$E:$E,B41) | S41: =SUMIFS(JV_Entries!$G:$G,JV_Entries!$C:$C,"BEPAARI",JV_Entries!$D:$D,B41)-SUMIFS(JV_Entries!$G:$G,JV_Entries!$E:$E,"BEPAARI",JV_Entries!$F:$F,B41) | T41: =IF(B41="","",Q41-R41+S41)
...

Sheet Dukandar_Ledger
A1: DUKANDAR LEDGER
A3: Sr | B3: Dukandar | C3: Opening | D3: Purchases | E3: Discounts | F3: Net Receivable | G3: Receipts | H3: JV Adj | I3: BALANCE
