Workbook

Sheet Masters
A1: BEPAARI MASTER | H1: DUKANDAR MASTER | N1: CAPITAL/LOAN PARTIES | S1: ADVANCE PARTIES | W1: SETTINGS
A2: Sr | B2: Bepaari Name | C2: Comm% | D2: Opening Bal | E2: Phone | F2: Remarks | H2: Sr | I2: Dukandar Name | J2: Opening Bal | K2: Phone | L2: Remarks | N2: Sr | O2: Party Name | P2: Opening Bal | Q2: Type | S2: Sr | T2: Party Name | U2: Opening Bal | W2: Commission Rate (%) | X2: 4
A3: 1 | B3: ABUL HASAN | C3: 4 | D3: 0 | H3: 1 | I3: SAKIM | J3: 0 | N3: 1 | O3: MHN | P3: 0 | Q3: CAPITAL | S3: 1 | W3: KK Fixed (₹/Bepari) | X3: 100
A4: 2 | B4: SHARAFAT | C4: 4 | D4: 0 | H4: 2 | I4: SHARIK | J4: 0 | N4: 2 | O4: SHAKIL GHODEGAON | P4: 0 | Q4: LOAN | S4: 2 | W4: JB Rate (₹/Goat) | X4: 10
A5: 3 | B5: SHARIK | C5: 4 | D5: 0 | H5: 3 | I5: YUNUS | J5: 0 | N5: 3 | S5: 3
A6: 4 | B6: JUNAID | C6: 4 | D6: 0 | H6: 4 | I6: MUDASSIR | J6: 0 | N6: 4 | S6: 4 | W6: Opening Cash | X6: 0
A7: 5 | B7: ANNU SHARIF | C7: 4 | D7: 0 | H7: 5 | I7: ARIF | J7: 0 | N7: 5 | S7: 5 | W7: Opening Bank | X7: 0
A8: 6 | B8: GAYYUR | C8: 4 | D8: 0 | H8: 6 | I8: SHOEB BYCULLA | J8: 0 | N8: 6 | S8: 6
A9: 7 | B9: ARIF KK | C9: 4 | D9: 0 | H9: 7 | I9: ISLAM D | J9: 0 | N9: 7 | S9: 7 | W9: ZAKAT Opening Payable | X9: 0
A10: 8 | B10: KISHOR | C10: 4 | D10: 0 | H10: 8 | I10: MEHMOOD MADH | J10: 0 | N10: 8 | S10: 8
A11: 9 | B11: SHOEB BYCULLA | C11: 4 | D11: 0 | H11: 9 | I11: MOBIN CHIPLUN | J11: 0 | N11: 9 | S11: 9
A12: 10 | B12: MAULANA | C12: 4 | D12: 0 | H12: 10 | I12: JALIL | J12: 0 | N12: 10 | S12: 10
A13: 11 | B13: ISLAM D | C13: 4 | D13: 0 | H13: 11 | I13: IRFAN JOGESHWARI | J13: 0 | N13: 11 | S13: 11
A14: 12 | B14: SALIM RAJ | C14: 4 | D14: 0 | H14: 12 | I14: YUNUS DOMBIVLI | J14: 0 | N14: 12 | S14: 12
A15: 13 | B15: MEHMOOD MADH | C15: 4 | D15: 0 | H15: 13 | I15: IFTEKHAR PUNE | J15: 0 | N15: 13 | S15: 13
A16: 14 | B16: ANAS RAJ | C16: 4 | D16: 0 | H16: 14 | I16: LALA/ASIF | J16: 0 | N16: 14 | S16: 14
A17: 15 | B17: MOBIN CHIPLUN | C17: 4 | D17: 0 | H17: 15 | I17: JAFER KASHIMIRA | J17: 0 | N17: 15 | S17: 15
A18: 16 | B18: AYAZ | C18: 4 | D18: 0 | H18: 16 | I18: CHAND | J18: 0 | N18: 16 | S18: 16
A19: 17 | B19: JALIL | C19: 4 | D19: 0 | H19: 17 | I19: ASIF GOREGAON | J19: 0 | N19: 17 | S19: 17
A20: 18 | B20: NEERAJ | C20: 4 | D20: 0 | H20: 18 | I20: CHINTU SHUJALPUR | J20: 0 | N20: 18 | S20: 18
A21: 19 | B21: IRFAN JOGESHWARI | C21: 4 | D21: 0 | H21: 19 | I21: VAZIR | J21: 0 | N21: 19 | S21: 19
A22: 20 | B22: CHINTU SHUJALPUR | C22: 4 | D22: 0 | H22: 20 | I22: AKRAM | J22: 0 | N22: 20 | S22: 20
A23: 21 | H23: 21 | I23: NADEEM BHIWANDI | J23: 0 | N23: 21 | S23: 21
A24: 22 | H24: 22 | I24: SHAKIL KON | J24: 0 | N24: 22 | S24: 22
A25: 23 | H25: 23 | I25: PARVEZ | J25: 0
A26: 24 | H26: 24
A27: 25 | H27: 25
A28: 26 | H28: 26
A29: 27 | H29: 27
A30: 28 | H30: 28
A31: 29 | H31: 29
A32: 30 | H32: 30
A33: 31 | H33: 31
A34: 32 | H34: 32
A35: 33 | H35: 33
A36: 34 | H36: 34
A37: 35 | H37: 35
... A79: 77 | H79: 77

Sheet Daily_Sales
A1: DAILY SALES (Bepaari → Dukandar)
A2: This feeds: Bepaari Ledger, Dukandar Ledger, Commission
A3: Sr | B3: Date | C3: Bepaari | D3: Dukandar | E3: Qty | F3: Rate | G3: Gross | H3: Discount | I3: Net
A4: 1 | G4: =IF(E4="","",E4*F4) | I4: =IF(G4="","",G4-IF(H4="",0,H4))
A5: 2 | G5: =IF(E5="","",E5*F5) | I5: =IF(G5="","",G5-IF(H5="",0,H5))
A6: 3 | G6: =IF(E6="","",E6*F6) | I6: =IF(G6="","",G6-IF(H6="",0,H6))
A7: 4 | G7: =IF(E7="","",E7*F7) | I7: =IF(G7="","",G7-IF(H7="",0,H7))
A8: 5 | G8: =IF(E8="","",E8*F8) | I8: =IF(G8="","",G8-IF(H8="",0,H8))
A9: 6 | G9: =IF(E9="","",E9*F9) | I9: =IF(G9="","",G9-IF(H9="",0,H9))
A10: 7 | G10: =IF(E10="","",E10*F10) | I10: =IF(G10="","",G10-IF(H10="",0,H10))
A11: 8 | G11: =IF(E11="","",E11*F11) | I11: =IF(G11="","",G11-IF(H11="",0,H11))
A12: 9 | G12: =IF(E12="","",E12*F12) | I12: =IF(G12="","",G12-IF(H12="",0,H12))
A13: 10 | G13: =IF(E13="","",E13*F13) | I13: =IF(G13="","",G13-IF(H13="",0,H13))
A14: 11 | G14: =IF(E14="","",E14*F14) | I14: =IF(G14="","",G14-IF(H14="",0,H14))
A15: 12 | G15: =IF(E15="","",E15*F15) | I15: =IF(G15="","",G15-IF(H15="",0,H15))
... A1003: 1000 | G1003: =IF(E1003="","",E1003*F1003) | I1003: =IF(G1003="","",G1003-IF(H1003="",0,H1003))

Sheet Cash_Book
A1: CASH BOOK (All Transactions) | L1: CASH/BANK SUMMARY
A2: BEP expenses in OUT cols. ZAKAT: PROVISION=provision, PAID=payment | K2: Opening Cash | L2: =Masters!$X$6
A3: Sr | B3: Date | C3: Type | D3: Sub-Type | E3: Party | F3: Particulars | G3: Cash OUT | H3: Bank OUT | I3: Cash IN | J3: Bank IN | K3: Opening Bank | L3: =Masters!$X$7
A4: 1 | K4: Total Cash OUT | L4: =SUM(G:G)
A5: 2 | K5: Total Bank OUT | L5: =SUM(H:H)
A6: 3 | K6: Total Cash IN | L6: =SUM(I:I)
A7: 4 | K7: Total Bank IN | L7: =SUM(J:J)
A8: 5 | K8: CLOSING CASH | L8: =L2-L4+L6
A9: 6 | K9: CLOSING BANK | L9: =L3-L5+L7
A10: 7
A11: 8
A12: 9
A13: 10
A14: 11
A15: 12
A16: 13
A17: 14
A18: 15
A19: 16
A20: 17
A21: 18
... A2003: 2000

Sheet Bepaari_Ledger
A1: BEPAARI LEDGER (Auto-calculated)
A2: From: Daily_Sales + Cash_Book (Type=BEPAARI)
A4: Sr | B4: Bepaari | C4: Comm% | D4: Opening | E4: Gross Sales | F4: Qty | G4: Commission | H4: KK | I4: JB | J4: Motor | K4: Bhussa | L4: Gawali | M4: Cash/Adv | N4: Other | O4: Tot.Deduct | P4: Net Payable | Q4: Payments | R4: BALANCE
A5: 1 | B5: =IF(Masters!$B$3="","",Masters!$B$3) | C5: =IF(B5="","",Masters!$C$3) | D5: =IF(B5="",0,Masters!$D$3) | E5: =SUMIF(Daily_Sales!$C:$C,B5,Daily_Sales!$G:$G) | F5: =SUMIF(Daily_Sales!$C:$C,B5,Daily_Sales!$E:$E) | G5: =IF(B5="",0,E5*C5/100) | H5: =IF(F5>0,Masters!$X$3,0) | I5: =F5*Masters!$X$4 | J5: =SUMIFS(Cash_Book!$G:$G,Cash_Book!$C:$C,"BEPAARI",Cash_Book!$D:$D,"MOTOR",Cash_Book!$E:$E,B5)+SUMIFS(Cash_Book!$H:$H,Cash_Book!$C:$C,"BEPAARI",Cash_Book!$D:$D,"MOTOR",Cash_Book!$E:$E,B5) | K5: =SUMIFS(Cash_Book!$G:$G,Cash_Book!$C:$C,"BEPAARI",Cash_Book!$D:$D,"BHUSSA",Cash_Book!$E:$E,B5)+SUMIFS(Cash_Book!$H:$H,Cash_Book!$C:$C,"BEPAARI",Cash_Book!$D:$D,"BHUSSA",Cash_Book!$E:$E,B5) | L5: =SUMIFS(Cash_Book!$G:$G,Cash_Book!$C:$C,"BEPAARI",Cash_Book!$D:$D,"GAWALI",Cash_Book!$E:$E,B5)+SUMIFS(Cash_Book!$H:$H,Cash_Book!$C:$C,"BEPAARI",Cash_Book!$D:$D,"GAWALI",Cash_Book!$E:$E,B5) | M5: =SUMIFS(Cash_Book!$G:$G,Cash_Book!$C:$C,"BEPAARI",Cash_Book!$D:$D,"CASH_ADV",Cash_Book!$E:$E,B5)+SUMIFS(Cash_Book!$H:$H,Cash_Book!$C:$C,"BEPAARI",Cash_Book!$D:$D,"CASH_ADV",Cash_Book!$E:$E,B5) | N5: =SUMIFS(Cash_Book!$G:$G,Cash_Book!$C:$C,"BEPAARI",Cash_Book!$D:$D,"OTHER",Cash_Book!$E:$E,B5)+SUMIFS(Cash_Book!$H:$H,Cash_Book!$C:$C,"BEPAARI",Cash_Book!$D:$D,"OTHER",Cash_Book!$E:$E,B5) | O5: =SUM(G5:N5) | P5: =IF(B5="","",E5-O5+D5) | Q5: =SUMIFS(Cash_Book!$G:$G,Cash_Book!$C:$C,"BEPAARI",Cash_Book!$D:$D,"PAYMENT",Cash_Book!$E:$E,B5)+SUMIFS(Cash_Book!$H:$H,Cash_Book!$C:$C,"BEPAARI",Cash_Book!$D:$D,"PAYMENT",Cash_Book!$E:$E,B5) | R5: =IF(B5="","",P5-Q5)
A6: 2 | B6: =IF(Masters!$B$4="","",Masters!$B$4) | C6: =IF(B6="","",Masters!$C$4) | D6: =IF(B6="",0,Masters!$D$4) | E6: =SUMIF(Daily_Sales!$C:$C,B6,Daily_Sales!$G:$G) | F6: =SUMIF(Daily_Sales!$C:$C,B6,Daily_Sales!$E:$E) | G6: =IF(B6="",0,E6*C6/100) | H6: =IF(F6>0,Masters!$X$3,0) | I6: =F6*Masters!$X$4 | J6: =SUMIFS(Cash_Book!$G:$G,Cash_Book!$C:$C,"BEPAARI",Cash_Book!$D:$D,"MOTOR",Cash_Book!$E:$E,B6)+SUMIFS(Cash_Book!$H:$H,Cash_Book!$C:$C,"BEPAARI",Cash_Book!$D:$D,"MOTOR",Cash_Book!$E:$E,B6) | K6: =SUMIFS(Cash_Book!$G:$G,Cash_Book!$C:$C,"BEPAARI",Cash_Book!$D:$D,"BHUSSA",Cash_Book!$E:$E,B6)+SUMIFS(Cash_Book!$H:$H,Cash_Book!$C:$C,"BEPAARI",Cash_Book!$D:$D,"BHUSSA",Cash_Book!$E:$E,B6) | L6: =SUMIFS(Cash_Book!$G:$G,Cash_Book!$C:$C,"BEPAARI",Cash_Book!$D:$D,"GAWALI",Cash_Book!$E:$E,B6)+SUMIFS(Cash_Book!$H:$H,Cash_Book!$C:$C,"BEPAARI",Cash_Book!$D:$D,"GAWALI",Cash_Book!$E:$E,B6) | M6: =SUMIFS(Cash_Book!$G:$G,Cash_Book!$C:$C,"BEPAARI",Cash_Book!$D:$D,"CASH_ADV",Cash_Book!$E:$E,B6)+SUMIFS(Cash_Book!$H:$H,Cash_Book!$C:$C,"BEPAARI",Cash_Book!$D:$D,"CASH_ADV",Cash_Book!$E:$E,B6) | N6: =SUMIFS(Cash_Book!$G:$G,Cash_Book!$C:$C,"BEPAARI",Cash_Book!$D:$D,"OTHER",Cash_Book!$E:$E,B6)+SUMIFS(Cash_Book!$H:$H,Cash_Book!$C:$C,"BEPAARI",Cash_Book!$D:$D,"OTHER",Cash_Book!$E:$E,B6) | O6: =SUM(G6:N6) | P6: =IF(B6="","",E6-O6+D6) | Q6: =SUMIFS(Cash_Book!$G:$G,Cash_Book!$C:$C,"BEPAARI",Cash_Book!$D:$D,"PAYMENT",Cash_Book!$E:$E,B6)+SUMIFS(Cash_Book!$H:$H,Cash_Book!$C:$C,"BEPAARI",Cash_Book!$D:$D,"PAYMENT",Cash_Book!$E:$E,B6) | R6: =IF(B6="","",P6-Q6)
A7: 3 | B7: =IF(Masters!$B$5="","",Masters!$B$5) | C7: =IF(B7="","",Masters!$C$5) | D7: =IF(B7="",0,Masters!$D$5) | E7: =SUMIF(Daily_Sales!$C:$C,B7,Daily_Sales!$G:$G) | F7: =SUMIF(Daily_Sales!$C:$C,B7,Daily_Sales!$E:$E) | G7: =IF(B7="",0,E7*C7/100) | H7: =IF(F7>0,Masters!$X$3,0) | I7: =F7*Masters!$X$4 | J7: =SUMIFS(Cash_Book!$G:$G,Cash_Book!$C:$C,"BEPAARI",Cash_Book!$D:$D,"MOTOR",Cash_Book!$E:$E,B7)+SUMIFS(Cash_Book!$H:$H,Cash_Book!$C:$C,"BEPAARI",Cash_Book!$D:$D,"MOTOR",Cash_Book!$E:$E,B7) | K7: =SUMIFS(Cash_Book!$G:$G,Cash_Book!$C:$C,"BEPAARI",Cash_Book!$D:$D,"BHUSSA",Cash_Book!$E:$E,B7)+SUMIFS(Cash_Book!$H:$H,Cash_Book!$C:$C,"BEPAARI",Cash_Book!$D:$D,"BHUSSA",Cash_Book!$E:$E,B7) | L7: =SUMIFS(Cash_Book!$G:$G,Cash_Book!$C:$C,"BEPAARI",Cash_Book!$D:$D,"GAWALI",Cash_Book!$E:$E,B7)+SUMIFS(Cash_Book!$H:$H,Cash_Book!$C:$C,"BEPAARI",Cash_Book!$D:$D,"GAWALI",Cash_Book!$E:$E,B7) | M7: =SUMIFS(Cash_Book!$G:$G,Cash_Book!$C:$C,"BEPAARI",Cash_Book!$D:$D,"CASH_ADV",Cash_Book!$E:$E,B7)+SUMIFS(Cash_Book!$H:$H,Cash_Book!$C:$C,"BEPAARI",Cash_Book!$D:$D,"CASH_ADV",Cash_Book!$E:$E,B7) | N7: =SUMIFS(Cash_Book!$G:$G,Cash_Book!$C:$C,"BEPAARI",Cash_Book!$D:$D,"OTHER",Cash_Book!$E:$E,B7)+SUMIFS(Cash_Book!$H:$H,Cash_Book!$C:$C,"BEPAARI",Cash_Book!$D:$D,"OTHER",Cash_Book!$E:$E,B7) | O7: =SUM(G7:N7) | P7: =IF(B7="","",E7-O7+D7) | Q7: =SUMIFS(Cash_Book!$G:$G,Cash_Book!$C:$C,"BEPAARI",Cash_Book!$D:$D,"PAYMENT",Cash_Book!$E:$E,B7)+SUMIFS(Cash_Book!$H:$H,Cash_Book!$C:$C,"BEPAARI",Cash_Book!$D:$D,"PAYMENT",Cash_Book!$E:$E,B7) | R7: =IF(B7="","",P7-Q7)
A8: 4 | B8: =IF(Masters!$B$6="","",Masters!$B$6) | C8: =IF(B8="","",Masters!$C$6) | D8: =IF(B8="",0,Masters!$D$6) | E8: =SUMIF(Daily_Sales!$C:$C,B8,Daily_Sales!$G:$G) | F8: =SUMIF(Daily_Sales!$C:$C,B8,Daily_Sales!$E:$E) | G8: =IF(B8="",0,E8*C8/100) | H8: =IF(F8>0,Masters!$X$3,0) | I8: =F8*Masters!$X$4 | J8: =SUMIFS(Cash_Book!$G:$G,Cash_Book!$C:$C,"BEPAARI",Cash_Book!$D:$D,"MOTOR",Cash_Book!$E:$E,B8)+SUMIFS(Cash_Book!$H:$H,Cash_Book!$C:$C,"BEPAARI",Cash_Book!$D:$D,"MOTOR",Cash_Book!$E:$E,B8) | K8: =SUMIFS(Cash_Book!$G:$G,Cash_Book!$C:$C,"BEPAARI",Cash_Book!$D:$D,"BHUSSA",Cash_Book!$E:$E,B8)+SUMIFS(Cash_Book!$H:$H,Cash_Book!$C:$C,"BEPAARI",Cash_Book!$D:$D,"BHUSSA",Cash_Book!$E:$E,B8) | L8: =SUMIFS(Cash_Book!$G:$G,Cash_Book!$C:$C,"BEPAARI",Cash_Book!$D:$D,"GAWALI",Cash_Book!$E:$E,B8)+SUMIFS(Cash_Book!$H:$H,Cash_Book!$C:$C,"BEPAARI",Cash_Book!$D:$D,"GAWALI",Cash_Book!$E:$E,B8) | M8: =SUMIFS(Cash_Book!$G:$G,Cash_Book!$C:$C,"BEPAARI",Cash_Book!$D:$D,"CASH_ADV",Cash_Book!$E:$E,B8)+SUMIFS(Cash_Book!$H:$H,Cash_Book!$C:$C,"BEPAARI",Cash_Book!$D:$D,"CASH_ADV",Cash_Book!$E:$E,B8) | N8: =SUMIFS(Cash_Book!$G:$G,Cash_Book!$C:$C,"BEPAARI",Cash_Book!$D:$D,"OTHER",Cash_Book!$E:$E,B8)+SUMIFS(Cash_Book!$H:$H,Cash_Book!$C:$C,"BEPAARI",Cash_Book!$D:$D,"OTHER",Cash_Book!$E:$E,B8) | O8: =SUM(G8:N8) | P8: =IF(B8="","",E8-O8+D8) | Q8: =SUMIFS(Cash_Book!$G:$G,Cash_Book!$C:$C,"BEPAARI",Cash_Book!$D:$D,"PAYMENT",Cash_Book!$E:$E,B8)+SUMIFS(Cash_Book!$H:$H,Cash_Book!$C:$C,"BEPAARI",Cash_Book!$D:$D,"PAYMENT",Cash_Book!$E:$E,B8) | R8: =IF(B8="","",P8-Q8)
A9: 5 | B9: =IF(Masters!$B$7="","",Masters!$B$7) | C9: =IF(B9="","",Masters!$C$7) | D9: =IF(B9="",0,Masters!$D$7) | E9: =SUMIF(Daily_Sales!$C:$C,B9,Daily_Sales!$G:$G) | F9: =SUMIF(Daily_Sales!$C:$C,B9,Daily_Sales!$E:$E) | G9: =IF(B9="",0,E9*C9/100) | H9: =IF(F9>0,Masters!$X$3,0) | I9: =F9*Masters!$X$4 | J9: =SUMIFS(Cash_Book!$G:$G,Cash_Book!$C:$C,"BEPAARI",Cash_Book!$D:$D,"MOTOR",Cash_Book!$E:$E,B9)+SUMIFS(Cash_Book!$H:$H,Cash_Book!$C:$C,"BEPAARI",Cash_Book!$D:$D,"MOTOR",Cash_Book!$E:$E,B9) | K9: =SUMIFS(Cash_Book!$G:$G,Cash_Book!$C:$C,"BEPAARI",Cash_Book!$D:$D,"BHUSSA",Cash_Book!$E:$E,B9)+SUMIFS(Cash_Book!$H:$H,Cash_Book!$C:$C,"BEPAARI",Cash_Book!$D:$D,"BHUSSA",Cash_Book!$E:$E,B9) | L9: =SUMIFS(Cash_Book!$G:$G,Cash_Book!$C:$C,"BEPAARI",Cash_Book!$D:$D,"GAWALI",Cash_Book!$E:$E,B9)+SUMIFS(Cash_Book!$H:$H,Cash_Book!$C:$C,"BEPAARI",Cash_Book!$D:$D,"GAWALI",Cash_Book!$E:$E,B9) | M9: =SUMIFS(Cash_Book!$G:$G,Cash_Book!$C:$C,"BEPAARI",Cash_Book!$D:$D,"CASH_ADV",Cash_Book!$E:$E,B9)+SUMIFS(Cash_Book!$H:$H,Cash_Book!$C:$C,"BEPAARI",Cash_Book!$D:$D,"CASH_ADV",Cash_Book!$E:$E,B9) | N9: =SUMIFS(Cash_Book!$G:$G,Cash_Book!$C:$C,"BEPAARI",Cash_Book!$D:$D,"OTHER",Cash_Book!$E:$E,B9)+SUMIFS(Cash_Book!$H:$H,Cash_Book!$C:$C,"BEPAARI",Cash_Book!$D:$D,"OTHER",Cash_Book!$E:$E,B9) | O9: =SUM(G9:N9) | P9: =IF(B9="","",E9-O9+D9) | Q9: =SUMIFS(Cash_Book!$G:$G,Cash_Book!$C:$C,"BEPAARI",Cash_Book!$D:$D,"PAYMENT",Cash_Book!$E:$E,B9)+SUMIFS(Cash_Book!$H:$H,Cash_Book!$C:$C,"BEPAARI",Cash_Book!$D:$D,"PAYMENT",Cash_Book!$E:$E,B9) | R9: =IF(B9="","",P9-Q9)
A10: 6 | B10: =IF(Masters!$B$8="","",Masters!$B$8) | C10: =IF(B10="","",Masters!$C$8) | D10: =IF(B10="",0,Masters!$D$8) | E10: =SUMIF(Daily_Sales!$C:$C,B10,Daily_Sales!$G:$G) | F10: =SUMIF(Daily_Sales!$C:$C,B10,Daily_Sales!$E:$E) | G10: =IF(B10="",0,E10*C10/100) | H10: =IF(F10>0,Masters!$X$3,0) | I10: =F10*Masters!$X$4 | J10: =SUMIFS(Cash_Book!$G:$G,Cash_Book!$C:$C,"BEPAARI",Cash_Book!$D:$D,"MOTOR",Cash_Book!$E:$E,B10)+SUMIFS(Cash_Book!$H:$H,Cash_Book!$C:$C,"BEPAARI",Cash_Book!$D:$D,"MOTOR",Cash_Book!$E:$E,B10) | K10: =SUMIFS(Cash_Book!$G:$G,Cash_Book!$C:$C,"BEPAARI",Cash_Book!$D:$D,"BHUSSA",Cash_Book!$E:$E,B10)+SUMIFS(Cash_Book!$H:$H,Cash_Book!$C:$C,"BEPAARI",Cash_Book!$D:$D,"BHUSSA",Cash_Book!$E:$E,B10) | L10: =SUMIFS(Cash_Book!$G:$G,Cash_Book!$C:$C,"BEPAARI",Cash_Book!$D:$D,"GAWALI",Cash_Book!$E:$E,B10)+SUMIFS(Cash_Book!$H:$H,Cash_Book!$C:$C,"BEPAARI",Cash_Book!$D:$D,"GAWALI",Cash_Book!$E:$E,B10) | M10: =SUMIFS(Cash_Book!$G:$G,Cash_Book!$C:$C,"BEPAARI",Cash_Book!$D:$D,"CASH_ADV",Cash_Book!$E:$E,B10)+SUMIFS(Cash_Book!$H:$H,Cash_Book!$C:$C,"BEPAARI",Cash_Book!$D:$D,"CASH_ADV",Cash_Book!$E:$E,B10) | N10: =SUMIFS(Cash_Book!$G:$G,Cash_Book!$C:$C,"BEPAARI",Cash_Book!$D:$D,"OTHER",Cash_Book!$E:$E,B10)+SUMIFS(Cash_Book!$H:$H,Cash_Book!$C:$C,"BEPAARI",Cash_Book!$D:$D,"OTHER",Cash_Book!$E:$E,B10) | O10: =SUM(G10:N10) | P10: =IF(B10="","",E10-O10+D10) | Q10: =SUMIFS(Cash_Book!$G:$G,Cash_Book!$C:$C,"BEPAARI",Cash_Book!$D:$D,"PAYMENT",Cash_Book!$E:$E,B10)+SUMIFS(Cash_Book!$H:$H,Cash_Book!$C:$C,"BEPAARI",Cash_Book!$D:$D,"PAYMENT",Cash_Book!$E:$E,B10) | R10: =IF(B10="","",P10-Q10)
A11: 7 | B11: =IF(Masters!$B$9="","",Masters!$B$9) | C11: =IF(B11="","",Masters!$C$9) | D11: =IF(B11="",0,Masters!$D$9) | E11: =SUMIF(Daily_Sales!$C:$C,B11,Daily_Sales!$G:$G) | F11: =SUMIF(Daily_Sales!$C:$C,B11,Daily_Sales!$E:$E) | G11: =IF(B11="",0,E11*C11/100) | H11: =IF(F11>0,Masters!$X$3,0) | I11: =F11*Masters!$X$4 | J11: =SUMIFS(Cash_Book!$G:$G,Cash_Book!$C:$C,"BEPAARI",Cash_Book!$D:$D,"MOTOR",Cash_Book!$E:$E,B11)+SUMIFS(Cash_Book!$H:$H,Cash_Book!$C:$C,"BEPAARI",Cash_Book!$D:$D,"MOTOR",Cash_Book!$E:$E,B11) | K11: =SUMIFS(Cash_Book!$G:$G,Cash_Book!$C:$C,"BEPAARI",Cash_Book!$D:$D,"BHUSSA",Cash_Book!$E:$E,B11)+SUMIFS(Cash_Book!$H:$H,Cash_Book!$C:$C,"BEPAARI",Cash_Book!$D:$D,"BHUSSA",Cash_Book!$E:$E,B11) | L11: =SUMIFS(Cash_Book!$G:$G,Cash_Book!$C:$C,"BEPAARI",Cash_Book!$D:$D,"GAWALI",Cash_Book!$E:$E,B11)+SUMIFS(Cash_Book!$H:$H,Cash_Book!$C:$C,"BEPAARI",Cash_Book!$D:$D,"GAWALI",Cash_Book!$E:$E,B11) | M11: =SUMIFS(Cash_Book!$G:$G,Cash_Book!$C:$C,"BEPAARI",Cash_Book!$D:$D,"CASH_ADV",Cash_Book!$E:$E,B11)+SUMIFS(Cash_Book!$H:$H,Cash_Book!$C:$C,"BEPAARI",Cash_Book!$D:$D,"CASH_ADV",Cash_Book!$E:$E,B11) | N11: =SUMIFS(Cash_Book!$G:$G,Cash_Book!$C:$C,"BEPAARI",Cash_Book!$D:$D,"OTHER",Cash_Book!$E:$E,B11)+SUMIFS(Cash_Book!$H:$H,Cash_Book!$C:$C,"BEPAARI",Cash_Book!$D:$D,"OTHER",Cash_Book!$E:$E,B11) | O11: =SUM(G11:N11) | P11: =IF(B11="","",E11-O11+D11) | Q11: =SUMIFS(Cash_Book!$G:$G,Cash_Book!$C:$C,"BEPAARI",Cash_Book!$D:$D,"PAYMENT",Cash_Book!$E:$E,B11)+SUMIFS(Cash_Book!$H:$H,Cash_Book!$C:$C,"BEPAARI",Cash_Book!$D:$D,"PAYMENT",Cash_Book!$E:$E,B11) | R11: =IF(B11="","",P11-Q11)
A12: 8 | B12: =IF(Masters!$B$10="","",Masters!$B$10) | C12: =IF(B12="","",Masters!$C$10) | D12: =IF(B12="",0,Masters!$D$10) | E12: =SUMIF(Daily_Sales!$C:$C,B12,Daily_Sales!$G:$G) | F12: =SUMIF(Daily_Sales!$C:$C,B12,Daily_Sales!$E:$E) | G12: =IF(B12="",0,E12*C12/100) | H12: =IF(F12>0,Masters!$X$3,0) | I12: =F12*Masters!$X$4 | J12: =SUMIFS(Cash_Book!$G:$G,Cash_Book!$C:$C,"BEPAARI",Cash_Book!$D:$D,"MOTOR",Cash_Book!$E:$E,B12)+SUMIFS(Cash_Book!$H:$H,Cash_Book!$C:$C,"BEPAARI",Cash_Book!$D:$D,"MOTOR",Cash_Book!$E:$E,B12) | K12: =SUMIFS(Cash_Book!$G:$G,Cash_Book!$C:$C,"BEPAARI",Cash_Book!$D:$D,"BHUSSA",Cash_Book!$E:$E,B12)+SUMIFS(Cash_Book!$H:$H,Cash_Book!$C:$C,"BEPAARI",Cash_Book!$D:$D,"BHUSSA",Cash_Book!$E:$E,B12) | L12: =SUMIFS(Cash_Book!$G:$G,Cash_Book!$C:$C,"BEPAARI",Cash_Book!$D:$D,"GAWALI",Cash_Book!$E:$E,B12)+SUMIFS(Cash_Book!$H:$H,Cash_Book!$C:$C,"BEPAARI",Cash_Book!$D:$D,"GAWALI",Cash_Book!$E:$E,B12) | M12: =SUMIFS(Cash_Book!$G:$G,Cash_Book!$C:$C,"BEPAARI",Cash_Book!$D:$D,"CASH_ADV",Cash_Book!$E:$E,B12)+SUMIFS(Cash_Book!$H:$H,Cash_Book!$C:$C,"BEPAARI",Cash_Book!$D:$D,"CASH_ADV",Cash_Book!$E:$E,B12) | N12: =SUMIFS(Cash_Book!$G:$G,Cash_Book!$C:$C,"BEPAARI",Cash_Book!$D:$D,"OTHER",Cash_Book!$E:$E,B12)+SUMIFS(Cash_Book!$H:$H,Cash_Book!$C:$C,"BEPAARI",Cash_Book!$D:$D,"OTHER",Cash_Book!$E:$E,B12) | O12: =SUM(G12:N12) | P12: =IF(B12="","",E12-O12+D12) | Q12: =SUMIFS(Cash_Book!$G:$G,Cash_Book!$C:$C,"BEPAARI",Cash_Book!$D:$D,"PAYMENT",Cash_Book!$E:$E,B12)+SUMIFS(Cash_Book!$H:$H,Cash_Book!$C:$C,"BEPAARI",Cash_Book!$D:$D,"PAYMENT",Cash_Book!$E:$E,B12) | R12: =IF(B12="","",P12-Q12)
A13: 9 | B13: =IF(Masters!$B$11="","",Masters!$B$11) | C13: =IF(B13="","",Masters!$C$11) | D13: =IF(B13="",0,Masters!$D$11) | E13: =SUMIF(Daily_Sales!$C:$C,B13,Daily_Sales!$G:$G) | F13: =SUMIF(Daily_Sales!$C:$C,B13,Daily_Sales!$E:$E) | G13: =IF(B13="",0,E13*C13/100) | H13: =IF(F13>0,Masters!$X$3,0) | I13: =F13*Masters!$X$4 | J13: =SUMIFS(Cash_Book!$G:$G,Cash_Book!$C:$C,"BEPAARI",Cash_Book!$D:$D,"MOTOR",Cash_Book!$E:$E,B13)+SUMIFS(Cash_Book!$H:$H,Cash_Book!$C:$C,"BEPAARI",Cash_Book!$D:$D,"MOTOR",Cash_Book!$E:$E,B13) | K13: =SUMIFS(Cash_Book!$G:$G,Cash_Book!$C:$C,"BEPAARI",Cash_Book!$D:$D,"BHUSSA",Cash_Book!$E:$E,B13)+SUMIFS(Cash_Book!$H:$H,Cash_Book!$C:$C,"BEPAARI",Cash_Book!$D:$D,"BHUSSA",Cash_Book!$E:$E,B13) | L13: =SUMIFS(Cash_Book!$G:$G,Cash_Book!$C:$C,"BEPAARI",Cash_Book!$D:$D,"GAWALI",Cash_Book!$E:$E,B13)+SUMIFS(Cash_Book!$H:$H,Cash_Book!$C:$C,"BEPAARI",Cash_Book!$D:$D,"GAWALI",Cash_Book!$E:$E,B13) | M13: =SUMIFS(Cash_Book!$G:$G,Cash_Book!$C:$C,"BEPAARI",Cash_Book!$D:$D,"CASH_ADV",Cash_Book!$E:$E,B13)+SUMIFS(Cash_Book!$H:$H,Cash_Book!$C:$C,"BEPAARI",Cash_Book!$D:$D,"CASH_ADV",Cash_Book!$E:$E,B13) | N13: =SUMIFS(Cash_Book!$G:$G,Cash_Book!$C:$C,"BEPAARI",Cash_Book!$D:$D,"OTHER",Cash_Book!$E:$E,B13)+SUMIFS(Cash_Book!$H:$H,Cash_Book!$C:$C,"BEPAARI",Cash_Book!$D:$D,"OTHER",Cash_Book!$E:$E,B13) | O13: =SUM(G13:N13) | P13: =IF(B13="","",E13-O13+D13) | Q13: =SUMIFS(Cash_Book!$G:$G,Cash_Book!$C:$C,"BEPAARI",Cash_Book!$D:$D,"PAYMENT",Cash_Book!$E:$E,B13)+SUMIFS(Cash_Book!$H:$H,Cash_Book!$C:$C,"BEPAARI",Cash_Book!$D:$D,"PAYMENT",Cash_Book!$E:$E,B13) | R13: =IF(B13="","",P13-Q13)
A14: 10 | B14: =IF(Masters!$B$12="","",Masters!$B$12) | C14: =IF(B14="","",Masters!$C$12) | D14: =IF(B14="",0,Masters!$D$12) | E14: =SUMIF(Daily_Sales!$C:$C,B14,Daily_Sales!$G:$G) | F14: =SUMIF(Daily_Sales!$C:$C,B14,Daily_Sales!$E:$E) | G14: =IF(B14="",0,E14*C14/100) | H14: =IF(F14>0,Masters!$X$3,0) | I14: =F14*Masters!$X$4 | J14: =SUMIFS(Cash_Book!$G:$G,Cash_Book!$C:$C,"BEPAARI",Cash_Book!$D:$D,"MOTOR",Cash_Book!$E:$E,B14)+SUMIFS(Cash_Book!$H:$H,Cash_Book!$C:$C,"BEPAARI",Cash_Book!$D:$D,"MOTOR",Cash_Book!$E:$E,B14) | K14: =SUMIFS(Cash_Book!$G:$G,Cash_Book!$C:$C,"BEPAARI",Cash_Book!$D:$D,"BHUSSA",Cash_Book!$E:$E,B14)+SUMIFS(Cash_Book!$H:$H,Cash_Book!$C:$C,"BEPAARI",Cash_Book!$D:$D,"BHUSSA",Cash_Book!$E:$E,B14) | L14: =SUMIFS(Cash_Book!$G:$G,Cash_Book!$C:$C,"BEPAARI",Cash_Book!$D:$D,"GAWALI",Cash_Book!$E:$E,B14)+SUMIFS(Cash_Book!$H:$H,Cash_Book!$C:$C,"BEPAARI",Cash_Book!$D:$D,"GAWALI",Cash_Book!$E:$E,B14) | M14: =SUMIFS(Cash_Book!$G:$G,Cash_Book!$C:$C,"BEPAARI",Cash_Book!$D:$D,"CASH_ADV",Cash_Book!$E:$E,B14)+SUMIFS(Cash_Book!$H:$H,Cash_Book!$C:$C,"BEPAARI",Cash_Book!$D:$D,"CASH_ADV",Cash_Book!$E:$E,B14) | N14: =SUMIFS(Cash_Book!$G:$G,Cash_Book!$C:$C,"BEPAARI",Cash_Book!$D:$D,"OTHER",Cash_Book!$E:$E,B14)+SUMIFS(Cash_Book!$H:$H,Cash_Book!$C:$C,"BEPAARI",Cash_Book!$D:$D,"OTHER",Cash_Book!$E:$E,B14) | O14: =SUM(G14:N14) | P14: =IF(B14="","",E14-O14+D14) | Q14: =SUMIFS(Cash_Book!$G:$G,Cash_Book!$C:$C,"BEPAARI",Cash_Book!$D:$D,"PAYMENT",Cash_Book!$E:$E,B14)+SUMIFS(Cash_Book!$H:$H,Cash_Book!$C:$C,"BEPAARI",Cash_Book!$D:$D,"PAYMENT",Cash_Book!$E:$E,B14) | R14: =IF(B14="","",P14-Q14)
A15: 11 | B15: =IF(Masters!$B$13="","",Masters!$B$13) | C15: =IF(B15="","",Masters!$C$13) | D15: =IF(B15="",0,Masters!$D$13) | E15: =SUMIF(Daily_Sales!$C:$C,B15,Daily_Sales!$G:$G) | F15: =SUMIF(Daily_Sales!$C:$C,B15,Daily_Sales!$E:$E) | G15: =IF(B15="",0,E15*C15/100) | H15: =IF(F15>0,Masters!$X$3,0) | I15: =F15*Masters!$X$4 | J15: =SUMIFS(Cash_Book!$G:$G,Cash_Book!$C:$C,"BEPAARI",Cash_Book!$D:$D,"MOTOR",Cash_Book!$E:$E,B15)+SUMIFS(Cash_Book!$H:$H,Cash_Book!$C:$C,"BEPAARI",Cash_Book!$D:$D,"MOTOR",Cash_Book!$E:$E,B15) | K15: =SUMIFS(Cash_Book!$G:$G,Cash_Book!$C:$C,"BEPAARI",Cash_Book!$D:$D,"BHUSSA",Cash_Book!$E:$E,B15)+SUMIFS(Cash_Book!$H:$H,Cash_Book!$C:$C,"BEPAARI",Cash_Book!$D:$D,"BHUSSA",Cash_Book!$E:$E,B15) | L15: =SUMIFS(Cash_Book!$G:$G,Cash_Book!$C:$C,"BEPAARI",Cash_Book!$D:$D,"GAWALI",Cash_Book!$E:$E,B15)+SUMIFS(Cash_Book!$H:$H,Cash_Book!$C:$C,"BEPAARI",Cash_Book!$D:$D,"GAWALI",Cash_Book!$E:$E,B15) | M15: =SUMIFS(Cash_Book!$G:$G,Cash_Book!$C:$C,"BEPAARI",Cash_Book!$D:$D,"CASH_ADV",Cash_Book!$E:$E,B15)+SUMIFS(Cash_Book!$H:$H,Cash_Book!$C:$C,"BEPAARI",Cash_Book!$D:$D,"CASH_ADV",Cash_Book!$E:$E,B15) | N15: =SUMIFS(Cash_Book!$G:$G,Cash_Book!$C:$C,"BEPAARI",Cash_Book!$D:$D,"OTHER",Cash_Book!$E:$E,B15)+SUMIFS(Cash_Book!$H:$H,Cash_Book!$C:$C,"BEPAARI",Cash_Book!$D:$D,"OTHER",Cash_Book!$E:$E,B15) | O15: =SUM(G15:N15) | P15: =IF(B15="","",E15-O15+D15) | Q15: =SUMIFS(Cash_Book!$G:$G,Cash_Book!$C:$C,"BEPAARI",Cash_Book!$D:$D,"PAYMENT",Cash_Book!$E:$E,B15)+SUMIFS(Cash_Book!$H:$H,Cash_Book!$C:$C,"BEPAARI",Cash_Book!$D:$D,"PAYMENT",Cash_Book!$E:$E,B15) | R15: =IF(B15="","",P15-Q15)
A16: 12 | B16: =IF(Masters!$B$14="","",Masters!$B$14) | C16: =IF(B16="","",Masters!$C$14) | D16: =IF(B16="",0,Masters!$D$14) | E16: =SUMIF(Daily_Sales!$C:$C,B16,Daily_Sales!$G:$G) | F16: =SUMIF(Daily_Sales!$C:$C,B16,Daily_Sales!$E:$E) | G16: =IF(B16="",0,E16*C16/100) | H16: =IF(F16>0,Masters!$X$3,0) | I16: =F16*Masters!$X$4 | J16: =SUMIFS(Cash_Book!$G:$G,Cash_Book!$C:$C,"BEPAARI",Cash_Book!$D:$D,"MOTOR",Cash_Book!$E:$E,B16)+SUMIFS(Cash_Book!$H:$H,Cash_Book!$C:$C,"BEPAARI",Cash_Book!$D:$D,"MOTOR",Cash_Book!$E:$E,B16) | K16: =SUMIFS(Cash_Book!$G:$G,Cash_Book!$C:$C,"BEPAARI",Cash_Book!$D:$D,"BHUSSA",Cash_Book!$E:$E,B16)+SUMIFS(Cash_Book!$H:$H,Cash_Book!$C:$C,"BEPAARI",Cash_Book!$D:$D,"BHUSSA",Cash_Book!$E:$E,B16) | L16: =SUMIFS(Cash_Book!$G:$G,Cash_Book!$C:$C,"BEPAARI",Cash_Book!$D:$D,"GAWALI",Cash_Book!$E:$E,B16)+SUMIFS(Cash_Book!$H:$H,Cash_Book!$C:$C,"BEPAARI",Cash_Book!$D:$D,"GAWALI",Cash_Book!$E:$E,B16) | M16: =SUMIFS(Cash_Book!$G:$G,Cash_Book!$C:$C,"BEPAARI",Cash_Book!$D:$D,"CASH_ADV",Cash_Book!$E:$E,B16)+SUMIFS(Cash_Book!$H:$H,Cash_Book!$C:$C,"BEPAARI",Cash_Book!$D:$D,"CASH_ADV",Cash_Book!$E:$E,B16) | N16: =SUMIFS(Cash_Book!$G:$G,Cash_Book!$C:$C,"BEPAARI",Cash_Book!$D:$D,"OTHER",Cash_Book!$E:$E,B16)+SUMIFS(Cash_Book!$H:$H,Cash_Book!$C:$C,"BEPAARI",Cash_Book!$D:$D,"OTHER",Cash_Book!$E:$E,B16) | O16: =SUM(G16:N16) | P16: =IF(B16="","",E16-O16+D16) | Q16: =SUMIFS(Cash_Book!$G:$G,Cash_Book!$C:$C,"BEPAARI",Cash_Book!$D:$D,"PAYMENT",Cash_Book!$E:$E,B16)+SUMIFS(Cash_Book!$H:$H,Cash_Book!$C:$C,"BEPAARI",Cash_Book!$D:$D,"PAYMENT",Cash_Book!$E:$E,B16) | R16: =IF(B16="","",P16-Q16)
A17: 13 | B17: =IF(Masters!$B$15="","",Masters!$B$15) | C17: =IF(B17="","",Masters!$C$15) | D17: =IF(B17="",0,Masters!$D$15) | E17: =SUMIF(Daily_Sales!$C:$C,B17,Daily_Sales!$G:$G) | F17: =SUMIF(Daily_Sales!$C:$C,B17,Daily_Sales!$E:$E) | G17: =IF(B17="",0,E17*C17/100) | H17: =IF(F17>0,Masters!$X$3,0) | I17: =F17*Masters!$X$4 | J17: =SUMIFS(Cash_Book!$G:$G,Cash_Book!$C:$C,"BEPAARI",Cash_Book!$D:$D,"MOTOR",Cash_Book!$E:$E,B17)+SUMIFS(Cash_Book!$H:$H,Cash_Book!$C:$C,"BEPAARI",Cash_Book!$D:$D,"MOTOR",Cash_Book!$E:$E,B17) | K17: =SUMIFS(Cash_Book!$G:$G,Cash_Book!$C:$C,"BEPAARI",Cash_Book!$D:$D,"BHUSSA",Cash_Book!$E:$E,B17)+SUMIFS(Cash_Book!$H:$H,Cash_Book!$C:$C,"BEPAARI",Cash_Book!$D:$D,"BHUSSA",Cash_Book!$E:$E,B17) | L17: =SUMIFS(Cash_Book!$G:$G,Cash_Book!$C:$C,"BEPAARI",Cash_Book!$D:$D,"GAWALI",Cash_Book!$E:$E,B17)+SUMIFS(Cash_Book!$H:$H,Cash_Book!$C:$C,"BEPAARI",Cash_Book!$D:$D,"GAWALI",Cash_Book!$E:$E,B17) | M17: =SUMIFS(Cash_Book!$G:$G,Cash_Book!$C:$C,"BEPAARI",Cash_Book!$D:$D,"CASH_ADV",Cash_Book!$E:$E,B17)+SUMIFS(Cash_Book!$H:$H,Cash_Book!$C:$C,"BEPAARI",Cash_Book!$D:$D,"CASH_ADV",Cash_Book!$E:$E,B17) | N17: =SUMIFS(Cash_Book!$G:$G,Cash_Book!$C:$C,"BEPAARI",Cash_Book!$D:$D,"OTHER",Cash_Book!$E:$E,B17)+SUMIFS(Cash_Book!$H:$H,Cash_Book!$C:$C,"BEPAARI",Cash_Book!$D:$D,"OTHER",Cash_Book!$E:$E,B17) | O17: =SUM(G17:N17) | P17: =IF(B17="","",E17-O17+D17) | Q17: =SUMIFS(Cash_Book!$G:$G,Cash_Book!$C:$C,"BEPAARI",Cash_Book!$D:$D,"PAYMENT",Cash_Book!$E:$E,B17)+SUMIFS(Cash_Book!$H:$H,Cash_Book!$C:$C,"BEPAARI",Cash_Book!$D:$D,"PAYMENT",Cash_Book!$E:$E,B17) | R17: =IF(B17="","",P17-Q17)
A18: 14 | B18: =IF(Masters!$B$16="","",Masters!$B$16) | C18: =IF(B18="","",Masters!$C$16) | D18: =IF(B18="",0,Masters!$D$16) | E18: =SUMIF(Daily_Sales!$C:$C,B18,Daily_Sales!$G:$G) | F18: =SUMIF(Daily_Sales!$C:$C,B18,Daily_Sales!$E:$E) | G18: =IF(B18="",0,E18*C18/100) | H18: =IF(F18>0,Masters!$X$3,0) | I18: =F18*Masters!$X$4 | J18: =SUMIFS(Cash_Book!$G:$G,Cash_Book!$C:$C,"BEPAARI",Cash_Book!$D:$D,"MOTOR",Cash_Book!$E:$E,B18)+SUMIFS(Cash_Book!$H:$H,Cash_Book!$C:$C,"BEPAARI",Cash_Book!$D:$D,"MOTOR",Cash_Book!$E:$E,B18) | K18: =SUMIFS(Cash_Book!$G:$G,Cash_Book!$C:$C,"BEPAARI",Cash_Book!$D:$D,"BHUSSA",Cash_Book!$E:$E,B18)+SUMIFS(Cash_Book!$H:$H,Cash_Book!$C:$C,"BEPAARI",Cash_Book!$D:$D,"BHUSSA",Cash_Book!$E:$E,B18) | L18: =SUMIFS(Cash_Book!$G:$G,Cash_Book!$C:$C,"BEPAARI",Cash_Book!$D:$D,"GAWALI",Cash_Book!$E:$E,B18)+SUMIFS(Cash_Book!$H:$H,Cash_Book!$C:$C,"BEPAARI",Cash_Book!$D:$D,"GAWALI",Cash_Book!$E:$E,B18) | M18: =SUMIFS(Cash_Book!$G:$G,Cash_Book!$C:$C,"BEPAARI",Cash_Book!$D:$D,"CASH_ADV",Cash_Book!$E:$E,B18)+SUMIFS(Cash_Book!$H:$H,Cash_Book!$C:$C,"BEPAARI",Cash_Book!$D:$D,"CASH_ADV",Cash_Book!$E:$E,B18) | N18: =SUMIFS(Cash_Book!$G:$G,Cash_Book!$C:$C,"BEPAARI",Cash_Book!$D:$D,"OTHER",Cash_Book!$E:$E,B18)+SUMIFS(Cash_Book!$H:$H,Cash_Book!$C:$C,"BEPAARI",Cash_Book!$D:$D,"OTHER",Cash_Book!$E:$E,B18) | O18: =SUM(G18:N18) | P18: =IF(B18="","",E18-O18+D18) | Q18: =SUMIFS(Cash_Book!$G:$G,Cash_Book!$C:$C,"BEPAARI",Cash_Book!$D:$D,"PAYMENT",Cash_Book!$E:$E,B18)+SUMIFS(Cash_Book!$H:$H,Cash_Book!$C:$C,"BEPAARI",Cash_Book!$D:$D,"PAYMENT",Cash_Book!$E:$E,B18) | R18: =IF(B18="","",P18-Q18)
A19: 15 | B19: =IF(Masters!$B$17="","",Masters!$B$17) | C19: =IF(B19="","",Masters!$C$17) | D19: =IF(B19="",0,Masters!$D$17) | E19: =SUMIF(Daily_Sales!$C:$C,B19,Daily_Sales!$G:$G) | F19: =SUMIF(Daily_Sales!$C:$C,B19,Daily_Sales!$E:$E) | G19: =IF(B19="",0,E19*C19/100) | H19: =IF(F19>0,Masters!$X$3,0) | I19: =F19*Masters!$X$4 | J19: =SUMIFS(Cash_Book!$G:$G,Cash_Book!$C:$C,"BEPAARI",Cash_Book!$D:$D,"MOTOR",Cash_Book!$E:$E,B19)+SUMIFS(Cash_Book!$H:$H,Cash_Book!$C:$C,"BEPAARI",Cash_Book!$D:$D,"MOTOR",Cash_Book!$E:$E,B19) | K19: =SUMIFS(Cash_Book!$G:$G,Cash_Book!$C:$C,"BEPAARI",Cash_Book!$D:$D,"BHUSSA",Cash_Book!$E:$E,B19)+SUMIFS(Cash_Book!$H:$H,Cash_Book!$C:$C,"BEPAARI",Cash_Book!$D:$D,"BHUSSA",Cash_Book!$E:$E,B19) | L19: =SUMIFS(Cash_Book!$G:$G,Cash_Book!$C:$C,"BEPAARI",Cash_Book!$D:$D,"GAWALI",Cash_Book!$E:$E,B19)+SUMIFS(Cash_Book!$H:$H,Cash_Book!$C:$C,"BEPAARI",Cash_Book!$D:$D,"GAWALI",Cash_Book!$E:$E,B19) | M19: =SUMIFS(Cash_Book!$G:$G,Cash_Book!$C:$C,"BEPAARI",Cash_Book!$D:$D,"CASH_ADV",Cash_Book!$E:$E,B19)+SUMIFS(Cash_Book!$H:$H,Cash_Book!$C:$C,"BEPAARI",Cash_Book!$D:$D,"CASH_ADV",Cash_Book!$E:$E,B19) | N19: =SUMIFS(Cash_Book!$G:$G,Cash_Book!$C:$C,"BEPAARI",Cash_Book!$D:$D,"OTHER",Cash_Book!$E:$E,B19)+SUMIFS(Cash_Book!$H:$H,Cash_Book!$C:$C,"BEPAARI",Cash_Book!$D:$D,"OTHER",Cash_Book!$E:$E,B19) | O19: =SUM(G19:N19) | P19: =IF(B19="","",E19-O19+D19) | Q19: =SUMIFS(Cash_Book!$G:$G,Cash_Book!$C:$C,"BEPAARI",Cash_Book!$D:$D,"PAYMENT",Cash_Book!$E:$E,B19)+SUMIFS(Cash_Book!$H:$H,Cash_Book!$C:$C,"BEPAARI",Cash_Book!$D:$D,"PAYMENT",Cash_Book!$E:$E,B19) | R19: =IF(B19="","",P19-Q19)
A20: 16 | B20: =IF(Masters!$B$18="","",Masters!$B$18) | C20: =IF(B20="","",Masters!$C$18) | D20: =IF(B20="",0,Masters!$D$18) | E20: =SUMIF(Daily_Sales!$C:$C,B20,Daily_Sales!$G:$G) | F20: =SUMIF(Daily_Sales!$C:$C,B20,Daily_Sales!$E:$E) | G20: =IF(B20="",0,E20*C20/100) | H20: =IF(F20>0,Masters!$X$3,0) | I20: =F20*Masters!$X$4 | J20: =SUMIFS(Cash_Book!$G:$G,Cash_Book!$C:$C,"BEPAARI",Cash_Book!$D:$D,"MOTOR",Cash_Book!$E:$E,B20)+SUMIFS(Cash_Book!$H:$H,Cash_Book!$C:$C,"BEPAARI",Cash_Book!$D:$D,"MOTOR",Cash_Book!$E:$E,B20) | K20: =SUMIFS(Cash_Book!$G:$G,Cash_Book!$C:$C,"BEPAARI",Cash_Book!$D:$D,"BHUSSA",Cash_Book!$E:$E,B20)+SUMIFS(Cash_Book!$H:$H,Cash_Book!$C:$C,"BEPAARI",Cash_Book!$D:$D,"BHUSSA",Cash_Book!$E:$E,B20) | L20: =SUMIFS(Cash_Book!$G:$G,Cash_Book!$C:$C,"BEPAARI",Cash_Book!$D:$D,"GAWALI",Cash_Book!$E:$E,B20)+SUMIFS(Cash_Book!$H:$H,Cash_Book!$C:$C,"BEPAARI",Cash_Book!$D:$D,"GAWALI",Cash_Book!$E:$E,B20) | M20: =SUMIFS(Cash_Book!$G:$G,Cash_Book!$C:$C,"BEPAARI",Cash_Book!$D:$D,"CASH_ADV",Cash_Book!$E:$E,B20)+SUMIFS(Cash_Book!$H:$H,Cash_Book!$C:$C,"BEPAARI",Cash_Book!$D:$D,"CASH_ADV",Cash_Book!$E:$E,B20) | N20: =SUMIFS(Cash_Book!$G:$G,Cash_Book!$C:$C,"BEPAARI",Cash_Book!$D:$D,"OTHER",Cash_Book!$E:$E,B20)+SUMIFS(Cash_Book!$H:$H,Cash_Book!$C:$C,"BEPAARI",Cash_Book!$D:$D,"OTHER",Cash_Book!$E:$E,B20) | O20: =SUM(G20:N20) | P20: =IF(B20="","",E20-O20+D20) | Q20: =SUMIFS(Cash_Book!$G:$G,Cash_Book!$C:$C,"BEPAARI",Cash_Book!$D:$D,"PAYMENT",Cash_Book!$E:$E,B20)+SUMIFS(Cash_Book!$H:$H,Cash_Book!$C:$C,"BEPAARI",Cash_Book!$D:$D,"PAYMENT",Cash_Book!$E:$E,B20) | R20: =IF(B20="","",P20-Q20)
A21: 17 | B21: =IF(Masters!$B$19="","",Masters!$B$19) | C21: =IF(B21="","",Masters!$C$19) | D21: =IF(B21="",0,Masters!$D$19) | E21: =SUMIF(Daily_Sales!$C:$C,B21,Daily_Sales!$G:$G) | F21: =SUMIF(Daily_Sales!$C:$C,B21,Daily_Sales!$E:$E) | G21: =IF(B21="",0,E21*C21/100) | H21: =IF(F21>0,Masters!$X$3,0) | I21: =F21*Masters!$X$4 | J21: =SUMIFS(Cash_Book!$G:$G,Cash_Book!$C:$C,"BEPAARI",Cash_Book!$D:$D,"MOTOR",Cash_Book!$E:$E,B21)+SUMIFS(Cash_Book!$H:$H,Cash_Book!$C:$C,"BEPAARI",Cash_Book!$D:$D,"MOTOR",Cash_Book!$E:$E,B21) | K21: =SUMIFS(Cash_Book!$G:$G,Cash_Book!$C:$C,"BEPAARI",Cash_Book!$D:$D,"BHUSSA",Cash_Book!$E:$E,B21)+SUMIFS(Cash_Book!$H:$H,Cash_Book!$C:$C,"BEPAARI",Cash_Book!$D:$D,"BHUSSA",Cash_Book!$E:$E,B21) | L21: =SUMIFS(Cash_Book!$G:$G,Cash_Book!$C:$C,"BEPAARI",Cash_Book!$D:$D,"GAWALI",Cash_Book!$E:$E,B21)+SUMIFS(Cash_Book!$H:$H,Cash_Book!$C:$C,"BEPAARI",Cash_Book!$D:$D,"GAWALI",Cash_Book!$E:$E,B21) | M21: =SUMIFS(Cash_Book!$G:$G,Cash_Book!$C:$C,"BEPAARI",Cash_Book!$D:$D,"CASH_ADV",Cash_Book!$E:$E,B21)+SUMIFS(Cash_Book!$H:$H,Cash_Book!$C:$C,"BEPAARI",Cash_Book!$D:$D,"CASH_ADV",Cash_Book!$E:$E,B21) | N21: =SUMIFS(Cash_Book!$G:$G,Cash_Book!$C:$C,"BEPAARI",Cash_Book!$D:$D,"OTHER",Cash_Book!$E:$E,B21)+SUMIFS(Cash_Book!$H:$H,Cash_Book!$C:$C,"BEPAARI",Cash_Book!$D:$D,"OTHER",Cash_Book!$E:$E,B21) | O21: =SUM(G21:N21) | P21: =IF(B21="","",E21-O21+D21) | Q21: =SUMIFS(Cash_Book!$G:$G,Cash_Book!$C:$C,"BEPAARI",Cash_Book!$D:$D,"PAYMENT",Cash_Book!$E:$E,B21)+SUMIFS(Cash_Book!$H:$H,Cash_Book!$C:$C,"BEPAARI",Cash_Book!$D:$D,"PAYMENT",Cash_Book!$E:$E,B21) | R21: =IF(B21="","",P21-Q21)
A22: 18 | B22: =IF(Masters!$B$20="","",Masters!$B$20) | C22: =IF(B22="","",Masters!$C$20) | D22: =IF(B22="",0,Masters!$D$20) | E22: =SUMIF(Daily_Sales!$C:$C,B22,Daily_Sales!$G:$G) | F22: =SUMIF(Daily_Sales!$C:$C,B22,Daily_Sales!$E:$E) | G22: =IF(B22="",0,E22*C22/100) | H22: =IF(F22>0,Masters!$X$3,0) | I22: =F22*Masters!$X$4 | J22: =SUMIFS(Cash_Book!$G:$G,Cash_Book!$C:$C,"BEPAARI",Cash_Book!$D:$D,"MOTOR",Cash_Book!$E:$E,B22)+SUMIFS(Cash_Book!$H:$H,Cash_Book!$C:$C,"BEPAARI",Cash_Book!$D:$D,"MOTOR",Cash_Book!$E:$E,B22) | K22: =SUMIFS(Cash_Book!$G:$G,Cash_Book!$C:$C,"BEPAARI",Cash_Book!$D:$D,"BHUSSA",Cash_Book!$E:$E,B22)+SUMIFS(Cash_Book!$H:$H,Cash_Book!$C:$C,"BEPAARI",Cash_Book!$D:$D,"BHUSSA",Cash_Book!$E:$E,B22) | L22: =SUMIFS(Cash_Book!$G:$G,Cash_Book!$C:$C,"BEPAARI",Cash_Book!$D:$D,"GAWALI",Cash_Book!$E:$E,B22)+SUMIFS(Cash_Book!$H:$H,Cash_Book!$C:$C,"BEPAARI",Cash_Book!$D:$D,"GAWALI",Cash_Book!$E:$E,B22) | M22: =SUMIFS(Cash_Book!$G:$G,Cash_Book!$C:$C,"BEPAARI",Cash_Book!$D:$D,"CASH_ADV",Cash_Book!$E:$E,B22)+SUMIFS(Cash_Book!$H:$H,Cash_Book!$C:$C,"BEPAARI",Cash_Book!$D:$D,"CASH_ADV",Cash_Book!$E:$E,B22) | N22: =SUMIFS(Cash_Book!$G:$G,Cash_Book!$C:$C,"BEPAARI",Cash_Book!$D:$D,"OTHER",Cash_Book!$E:$E,B22)+SUMIFS(Cash_Book!$H:$H,Cash_Book!$C:$C,"BEPAARI",Cash_Book!$D:$D,"OTHER",Cash_Book!$E:$E,B22) | O22: =SUM(G22:N22) | P22: =IF(B22="","",E22-O22+D22) | Q22: =SUMIFS(Cash_Book!$G:$G,Cash_Book!$C:$C,"BEPAARI",Cash_Book!$D:$D,"PAYMENT",Cash_Book!$E:$E,B22)+SUMIFS(Cash_Book!$H:$H,Cash_Book!$C:$C,"BEPAARI",Cash_Book!$D:$D,"PAYMENT",Cash_Book!$E:$E,B22) | R22: =IF(B22="","",P22-Q22)
A23: 19 | B23: =IF(Masters!$B$21="","",Masters!$B$21) | C23: =IF(B23="","",Masters!$C$21) | D23: =IF(B23="",0,Masters!$D$21) | E23: =SUMIF(Daily_Sales!$C:$C,B23,Daily_Sales!$G:$G) | F23: =SUMIF(Daily_Sales!$C:$C,B23,Daily_Sales!$E:$E) | G23: =IF(B23="",0,E23*C23/100) | H23: =IF(F23>0,Masters!$X$3,0) | I23: =F23*Masters!$X$4 | J23: =SUMIFS(Cash_Book!$G:$G,Cash_Book!$C:$C,"BEPAARI",Cash_Book!$D:$D,"MOTOR",Cash_Book!$E:$E,B23)+SUMIFS(Cash_Book!$H:$H,Cash_Book!$C:$C,"BEPAARI",Cash_Book!$D:$D,"MOTOR",Cash_Book!$E:$E,B23) | K23: =SUMIFS(Cash_Book!$G:$G,Cash_Book!$C:$C,"BEPAARI",Cash_Book!$D:$D,"BHUSSA",Cash_Book!$E:$E,B23)+SUMIFS(Cash_Book!$H:$H,Cash_Book!$C:$C,"BEPAARI",Cash_Book!$D:$D,"BHUSSA",Cash_Book!$E:$E,B23) | L23: =SUMIFS(Cash_Book!$G:$G,Cash_Book!$C:$C,"BEPAARI",Cash_Book!$D:$D,"GAWALI",Cash_Book!$E:$E,B23)+SUMIFS(Cash_Book!$H:$H,Cash_Book!$C:$C,"BEPAARI",Cash_Book!$D:$D,"GAWALI",Cash_Book!$E:$E,B23) | M23: =SUMIFS(Cash_Book!$G:$G,Cash_Book!$C:$C,"BEPAARI",Cash_Book!$D:$D,"CASH_ADV",Cash_Book!$E:$E,B23)+SUMIFS(Cash_Book!$H:$H,Cash_Book!$C:$C,"BEPAARI",Cash_Book!$D:$D,"CASH_ADV",Cash_Book!$E:$E,B23) | N23: =SUMIFS(Cash_Book!$G:$G,Cash_Book!$C:$C,"BEPAARI",Cash_Book!$D:$D,"OTHER",Cash_Book!$E:$E,B23)+SUMIFS(Cash_Book!$H:$H,Cash_Book!$C:$C,"BEPAARI",Cash_Book!$D:$D,"OTHER",Cash_Book!$E:$E,B23) | O23: =SUM(G23:N23) | P23: =IF(B23="","",E23-O23+D23) | Q23: =SUMIFS(Cash_Book!$G:$G,Cash_Book!$C:$C,"BEPAARI",Cash_Book!$D:$D,"PAYMENT",Cash_Book!$E:$E,B23)+SUMIFS(Cash_Book!$H:$H,Cash_Book!$C:$C,"BEPAARI",Cash_Book!$D:$D,"PAYMENT",Cash_Book!$E:$E,B23) | R23: =IF(B23="","",P23-Q23)
A24: 20 | B24: =IF(Masters!$B$22="","",Masters!$B$22) | C24: =IF(B24="","",Masters!$C$22) | D24: =IF(B24="",0,Masters!$D$22) | E24: =SUMIF(Daily_Sales!$C:$C,B24,Daily_Sales!$G:$G) | F24: =SUMIF(Daily_Sales!$C:$C,B24,Daily_Sales!$E:$E) | G24: =IF(B24="",0,E24*C24/100) | H24: =IF(F24>0,Masters!$X$3,0) | I24: =F24*Masters!$X$4 | J24: =SUMIFS(Cash_Book!$G:$G,Cash_Book!$C:$C,"BEPAARI",Cash_Book!$D:$D,"MOTOR",Cash_Book!$E:$E,B24)+SUMIFS(Cash_Book!$H:$H,Cash_Book!$C:$C,"BEPAARI",Cash_Book!$D:$D,"MOTOR",Cash_Book!$E:$E,B24) | K24: =SUMIFS(Cash_Book!$G:$G,Cash_Book!$C:$C,"BEPAARI",Cash_Book!$D:$D,"BHUSSA",Cash_Book!$E:$E,B24)+SUMIFS(Cash_Book!$H:$H,Cash_Book!$C:$C,"BEPAARI",Cash_Book!$D:$D,"BHUSSA",Cash_Book!$E:$E,B24) | L24: =SUMIFS(Cash_Book!$G:$G,Cash_Book!$C:$C,"BEPAARI",Cash_Book!$D:$D,"GAWALI",Cash_Book!$E:$E,B24)+SUMIFS(Cash_Book!$H:$H,Cash_Book!$C:$C,"BEPAARI",Cash_Book!$D:$D,"GAWALI",Cash_Book!$E:$E,B24) | M24: =SUMIFS(Cash_Book!$G:$G,Cash_Book!$C:$C,"BEPAARI",Cash_Book!$D:$D,"CASH_ADV",Cash_Book!$E:$E,B24)+SUMIFS(Cash_Book!$H:$H,Cash_Book!$C:$C,"BEPAARI",Cash_Book!$D:$D,"CASH_ADV",Cash_Book!$E:$E,B24) | N24: =SUMIFS(Cash_Book!$G:$G,Cash_Book!$C:$C,"BEPAARI",Cash_Book!$D:$D,"OTHER",Cash_Book!$E:$E,B24)+SUMIFS(Cash_Book!$H:$H,Cash_Book!$C:$C,"BEPAARI",Cash_Book!$D:$D,"OTHER",Cash_Book!$E:$E,B24) | O24: =SUM(G24:N24) | P24: =IF(B24="","",E24-O24+D24) | Q24: =SUMIFS(Cash_Book!$G:$G,Cash_Book!$C:$C,"BEPAARI",Cash_Book!$D:$D,"PAYMENT",Cash_Book!$E:$E,B24)+SUMIFS(Cash_Book!$H:$H,Cash_Book!$C:$C,"BEPAARI",Cash_Book!$D:$D,"PAYMENT",Cash_Book!$E:$E,B24) | R24: =IF(B24="","",P24-Q24)
A25: 21 | B25: =IF(Masters!$B$23="","",Masters!$B$23) | C25: =IF(B25="","",Masters!$C$23) | D25: =IF(B25="",0,Masters!$D$23) | E25: =SUMIF(Daily_Sales!$C:$C,B25,Daily_Sales!$G:$G) | F25: =SUMIF(Daily_Sales!$C:$C,B25,Daily_Sales!$E:$E) | G25: =IF(B25="",0,E25*C25/100) | H25: =IF(F25>0,Masters!$X$3,0) | I25: =F25*Masters!$X$4 | J25: =SUMIFS(Cash_Book!$G:$G,Cash_Book!$C:$C,"BEPAARI",Cash_Book!$D:$D,"MOTOR",Cash_Book!$E:$E,B25)+SUMIFS(Cash_Book!$H:$H,Cash_Book!$C:$C,"BEPAARI",Cash_Book!$D:$D,"MOTOR",Cash_Book!$E:$E,B25) | K25: =SUMIFS(Cash_Book!$G:$G,Cash_Book!$C:$C,"BEPAARI",Cash_Book!$D:$D,"BHUSSA",Cash_Book!$E:$E,B25)+SUMIFS(Cash_Book!$H:$H,Cash_Book!$C:$C,"BEPAARI",Cash_Book!$D:$D,"BHUSSA",Cash_Book!$E:$E,B25) | L25: =SUMIFS(Cash_Book!$G:$G,Cash_Book!$C:$C,"BEPAARI",Cash_Book!$D:$D,"GAWALI",Cash_Book!$E:$E,B25)+SUMIFS(Cash_Book!$H:$H,Cash_Book!$C:$C,"BEPAARI",Cash_Book!$D:$D,"GAWALI",Cash_Book!$E:$E,B25) | M25: =SUMIFS(Cash_Book!$G:$G,Cash_Book!$C:$C,"BEPAARI",Cash_Book!$D:$D,"CASH_ADV",Cash_Book!$E:$E,B25)+SUMIFS(Cash_Book!$H:$H,Cash_Book!$C:$C,"BEPAARI",Cash_Book!$D:$D,"CASH_ADV",Cash_Book!$E:$E,B25) | N25: =SUMIFS(Cash_Book!$G:$G,Cash_Book!$C:$C,"BEPAARI",Cash_Book!$D:$D,"OTHER",Cash_Book!$E:$E,B25)+SUMIFS(Cash_Book!$H:$H,Cash_Book!$C:$C,"BEPAARI",Cash_Book!$D:$D,"OTHER",Cash_Book!$E:$E,B25) | O25: =SUM(G25:N25) | P25: =IF(B25="","",E25-O25+D25) | Q25: =SUMIFS(Cash_Book!$G:$G,Cash_Book!$C:$C,"BEPAARI",Cash_Book!$D:$D,"PAYMENT",Cash_Book!$E:$E,B25)+SUMIFS(Cash_Book!$H:$H,Cash_Book!$C:$C,"BEPAARI",Cash_Book!$D:$D,"PAYMENT",Cash_Book!$E:$E,B25) | R25: =IF(B25="","",P25-Q25)
A26: 22 | B26: =IF(Masters!$B$24="","",Masters!$B$24) | C26: =IF(B26="","",Masters!$C$24) | D26: =IF(B26="",0,Masters!$D$24) | E26: =SUMIF(Daily_Sales!$C:$C,B26,Daily_Sales!$G:$G) | F26: =SUMIF(Daily_Sales!$C:$C,B26,Daily_Sales!$E:$E) | G26: =IF(B26="",0,E26*C26/100) | H26: =IF(F26>0,Masters!$X$3,0) | I26: =F26*Masters!$X$4 | J26: =SUMIFS(Cash_Book!$G:$G,Cash_Book!$C:$C,"BEPAARI",Cash_Book!$D:$D,"MOTOR",Cash_Book!$E:$E,B26)+SUMIFS(Cash_Book!$H:$H,Cash_Book!$C:$C,"BEPAARI",Cash_Book!$D:$D,"MOTOR",Cash_Book!$E:$E,B26) | K26: =SUMIFS(Cash_Book!$G:$G,Cash_Book!$C:$C,"BEPAARI",Cash_Book!$D:$D,"BHUSSA",Cash_Book!$E:$E,B26)+SUMIFS(Cash_Book!$H:$H,Cash_Book!$C:$C,"BEPAARI",Cash_Book!$D:$D,"BHUSSA",Cash_Book!$E:$E,B26) | L26: =SUMIFS(Cash_Book!$G:$G,Cash_Book!$C:$C,"BEPAARI",Cash_Book!$D:$D,"GAWALI",Cash_Book!$E:$E,B26)+SUMIFS(Cash_Book!$H:$H,Cash_Book!$C:$C,"BEPAARI",Cash_Book!$D:$D,"GAWALI",Cash_Book!$E:$E,B26) | M26: =SUMIFS(Cash_Book!$G:$G,Cash_Book!$C:$C,"BEPAARI",Cash_Book!$D:$D,"CASH_ADV",Cash_Book!$E:$E,B26)+SUMIFS(Cash_Book!$H:$H,Cash_Book!$C:$C,"BEPAARI",Cash_Book!$D:$D,"CASH_ADV",Cash_Book!$E:$E,B26) | N26: =SUMIFS(Cash_Book!$G:$G,Cash_Book!$C:$C,"BEPAARI",Cash_Book!$D:$D,"OTHER",Cash_Book!$E:$E,B26)+SUMIFS(Cash_Book!$H:$H,Cash_Book!$C:$C,"BEPAARI",Cash_Book!$D:$D,"OTHER",Cash_Book!$E:$E,B26) | O26: =SUM(G26:N26) | P26: =IF(B26="","",E26-O26+D26) | Q26: =SUMIFS(Cash_Book!$G:$G,Cash_Book!$C:$C,"BEPAARI",Cash_Book!$D:$D,"PAYMENT",Cash_Book!$E:$E,B26)+SUMIFS(Cash_Book!$H:$H,Cash_Book!$C:$C,"BEPAARI",Cash_Book!$D:$D,"PAYMENT",Cash_Book!$E:$E,B26) | R26: =IF(B26="","",P26-Q26)
A27: 23 | B27: =IF(Masters!$B$25="","",Masters!$B$25) | C27: =IF(B27="","",Masters!$C$25) | D27: =IF(B27="",0,Masters!$D$25) | E27: =SUMIF(Daily_Sales!$C:$C,B27,Daily_Sales!$G:$G) | F27: =SUMIF(Daily_Sales!$C:$C,B27,Daily_Sales!$E:$E) | G27: =IF(B27="",0,E27*C27/100) | H27: =IF(F27>0,Masters!$X$3,0) | I27: =F27*Masters!$X$4 | J27: =SUMIFS(Cash_Book!$G:$G,Cash_Book!$C:$C,"BEPAARI",Cash_Book!$D:$D,"MOTOR",Cash_Book!$E:$E,B27)+SUMIFS(Cash_Book!$H:$H,Cash_Book!$C:$C,"BEPAARI",Cash_Book!$D:$D,"MOTOR",Cash_Book!$E:$E,B27) | K27: =SUMIFS(Cash_Book!$G:$G,Cash_Book!$C:$C,"BEPAARI",Cash_Book!$D:$D,"BHUSSA",Cash_Book!$E:$E,B27)+SUMIFS(Cash_Book!$H:$H,Cash_Book!$C:$C,"BEPAARI",Cash_Book!$D:$D,"BHUSSA",Cash_Book!$E:$E,B27) | L27: =SUMIFS(Cash_Book!$G:$G,Cash_Book!$C:$C,"BEPAARI",Cash_Book!$D:$D,"GAWALI",Cash_Book!$E:$E,B27)+SUMIFS(Cash_Book!$H:$H,Cash_Book!$C:$C,"BEPAARI",Cash_Book!$D:$D,"GAWALI",Cash_Book!$E:$E,B27) | M27: =SUMIFS(Cash_Book!$G:$G,Cash_Book!$C:$C,"BEPAARI",Cash_Book!$D:$D,"CASH_ADV",Cash_Book!$E:$E,B27)+SUMIFS(Cash_Book!$H:$H,Cash_Book!$C:$C,"BEPAARI",Cash_Book!$D:$D,"CASH_ADV",Cash_Book!$E:$E,B27) | N27: =SUMIFS(Cash_Book!$G:$G,Cash_Book!$C:$C,"BEPAARI",Cash_Book!$D:$D,"OTHER",Cash_Book!$E:$E,B27)+SUMIFS(Cash_Book!$H:$H,Cash_Book!$C:$C,"BEPAARI",Cash_Book!$D:$D,"OTHER",Cash_Book!$E:$E,B27) | O27: =SUM(G27:N27) | P27: =IF(B27="","",E27-O27+D27) | Q27: =SUMIFS(Cash_Book!$G:$G,Cash_Book!$C:$C,"BEPAARI",Cash_Book!$D:$D,"PAYMENT",Cash_Book!$E:$E,B27)+SUMIFS(Cash_Book!$H:$H,Cash_Book!$C:$C,"BEPAARI",Cash_Book!$D:$D,"PAYMENT",Cash_Book!$E:$E,B27) | R27: =IF(B27="","",P27-Q27)
A28: 24 | B28: =IF(Masters!$B$26="","",Masters!$B$26) | C28: =IF(B28="","",Masters!$C$26) | D28: =IF(B28="",0,Masters!$D$26) | E28: =SUMIF(Daily_Sales!$C:$C,B28,Daily_Sales!$G:$G) | F28: =SUMIF(Daily_Sales!$C:$C,B28,Daily_Sales!$E:$E) | G28: =IF(B28="",0,E28*C28/100) | H28: =IF(F28>0,Masters!$X$3,0) | I28: =F28*Masters!$X$4 | J28: =SUMIFS(Cash_Book!$G:$G,Cash_Book!$C:$C,"BEPAARI",Cash_Book!$D:$D,"MOTOR",Cash_Book!$E:$E,B28)+SUMIFS(Cash_Book!$H:$H,Cash_Book!$C:$C,"BEPAARI",Cash_Book!$D:$D,"MOTOR",Cash_Book!$E:$E,B28) | K28: =SUMIFS(Cash_Book!$G:$G,Cash_Book!$C:$C,"BEPAARI",Cash_Book!$D:$D,"BHUSSA",Cash_Book!$E:$E,B28)+SUMIFS(Cash_Book!$H:$H,Cash_Book!$C:$C,"BEPAARI",Cash_Book!$D:$D,"BHUSSA",Cash_Book!$E:$E,B28) | L28: =SUMIFS(Cash_Book!$G:$G,Cash_Book!$C:$C,"BEPAARI",Cash_Book!$D:$D,"GAWALI",Cash_Book!$E:$E,B28)+SUMIFS(Cash_Book!$H:$H,Cash_Book!$C:$C,"BEPAARI",Cash_Book!$D:$D,"GAWALI",Cash_Book!$E:$E,B28) | M28: =SUMIFS(Cash_Book!$G:$G,Cash_Book!$C:$C,"BEPAARI",Cash_Book!$D:$D,"CASH_ADV",Cash_Book!$E:$E,B28)+SUMIFS(Cash_Book!$H:$H,Cash_Book!$C:$C,"BEPAARI",Cash_Book!$D:$D,"CASH_ADV",Cash_Book!$E:$E,B28) | N28: =SUMIFS(Cash_Book!$G:$G,Cash_Book!$C:$C,"BEPAARI",Cash_Book!$D:$D,"OTHER",Cash_Book!$E:$E,B28)+SUMIFS(Cash_Book!$H:$H,Cash_Book!$C:$C,"BEPAARI",Cash_Book!$D:$D,"OTHER",Cash_Book!$E:$E,B28) | O28: =SUM(G28:N28) | P28: =IF(B28="","",E28-O28+D28) | Q28: =SUMIFS(Cash_Book!$G:$G,Cash_Book!$C:$C,"BEPAARI",Cash_Book!$D:$D,"PAYMENT",Cash_Book!$E:$E,B28)+SUMIFS(Cash_Book!$H:$H,Cash_Book!$C:$C,"BEPAARI",Cash_Book!$D:$D,"PAYMENT",Cash_Book!$E:$E,B28) | R28: =IF(B28="","",P28-Q28)
A29: 25 | B29: =IF(Masters!$B$27="","",Masters!$B$27) | C29: =IF(B29="","",Masters!$C$27) | D29: =IF(B29="",0,Masters!$D$27) | E29: =SUMIF(Daily_Sales!$C:$C,B29,Daily_Sales!$G:$G) | F29: =SUMIF(Daily_Sales!$C:$C,B29,Daily_Sales!$E:$E) | G29: =IF(B29="",0,E29*C29/100) | H29: =IF(F29>0,Masters!$X$3,0) | I29: =F29*Masters!$X$4 | J29: =SUMIFS(Cash_Book!$G:$G,Cash_Book!$C:$C,"BEPAARI",Cash_Book!$D:$D,"MOTOR",Cash_Book!$E:$E,B29)+SUMIFS(Cash_Book!$H:$H,Cash_Book!$C:$C,"BEPAARI",Cash_Book!$D:$D,"MOTOR",Cash_Book!$E:$E,B29) | K29: =SUMIFS(Cash_Book!$G:$G,Cash_Book!$C:$C,"BEPAARI",Cash_Book!$D:$D,"BHUSSA",Cash_Book!$E:$E,B29)+SUMIFS(Cash_Book!$H:$H,Cash_Book!$C:$C,"BEPAARI",Cash_Book!$D:$D,"BHUSSA",Cash_Book!$E:$E,B29) | L29: =SUMIFS(Cash_Book!$G:$G,Cash_Book!$C:$C,"BEPAARI",Cash_Book!$D:$D,"GAWALI",Cash_Book!$E:$E,B29)+SUMIFS(Cash_Book!$H:$H,Cash_Book!$C:$C,"BEPAARI",Cash_Book!$D:$D,"GAWALI",Cash_Book!$E:$E,B29) | M29: =SUMIFS(Cash_Book!$G:$G,Cash_Book!$C:$C,"BEPAARI",Cash_Book!$D:$D,"CASH_ADV",Cash_Book!$E:$E,B29)+SUMIFS(Cash_Book!$H:$H,Cash_Book!$C:$C,"BEPAARI",Cash_Book!$D:$D,"CASH_ADV",Cash_Book!$E:$E,B29) | N29: =SUMIFS(Cash_Book!$G:$G,Cash_Book!$C:$C,"BEPAARI",Cash_Book!$D:$D,"OTHER",Cash_Book!$E:$E,B29)+SUMIFS(Cash_Book!$H:$H,Cash_Book!$C:$C,"BEPAARI",Cash_Book!$D:$D,"OTHER",Cash_Book!$E:$E,B29) | O29: =SUM(G29:N29) | P29: =IF(B29="","",E29-O29+D29) | Q29: =SUMIFS(Cash_Book!$G:$G,Cash_Book!$C:$C,"BEPAARI",Cash_Book!$D:$D,"PAYMENT",Cash_Book!$E:$E,B29)+SUMIFS(Cash_Book!$H:$H,Cash_Book!$C:$C,"BEPAARI",Cash_Book!$D:$D,"PAYMENT",Cash_Book!$E:$E,B29) | R29: =IF(B29="","",P29-Q29)
A30: 26 | B30: =IF(Masters!$B$28="","",Masters!$B$28) | C30: =IF(B30="","",Masters!$C$28) | D30: =IF(B30="",0,Masters!$D$28) | E30: =SUMIF(Daily_Sales!$C:$C,B30,Daily_Sales!$G:$G) | F30: =SUMIF(Daily_Sales!$C:$C,B30,Daily_Sales!$E:$E) | G30: =IF(B30="",0,E30*C30/100) | H30: =IF(F30>0,Masters!$X$3,0) | I30: =F30*Masters!$X$4 | J30: =SUMIFS(Cash_Book!$G:$G,Cash_Book!$C:$C,"BEPAARI",Cash_Book!$D:$D,"MOTOR",Cash_Book!$E:$E,B30)+SUMIFS(Cash_Book!$H:$H,Cash_Book!$C:$C,"BEPAARI",Cash_Book!$D:$D,"MOTOR",Cash_Book!$E:$E,B30) | K30: =SUMIFS(Cash_Book!$G:$G,Cash_Book!$C:$C,"BEPAARI",Cash_Book!$D:$D,"BHUSSA",Cash_Book!$E:$E,B30)+SUMIFS(Cash_Book!$H:$H,Cash_Book!$C:$C,"BEPAARI",Cash_Book!$D:$D,"BHUSSA",Cash_Book!$E:$E,B30) | L30: =SUMIFS(Cash_Book!$G:$G,Cash_Book!$C:$C,"BEPAARI",Cash_Book!$D:$D,"GAWALI",Cash_Book!$E:$E,B30)+SUMIFS(Cash_Book!$H:$H,Cash_Book!$C:$C,"BEPAARI",Cash_Book!$D:$D,"GAWALI",Cash_Book!$E:$E,B30) | M30: =SUMIFS(Cash_Book!$G:$G,Cash_Book!$C:$C,"BEPAARI",Cash_Book!$D:$D,"CASH_ADV",Cash_Book!$E:$E,B30)+SUMIFS(Cash_Book!$H:$H,Cash_Book!$C:$C,"BEPAARI",Cash_Book!$D:$D,"CASH_ADV",Cash_Book!$E:$E,B30) | N30: =SUMIFS(Cash_Book!$G:$G,Cash_Book!$C:$C,"BEPAARI",Cash_Book!$D:$D,"OTHER",Cash_Book!$E:$E,B30)+SUMIFS(Cash_Book!$H:$H,Cash_Book!$C:$C,"BEPAARI",Cash_Book!$D:$D,"OTHER",Cash_Book!$E:$E,B30) | O30: =SUM(G30:N30) | P30: =IF(B30="","",E30-O30+D30) | Q30: =SUMIFS(Cash_Book!$G:$G,Cash_Book!$C:$C,"BEPAARI",Cash_Book!$D:$D,"PAYMENT",Cash_Book!$E:$E,B30)+SUMIFS(Cash_Book!$H:$H,Cash_Book!$C:$C,"BEPAARI",Cash_Book!$D:$D,"PAYMENT",Cash_Book!$E:$E,B30) | R30: =IF(B30="","",P30-Q30)
A31: 27 | B31: =IF(Masters!$B$29="","",Masters!$B$29) | C31: =IF(B31="","",Masters!$C$29) | D31: =IF(B31="",0,Masters!$D$29) | E31: =SUMIF(Daily_Sales!$C:$C,B31,Daily_Sales!$G:$G) | F31: =SUMIF(Daily_Sales!$C:$C,B31,Daily_Sales!$E:$E) | G31: =IF(B31="",0,E31*C31/100) | H31: =IF(F31>0,Masters!$X$3,0) | I31: =F31*Masters!$X$4 | J31: =SUMIFS(Cash_Book!$G:$G,Cash_Book!$C:$C,"BEPAARI",Cash_Book!$D:$D,"MOTOR",Cash_Book!$E:$E,B31)+SUMIFS(Cash_Book!$H:$H,Cash_Book!$C:$C,"BEPAARI",Cash_Book!$D:$D,"MOTOR",Cash_Book!$E:$E,B31) | K31: =SUMIFS(Cash_Book!$G:$G,Cash_Book!$C:$C,"BEPAARI",Cash_Book!$D:$D,"BHUSSA",Cash_Book!$E:$E,B31)+SUMIFS(Cash_Book!$H:$H,Cash_Book!$C:$C,"BEPAARI",Cash_Book!$D:$D,"BHUSSA",Cash_Book!$E:$E,B31) | L31: =SUMIFS(Cash_Book!$G:$G,Cash_Book!$C:$C,"BEPAARI",Cash_Book!$D:$D,"GAWALI",Cash_Book!$E:$E,B31)+SUMIFS(Cash_Book!$H:$H,Cash_Book!$C:$C,"BEPAARI",Cash_Book!$D:$D,"GAWALI",Cash_Book!$E:$E,B31) | M31: =SUMIFS(Cash_Book!$G:$G,Cash_Book!$C:$C,"BEPAARI",Cash_Book!$D:$D,"CASH_ADV",Cash_Book!$E:$E,B31)+SUMIFS(Cash_Book!$H:$H,Cash_Book!$C:$C,"BEPAARI",Cash_Book!$D:$D,"CASH_ADV",Cash_Book!$E:$E,B31) | N31: =SUMIFS(Cash_Book!$G:$G,Cash_Book!$C:$C,"BEPAARI",Cash_Book!$D:$D,"OTHER",Cash_Book!$E:$E,B31)+SUMIFS(Cash_Book!$H:$H,Cash_Book!$C:$C,"BEPAARI",Cash_Book!$D:$D,"OTHER",Cash_Book!$E:$E,B31) | O31: =SUM(G31:N31) | P31: =IF(B31="","",E31-O31+D31) | Q31: =SUMIFS(Cash_Book!$G:$G,Cash_Book!$C:$C,"BEPAARI",Cash_Book!$D:$D,"PAYMENT",Cash_Book!$E:$E,B31)+SUMIFS(Cash_Book!$H:$H,Cash_Book!$C:$C,"BEPAARI",Cash_Book!$D:$D,"PAYMENT",Cash_Book!$E:$E,B31) | R31: =IF(B31="","",P31-Q31)
A32: 28 | B32: =IF(Masters!$B$30="","",Masters!$B$30) | C32: =IF(B32="","",Masters!$C$30) | D32: =IF(B32="",0,Masters!$D$30) | E32: =SUMIF(Daily_Sales!$C:$C,B32,Daily_Sales!$G:$G) | F32: =SUMIF(Daily_Sales!$C:$C,B32,Daily_Sales!$E:$E) | G32: =IF(B32="",0,E32*C32/100) | H32: =IF(F32>0,Masters!$X$3,0) | I32: =F32*Masters!$X$4 | J32: =SUMIFS(Cash_Book!$G:$G,Cash_Book!$C:$C,"BEPAARI",Cash_Book!$D:$D,"MOTOR",Cash_Book!$E:$E,B32)+SUMIFS(Cash_Book!$H:$H,Cash_Book!$C:$C,"BEPAARI",Cash_Book!$D:$D,"MOTOR",Cash_Book!$E:$E,B32) | K32: =SUMIFS(Cash_Book!$G:$G,Cash_Book!$C:$C,"BEPAARI",Cash_Book!$D:$D,"BHUSSA",Cash_Book!$E:$E,B32)+SUMIFS(Cash_Book!$H:$H,Cash_Book!$C:$C,"BEPAARI",Cash_Book!$D:$D,"BHUSSA",Cash_Book!$E:$E,B32) | L32: =SUMIFS(Cash_Book!$G:$G,Cash_Book!$C:$C,"BEPAARI",Cash_Book!$D:$D,"GAWALI",Cash_Book!$E:$E,B32)+SUMIFS(Cash_Book!$H:$H,Cash_Book!$C:$C,"BEPAARI",Cash_Book!$D:$D,"GAWALI",Cash_Book!$E:$E,B32) | M32: =SUMIFS(Cash_Book!$G:$G,Cash_Book!$C:$C,"BEPAARI",Cash_Book!$D:$D,"CASH_ADV",Cash_Book!$E:$E,B32)+SUMIFS(Cash_Book!$H:$H,Cash_Book!$C:$C,"BEPAARI",Cash_Book!$D:$D,"CASH_ADV",Cash_Book!$E:$E,B32) | N32: =SUMIFS(Cash_Book!$G:$G,Cash_Book!$C:$C,"BEPAARI",Cash_Book!$D:$D,"OTHER",Cash_Book!$E:$E,B32)+SUMIFS(Cash_Book!$H:$H,Cash_Book!$C:$C,"BEPAARI",Cash_Book!$D:$D,"OTHER",Cash_Book!$E:$E,B32) | O32: =SUM(G32:N32) | P32: =IF(B32="","",E32-O32+D32) | Q32: =SUMIFS(Cash_Book!$G:$G,Cash_Book!$C:$C,"BEPAARI",Cash_Book!$D:$D,"PAYMENT",Cash_Book!$E:$E,B32)+SUMIFS(Cash_Book!$H:$H,Cash_Book!$C:$C,"BEPAARI",Cash_Book!$D:$D,"PAYMENT",Cash_Book!$E:$E,B32) | R32: =IF(B32="","",P32-Q32)
A33: 29 | B33: =IF(Masters!$B$31="","",Masters!$B$31) | C33: =IF(B33="","",Masters!$C$31) | D33: =IF(B33="",0,Masters!$D$31) | E33: =SUMIF(Daily_Sales!$C:$C,B33,Daily_Sales!$G:$G) | F33: =SUMIF(Daily_Sales!$C:$C,B33,Daily_Sales!$E:$E) | G33: =IF(B33="",0,E33*C33/100) | H33: =IF(F33>0,Masters!$X$3,0) | I33: =F33*Masters!$X$4 | J33: =SUMIFS(Cash_Book!$G:$G,Cash_Book!$C:$C,"BEPAARI",Cash_Book!$D:$D,"MOTOR",Cash_Book!$E:$E,B33)+SUMIFS(Cash_Book!$H:$H,Cash_Book!$C:$C,"BEPAARI",Cash_Book!$D:$D,"MOTOR",Cash_Book!$E:$E,B33) | K33: =SUMIFS(Cash_Book!$G:$G,Cash_Book!$C:$C,"BEPAARI",Cash_Book!$D:$D,"BHUSSA",Cash_Book!$E:$E,B33)+SUMIFS(Cash_Book!$H:$H,Cash_Book!$C:$C,"BEPAARI",Cash_Book!$D:$D,"BHUSSA",Cash_Book!$E:$E,B33) | L33: =SUMIFS(Cash_Book!$G:$G,Cash_Book!$C:$C,"BEPAARI",Cash_Book!$D:$D,"GAWALI",Cash_Book!$E:$E,B33)+SUMIFS(Cash_Book!$H:$H,Cash_Book!$C:$C,"BEPAARI",Cash_Book!$D:$D,"GAWALI",Cash_Book!$E:$E,B33) | M33: =SUMIFS(Cash_Book!$G:$G,Cash_Book!$C:$C,"BEPAARI",Cash_Book!$D:$D,"CASH_ADV",Cash_Book!$E:$E,B33)+SUMIFS(Cash_Book!$H:$H,Cash_Book!$C:$C,"BEPAARI",Cash_Book!$D:$D,"CASH_ADV",Cash_Book!$E:$E,B33) | N33: =SUMIFS(Cash_Book!$G:$G,Cash_Book!$C:$C,"BEPAARI",Cash_Book!$D:$D,"OTHER",Cash_Book!$E:$E,B33)+SUMIFS(Cash_Book!$H:$H,Cash_Book!$C:$C,"BEPAARI",Cash_Book!$D:$D,"OTHER",Cash_Book!$E:$E,B33) | O33: =SUM(G33:N33) | P33: =IF(B33="","",E33-O33+D33) | Q33: =SUMIFS(Cash_Book!$G:$G,Cash_Book!$C:$C,"BEPAARI",Cash_Book!$D:$D,"PAYMENT",Cash_Book!$E:$E,B33)+SUMIFS(Cash_Book!$H:$H,Cash_Book!$C:$C,"BEPAARI",Cash_Book!$D:$D,"PAYMENT",Cash_Book!$E:$E,B33) | R33: =IF(B33="","",P33-Q33)
A34: 30 | B34: =IF(Masters!$B$32="","",Masters!$B$32) | C34: =IF(B34="","",Masters!$C$32) | D34: =IF(B34="",0,Masters!$D$32) | E34: =SUMIF(Daily_Sales!$C:$C,B34,Daily_Sales!$G:$G) | F34: =SUMIF(Daily_Sales!$C:$C,B34,Daily_Sales!$E:$E) | G34: =IF(B34="",0,E34*C34/100) | H34: =IF(F34>0,Masters!$X$3,0) | I34: =F34*Masters!$X$4 | J34: =SUMIFS(Cash_Book!$G:$G,Cash_Book!$C:$C,"BEPAARI",Cash_Book!$D:$D,"MOTOR",Cash_Book!$E:$E,B34)+SUMIFS(Cash_Book!$H:$H,Cash_Book!$C:$C,"BEPAARI",Cash_Book!$D:$D,"MOTOR",Cash_Book!$E:$E,B34) | K34: =SUMIFS(Cash_Book!$G:$G,Cash_Book!$C:$C,"BEPAARI",Cash_Book!$D:$D,"BHUSSA",Cash_Book!$E:$E,B34)+SUMIFS(Cash_Book!$H:$H,Cash_Book!$C:$C,"BEPAARI",Cash_Book!$D:$D,"BHUSSA",Cash_Book!$E:$E,B34) | L34: =SUMIFS(Cash_Book!$G:$G,Cash_Book!$C:$C,"BEPAARI",Cash_Book!$D:$D,"GAWALI",Cash_Book!$E:$E,B34)+SUMIFS(Cash_Book!$H:$H,Cash_Book!$C:$C,"BEPAARI",Cash_Book!$D:$D,"GAWALI",Cash_Book!$E:$E,B34) | M34: =SUMIFS(Cash_Book!$G:$G,Cash_Book!$C:$C,"BEPAARI",Cash_Book!$D:$D,"CASH_ADV",Cash_Book!$E:$E,B34)+SUMIFS(Cash_Book!$H:$H,Cash_Book!$C:$C,"BEPAARI",Cash_Book!$D:$D,"CASH_ADV",Cash_Book!$E:$E,B34) | N34: =SUMIFS(Cash_Book!$G:$G,Cash_Book!$C:$C,"BEPAARI",Cash_Book!$D:$D,"OTHER",Cash_Book!$E:$E,B34)+SUMIFS(Cash_Book!$H:$H,Cash_Book!$C:$C,"BEPAARI",Cash_Book!$D:$D,"OTHER",Cash_Book!$E:$E,B34) | O34: =SUM(G34:N34) | P34: =IF(B34="","",E34-O34+D34) | Q34: =SUMIFS(Cash_Book!$G:$G,Cash_Book!$C:$C,"BEPAARI",Cash_Book!$D:$D,"PAYMENT",Cash_Book!$E:$E,B34)+SUMIFS(Cash_Book!$H:$H,Cash_Book!$C:$C,"BEPAARI",Cash_Book!$D:$D,"PAYMENT",Cash_Book!$E:$E,B34) | R34: =IF(B34="","",P34-Q34)
A35: 31 | B35: =IF(Masters!$B$33="","",Masters!$B$33) | C35: =IF(B35="","",Masters!$C$33) | D35: =IF(B35="",0,Masters!$D$33) | E35: =SUMIF(Daily_Sales!$C:$C,B35,Daily_Sales!$G:$G) | F35: =SUMIF(Daily_Sales!$C:$C,B35,Daily_Sales!$E:$E) | G35: =IF(B35="",0,E35*C35/100) | H35: =IF(F35>0,Masters!$X$3,0) | I35: =F35*Masters!$X$4 | J35: =SUMIFS(Cash_Book!$G:$G,Cash_Book!$C:$C,"BEPAARI",Cash_Book!$D:$D,"MOTOR",Cash_Book!$E:$E,B35)+SUMIFS(Cash_Book!$H:$H,Cash_Book!$C:$C,"BEPAARI",Cash_Book!$D:$D,"MOTOR",Cash_Book!$E:$E,B35) | K35: =SUMIFS(Cash_Book!$G:$G,Cash_Book!$C:$C,"BEPAARI",Cash_Book!$D:$D,"BHUSSA",Cash_Book!$E:$E,B35)+SUMIFS(Cash_Book!$H:$H,Cash_Book!$C:$C,"BEPAARI",Cash_Book!$D:$D,"BHUSSA",Cash_Book!$E:$E,B35) | L35: =SUMIFS(Cash_Book!$G:$G,Cash_Book!$C:$C,"BEPAARI",Cash_Book!$D:$D,"GAWALI",Cash_Book!$E:$E,B35)+SUMIFS(Cash_Book!$H:$H,Cash_Book!$C:$C,"BEPAARI",Cash_Book!$D:$D,"GAWALI",Cash_Book!$E:$E,B35) | M35: =SUMIFS(Cash_Book!$G:$G,Cash_Book!$C:$C,"BEPAARI",Cash_Book!$D:$D,"CASH_ADV",Cash_Book!$E:$E,B35)+SUMIFS(Cash_Book!$H:$H,Cash_Book!$C:$C,"BEPAARI",Cash_Book!$D:$D,"CASH_ADV",Cash_Book!$E:$E,B35) | N35: =SUMIFS(Cash_Book!$G:$G,Cash_Book!$C:$C,"BEPAARI",Cash_Book!$D:$D,"OTHER",Cash_Book!$E:$E,B35)+SUMIFS(Cash_Book!$H:$H,Cash_Book!$C:$C,"BEPAARI",Cash_Book!$D:$D,"OTHER",Cash_Book!$E:$E,B35) | O35: =SUM(G35:N35) | P35: =IF(B35="","",E35-O35+D35) | Q35: =SUMIFS(Cash_Book!$G:$G,Cash_Book!$C:$C,"BEPAARI",Cash_Book!$D:$D,"PAYMENT",Cash_Book!$E:$E,B35)+SUMIFS(Cash_Book!$H:$H,Cash_Book!$C:$C,"BEPAARI",Cash_Book!$D:$D,"PAYMENT",Cash_Book!$E:$E,B35) | R35: =IF(B35="","",P35-Q35)
A36: 32 | B36: =IF(Masters!$B$34="","",Masters!$B$34) | C36: =IF(B36="","",Masters!$C$34) | D36: =IF(B36="",0,Masters!$D$34) | E36: =SUMIF(Daily_Sales!$C:$C,B36,Daily_Sales!$G:$G) | F36: =SUMIF(Daily_Sales!$C:$C,B36,Daily_Sales!$E:$E) | G36: =IF(B36="",0,E36*C36/100) | H36: =IF(F36>0,Masters!$X$3,0) | I36: =F36*Masters!$X$4 | J36: =SUMIFS(Cash_Book!$G:$G,Cash_Book!$C:$C,"BEPAARI",Cash_Book!$D:$D,"MOTOR",Cash_Book!$E:$E,B36)+SUMIFS(Cash_Book!$H:$H,Cash_Book!$C:$C,"BEPAARI",Cash_Book!$D:$D,"MOTOR",Cash_Book!$E:$E,B36) | K36: =SUMIFS(Cash_Book!$G:$G,Cash_Book!$C:$C,"BEPAARI",Cash_Book!$D:$D,"BHUSSA",Cash_Book!$E:$E,B36)+SUMIFS(Cash_Book!$H:$H,Cash_Book!$C:$C,"BEPAARI",Cash_Book!$D:$D,"BHUSSA",Cash_Book!$E:$E,B36) | L36: =SUMIFS(Cash_Book!$G:$G,Cash_Book!$C:$C,"BEPAARI",Cash_Book!$D:$D,"GAWALI",Cash_Book!$E:$E,B36)+SUMIFS(Cash_Book!$H:$H,Cash_Book!$C:$C,"BEPAARI",Cash_Book!$D:$D,"GAWALI",Cash_Book!$E:$E,B36) | M36: =SUMIFS(Cash_Book!$G:$G,Cash_Book!$C:$C,"BEPAARI",Cash_Book!$D:$D,"CASH_ADV",Cash_Book!$E:$E,B36)+SUMIFS(Cash_Book!$H:$H,Cash_Book!$C:$C,"BEPAARI",Cash_Book!$D:$D,"CASH_ADV",Cash_Book!$E:$E,B36) | N36: =SUMIFS(Cash_Book!$G:$G,Cash_Book!$C:$C,"BEPAARI",Cash_Book!$D:$D,"OTHER",Cash_Book!$E:$E,B36)+SUMIFS(Cash_Book!$H:$H,Cash_Book!$C:$C,"BEPAARI",Cash_Book!$D:$D,"OTHER",Cash_Book!$E:$E,B36) | O36: =SUM(G36:N36) | P36: =IF(B36="","",E36-O36+D36) | Q36: =SUMIFS(Cash_Book!$G:$G,Cash_Book!$C:$C,"BEPAARI",Cash_Book!$D:$D,"PAYMENT",Cash_Book!$E:$E,B36)+SUMIFS(Cash_Book!$H:$H,Cash_Book!$C:$C,"BEPAARI",Cash_Book!$D:$D,"PAYMENT",Cash_Book!$E:$E,B36) | R36: =IF(B36="","",P36-Q36)
A37: 33 | B37: =IF(Masters!$B$35="","",Masters!$B$35) | C37: =IF(B37="","",Masters!$C$35) | D37: =IF(B37="",0,Masters!$D$35) | E37: =SUMIF(Daily_Sales!$C:$C,B37,Daily_Sales!$G:$G) | F37: =SUMIF(Daily_Sales!$C:$C,B37,Daily_Sales!$E:$E) | G37: =IF(B37="",0,E37*C37/100) | H37: =IF(F37>0,Masters!$X$3,0) | I37: =F37*Masters!$X$4 | J37: =SUMIFS(Cash_Book!$G:$G,Cash_Book!$C:$C,"BEPAARI",Cash_Book!$D:$D,"MOTOR",Cash_Book!$E:$E,B37)+SUMIFS(Cash_Book!$H:$H,Cash_Book!$C:$C,"BEPAARI",Cash_Book!$D:$D,"MOTOR",Cash_Book!$E:$E,B37) | K37: =SUMIFS(Cash_Book!$G:$G,Cash_Book!$C:$C,"BEPAARI",Cash_Book!$D:$D,"BHUSSA",Cash_Book!$E:$E,B37)+SUMIFS(Cash_Book!$H:$H,Cash_Book!$C:$C,"BEPAARI",Cash_Book!$D:$D,"BHUSSA",Cash_Book!$E:$E,B37) | L37: =SUMIFS(Cash_Book!$G:$G,Cash_Book!$C:$C,"BEPAARI",Cash_Book!$D:$D,"GAWALI",Cash_Book!$E:$E,B37)+SUMIFS(Cash_Book!$H:$H,Cash_Book!$C:$C,"BEPAARI",Cash_Book!$D:$D,"GAWALI",Cash_Book!$E:$E,B37) | M37: =SUMIFS(Cash_Book!$G:$G,Cash_Book!$C:$C,"BEPAARI",Cash_Book!$D:$D,"CASH_ADV",Cash_Book!$E:$E,B37)+SUMIFS(Cash_Book!$H:$H,Cash_Book!$C:$C,"BEPAARI",Cash_Book!$D:$D,"CASH_ADV",Cash_Book!$E:$E,B37) | N37: =SUMIFS(Cash_Book!$G:$G,Cash_Book!$C:$C,"BEPAARI",Cash_Book!$D:$D,"OTHER",Cash_Book!$E:$E,B37)+SUMIFS(Cash_Book!$H:$H,Cash_Book!$C:$C,"BEPAARI",Cash_Book!$D:$D,"OTHER",Cash_Book!$E:$E,B37) | O37: =SUM(G37:N37) | P37: =IF(B37="","",E37-O37+D37) | Q37: =SUMIFS(Cash_Book!$G:$G,Cash_Book!$C:$C,"BEPAARI",Cash_Book!$D:$D,"PAYMENT",Cash_Book!$E:$E,B37)+SUMIFS(Cash_Book!$H:$H,Cash_Book!$C:$C,"BEPAARI",Cash_Book!$D:$D,"PAYMENT",Cash_Book!$E:$E,B37) | R37: =IF(B37="","",P37-Q37)
A38: 34 | B38: =IF(Masters!$B$36="","",Masters!$B$36) | C38: =IF(B38="","",Masters!$C$36) | D38: =IF(B38="",0,Masters!$D$36) | E38: =SUMIF(Daily_Sales!$C:$C,B38,Daily_Sales!$G:$G) | F38: =SUMIF(Daily_Sales!$C:$C,B38,Daily_Sales!$E:$E) | G38: =IF(B38="",0,E38*C38/100) | H38: =IF(F38>0,Masters!$X$3,0) | I38: =F38*Masters!$X$4 | J38: =SUMIFS(Cash_Book!$G:$G,Cash_Book!$C:$C,"BEPAARI",Cash_Book!$D:$D,"MOTOR",Cash_Book!$E:$E,B38)+SUMIFS(Cash_Book!$H:$H,Cash_Book!$C:$C,"BEPAARI",Cash_Book!$D:$D,"MOTOR",Cash_Book!$E:$E,B38) | K38: =SUMIFS(Cash_Book!$G:$G,Cash_Book!$C:$C,"BEPAARI",Cash_Book!$D:$D,"BHUSSA",Cash_Book!$E:$E,B38)+SUMIFS(Cash_Book!$H:$H,Cash_Book!$C:$C,"BEPAARI",Cash_Book!$D:$D,"BHUSSA",Cash_Book!$E:$E,B38) | L38: =SUMIFS(Cash_Book!$G:$G,Cash_Book!$C:$C,"BEPAARI",Cash_Book!$D:$D,"GAWALI",Cash_Book!$E:$E,B38)+SUMIFS(Cash_Book!$H:$H,Cash_Book!$C:$C,"BEPAARI",Cash_Book!$D:$D,"GAWALI",Cash_Book!$E:$E,B38) | M38: =SUMIFS(Cash_Book!$G:$G,Cash_Book!$C:$C,"BEPAARI",Cash_Book!$D:$D,"CASH_ADV",Cash_Book!$E:$E,B38)+SUMIFS(Cash_Book!$H:$H,Cash_Book!$C:$C,"BEPAARI",Cash_Book!$D:$D,"CASH_ADV",Cash_Book!$E:$E,B38) | N38: =SUMIFS(Cash_Book!$G:$G,Cash_Book!$C:$C,"BEPAARI",Cash_Book!$D:$D,"OTHER",Cash_Book!$E:$E,B38)+SUMIFS(Cash_Book!$H:$H,Cash_Book!$C:$C,"BEPAARI",Cash_Book!$D:$D,"OTHER",Cash_Book!$E:$E,B38) | O38: =SUM(G38:N38) | P38: =IF(B38="","",E38-O38+D38) | Q38: =SUMIFS(Cash_Book!$G:$G,Cash_Book!$C:$C,"BEPAARI",Cash_Book!$D:$D,"PAYMENT",Cash_Book!$E:$E,B38)+SUMIFS(Cash_Book!$H:$H,Cash_Book!$C:$C,"BEPAARI",Cash_Book!$D:$D,"PAYMENT",Cash_Book!$E:$E,B38) | R38: =IF(B38="","",P38-Q38)
